Workbook
Name Analyse: #REF!
Name Angebotsnr: [7]Angebot!$H$14
Name ANZ_Breite: [7]Bestellvorlage_neu!$K$31
Name ANZ_Breite: [2]Bestellvorlage_neu!$F$24
Name ANZ_Elemente: [7]Bestellvorlage_neu!$K$34
Name ANZ_Elemente: [2]Bestellvorlage_neu!$F$27
Name ANZ_Höhe: [7]Bestellvorlage_neu!$K$32
Name ANZ_Höhe: [2]Bestellvorlage_neu!$F$25
Name ANZ_Tiefe: [7]Bestellvorlage_neu!$K$33
Name ANZ_Tiefe: [2]Bestellvorlage_neu!$F$26
Name Bericht: '[3]Bericht gesamt'!$B$4:$DG$59
Name Einkauf: #REF!
Name Ertragssicherung: #REF!
Name EXT: #REF!
Name F_Doppeltür_PG1: #REF!
Name F_Doppeltür_PG2_3: #REF!
Name F_Doppeltür_PG4: #REF!
Name F_Klappe_PG1: #REF!
Name F_Klappe_PG2_3: #REF!
Name F_Klappe_PG4: #REF!
Name F_Platten_PG1: #REF!
Name F_Platten_PG2_3: #REF!
Name F_Platten_PG4: #REF!
Name F_Schublade_PG1: #REF!
Name F_Schublade_PG2_3: #REF!
Name F_Schublade_PG4: #REF!
Name F_Tür_PG1: #REF!
Name F_Tür_PG2_3: #REF!
Name F_Tür_PG4: #REF!
Name Freigabe: #REF!
Name Gewicht_Klappe: [7]Gewichte!$D$6
Name Gewicht_Platte: [7]Gewichte!$D$2
Name Gewicht_Profil: [7]Gewichte!$D$3
Name Gewicht_Scharnier: [7]Gewichte!$D$7
Name Gewicht_Schubkasten: [7]Gewichte!$D$5
Name Ideen: #REF!
Name Innovations__prozeß: #REF!
Name KDN: [7]Angebot!$H$7
Name KDName2: [7]Angebot!$A$10
Name Komminikation: #REF!
Name Kommunikation: #REF!
Name Kompetenz: #REF!
Name Konfektion: [5]Orga!$U$41:$AF$46
Name Konstruktion: #REF!
Name Kreativpotential: #REF!
Name LPU: #REF!
Name Ludwig: #REF!
Name Marketing: #REF!
Name Organisation: #REF!
Name Preisniveau: #REF!
Name Produkt__und_Preissystematik: #REF!
Name Rabatt: [7]Bestellvorlage_neu!$N$4
Name SkriptBeschreibung: #REF!
Name Telephonmarketing: #REF!
Name TEST: #REF!
Name Tiefe: [7]Bestellvorlage_neu!$D$4
Name Tiefe: [2]Bestellvorlage_neu!$C$4
Name Umsetzung: #REF!
Name Vertrieb: [5]Orga!$U$48:$AE$56
Name Vertriebs_steuerung: #REF!

Sheet Erkenntnisse
A1: Preisanalyse Artmodul vs. USM — Erkenntnisse & Handlungsempfehlungen
A2: Stand: Dynamisches Modell mit differenzierten Kategorie-Faktoren
A4: 1. Ausgangslage
A5: • | B5: Artmodul-Einzelteilpreise (PG1 MDF) wurden komponentenweise zu Konfigurationspreisen aufgebaut
A6: • | B6: Formel pro Element: 2× Boden + 2× Seite + 1× Rücken + 8× Würfel + 4× Profil (B/H/T) + ggf. Front
A7: • | B7: Verglichen mit USM-Bruttopreisen (inkl. MwSt), Artmodul + 19% MwSt
A8: • | B8: Vergleichsbasis: 32 Konfigurationspaare mit nächstliegenden Maßen (z.B. 420↔395, 580↔500, 780↔750 mm)
A9: • | B9: USM-Preismodell enthält nur noch vom Nutzer verifizierte/überarbeitete Konfigurationen
A11: 2. Kernerkenntnisse
A13: 2a. Gesamtvergleich bei Originalpreisen (Faktor 1,00)
A14: Kennzahl | B14: Artmodul Brutto | C14: USM Brutto | D14: Δ absolut | E14: Δ relativ
A15: Ø alle 32 Paare | B15: =Preisvergleich!F51 -> 674.73 | C15: =Preisvergleich!G51 -> 680.60531 | D15: =Preisvergleich!H51 -> -5.8753125 | E15: =Preisvergleich!I51 -> -0.0044009788
A17: 2b. Abweichung nach Front-Kategorie (differenzierte Faktoren)
A18: Kategorie | B18: Paare | C18: Ø Art. Brutto | D18: Ø USM Brutto | E18: Ø Δ absolut | F18: Ø Δ relativ | G18: Bewertung
A19: Offen | B19: =Preisvergleich!B47 -> (12 Paare) | C19: =Preisvergleich!F47 -> 494.24667 | D19: =Preisvergleich!G47 -> 481.25833 | E19: =Preisvergleich!H47 -> 12.988333 | F19: =Preisvergleich!I47 -> 0.025768333 | G19: ⚠️ Leicht teurer — Hebel bei Strukturbauteilen
A20: Klappe | B20: =Preisvergleich!B48 -> (9 Paare) | C20: =Preisvergleich!F48 -> 697.47222 | D20: =Preisvergleich!G48 -> 713.08 | E20: =Preisvergleich!H48 -> -15.607778 | F20: =Preisvergleich!I48 -> -0.023260989 | G20: ✅ Wettbewerbsfähig — im Schnitt günstiger
A21: Schublade | B21: =Preisvergleich!B49 -> (11 Paare) | C21: =Preisvergleich!F49 -> 853.01364 | D21: =Preisvergleich!G49 -> 871.50455 | E21: =Preisvergleich!H49 -> -18.490909 | F21: =Preisvergleich!I49 -> -0.021882038 | G21: ✅ Klar günstiger — stärkste Kategorie
A23: 2c. Warum sind offene Elemente teurer?
A24: • | B24: Bei offenen Elementen besteht der Preis nur aus Strukturbauteilen (Böden, Seiten, Rücken, Profile, Würfel).
A25: • | B25: USM-Preise beinhalten offenbar eine Quersubventionierung: offene Elemente sind relativ günstig, Front-Aufpreise relativ hoch.
A26: • | B26: Artmodul kalkuliert komponentenbasiert — ohne diese Quersubventionierung sind offene Elemente im Vergleich teurer.
A27: • | B27: Bei Fronten (Klappe, Schublade) wird dies ausgeglichen: Artmodul-Frontenpreise sind im Verhältnis moderater.
A28: • | B28: Die Tiefe 580 mm verschärft das Problem: größere Seitenplatten + Profile treiben den Strukturpreis überproportional.
A30: 3. Aktuelle Faktor-Konfiguration
A32: Bauteile-Gruppe | B32: Faktor | C32: Abschlag | D32: Begründung
A33: Strukturbauteile | B33: 0.75 | C33: =1-B33 -> 0.25 | D33: Stärkster Hebel — machen offene Elemente teuer
B34: Böden, Seiten, Rücken, Fachböden, Profile
A35: Zubehör & Kleinteile | B35: 0.8 | C35: =1-B35 -> 0.2 | D35: Mittelweg — geringer Preiseinfluss pro Element
B36: Würfel, Griffe, Schlösser, Hängeregister
A37: Klappen & Türen | B37: 0.88 | C37: =1-B37 -> 0.12 | D37: Bereits wettbewerbsfähig — moderater Abschlag genügt
B38: Klappe, Tür, Doppeltür
A39: Schubladen | B39: 0.9 | C39: =1-B39 -> 0.1 | D39: Stärkste Kategorie — nur minimaler Abschlag nötig
B40: Schublade, Schublade LB 1/2
A42: 4. Handlungsempfehlungen
A44: 🔴 Hoch | B44: Strukturbauteil-Kosten senken
B45: Böden, Seiten und Rücken machen bei offenen Elementen ~80% des Preises aus. Faktor 0,75 (−25%) bringt Offen-Elemente auf +2,6% vs. USM. Für volle Parität wäre ~0,70 nötig.
A47: 🟡 Mittel | B47: Differenzierte Preisgruppen etablieren
B48: Einheitlicher Abschlag passt nicht für alle Kategorien. Empfehlung: Strukturbauteile aggressiver bepreisen, Fronten moderater. Das aktuelle Modell mit 4 Faktor-Gruppen liefert eine ausgeglichene Preisstruktur.
A50: 🟢 Niedrig | B50: Schubladen als Verkaufsargument nutzen
B51: Schubladen-Konfigurationen sind im Schnitt 2,2% günstiger als USM. Bei großen Bestellungen mit Schubladenanteil kann Artmodul preislich überzeugen.
...

Sheet Preismodell_USM
A1: USM Haller – Vollständiges Preismodell (Netto €) | 🟢 Grüner Hintergrund = Konfigurator-Echtwert | Weißer/blauer Hintergrund = Hochrechnung
A3: Tiefe 350 mm
A4: Front | B4: Tiefe (mm) | C4: Breite (mm) | D4: H 100 mm | E4: H 175 mm | F4: H 250 mm | G4: H 350 mm | H4: H 395 mm | I4: H 500 mm
A5: Offen | B5: 350 | C5: 250 | D5: 407.82 | E5: 398.62 | F5: 411.69 | G5: 429.13 | H5: 436.97 | I5: 460.11
C6: 350 | D6: 401.89 | E6: 414.96 | F6: 428.04 | G6: 445.47 | H6: 453.32 | I6: 471.62
C7: 395 | D7: 409.25 | E7: 422.32 | F7: 435.39 | G7: 452.83 | H7: 460.67 | I7: 478.98
C8: 500 | D8: 426.41 | E8: 439.48 | F8: 452.56 | G8: 469.99 | H8: 477.84 | I8: 496.14
C9: 750 | D9: 476.81 | E9: 480.35 | F9: 493.43 | G9: 510.86 | H9: 518.7 | I9: 537.01
A11: Klappe | B11: 350 | C11: 250
C12: 350 | G12: 643.05
C13: 395 | G13: 673.36 | H13: 681.2
C14: 500 | G14: 690.52 | H14: 698.37
C15: 750 | G15: 731.39 | H15: 742.7
A17: Glastür | B17: 350 | C17: 250 | F17: 628.94
C18: 350 | F18: 675.26 | G18: 692.69 | H18: 700.54 | I18: 718.84
C19: 395 | F19: 682.62 | G19: 700.05 | H19: 707.89 | I19: 726.2
C20: 500 | F20: 699.78 | G20: 717.21 | H20: 725.06 | I20: 743.36
C21: 750 | F21: 740.65 | G21: 758.08 | H21: 765.92 | I21: 830.8
A23: Schublade | B23: 350 | C23: 250 | F23: 799.66 | G23: 817.1 | H23: 824.94
C24: 350 | F24: 816.01 | G24: 833.44 | H24: 841.29
C25: 395 | F25: 823.37 | G25: 840.8 | H25: 848.64 | I25: 823.93
C26: 500 | E26: 787.6 | F26: 840.53 | G26: 857.96 | H26: 865.81
C27: 750 | E27: 874.27 | F27: 881.4 | G27: 898.83 | H27: 910.15
A30: Tiefe 500 mm
A31: Front | B31: Tiefe (mm) | C31: Breite (mm) | D31: H 100 mm | E31: H 175 mm | F31: H 250 mm | G31: H 350 mm | H31: H 395 mm | I31: H 500 mm
A32: Offen | B32: 500 | C32: 250 | D32: 422.78 | E32: 435.86 | F32: 448.93 | G32: 466.37 | H32: 474.21 | I32: 492.52
C33: 350 | D33: 439.13 | E33: 452.2 | F33: 465.28 | G33: 482.71 | H33: 490.56 | I33: 508.86
C34: 395 | D34: 446.49 | E34: 459.56 | F34: 472.63 | G34: 490.07 | H34: 497.91 | I34: 516.22
C35: 500 | D35: 463.65 | E35: 476.72 | F35: 489.8 | G35: 507.23 | H35: 515.08 | I35: 533.38
C36: 750 | D36: 504.52 | E36: 517.59 | F36: 530.67 | G36: 548.1 | H36: 555.94 | I36: 574.25
A38: Klappe | B38: 500 | C38: 250 | D38: 643.31 | E38: 656.39 | F38: 669.46 | G38: 686.9 | H38: 694.74 | I38: 713.05
C39: 350 | D39: 659.66 | E39: 672.73 | F39: 685.81 | G39: 703.24 | H39: 711.09 | I39: 729.39
C40: 395 | D40: 667.01 | E40: 680.09 | F40: 693.16 | G40: 710.6 | H40: 718.44 | I40: 736.75
C41: 500 | D41: 684.18 | E41: 697.25 | F41: 710.33 | G41: 727.76 | H41: 735.61 | I41: 753.91
C42: 750 | D42: 725.05 | E42: 738.12 | F42: 751.2 | G42: 768.63 | H42: 776.47 | I42: 794.78
A44: Glastür | B44: 500 | C44: 250 | D44: 670 | E44: 683.08 | F44: 696.15 | G44: 713.59 | H44: 721.43 | I44: 739.74
C45: 350 | D45: 686.35 | E45: 699.42 | F45: 712.5 | G45: 729.93 | H45: 737.78 | I45: 756.08
C46: 395 | D46: 693.71 | E46: 706.78 | F46: 719.86 | G46: 737.29 | H46: 745.13 | I46: 763.44
C47: 500 | D47: 710.87 | E47: 723.94 | F47: 737.02 | G47: 754.45 | H47: 762.3 | I47: 780.6
C48: 750 | D48: 751.74 | E48: 764.81 | F48: 777.89 | G48: 795.32 | H48: 803.16 | I48: 821.47
...

Sheet Annahmen & Aufschläge
A1: Hochrechnungsformel
A2: Preis (Netto) = Basis + α × (Breite − 395) + β × (Höhe − 175) + γ × (Tiefe − 350) + Frontenaufschlag
A4: Basisparameter (abgeleitet aus Echtwerten)
A5: Basispreis B=395 / H=175 / T=350 / Offen | B5: 422.32 | C5: € | D5: Echtwert
A6: α – Aufschlag je mm Breite | B6: 0.1635 | C6: €/mm | D6: aus Δ 395→750mm, H=175
A7: β – Aufschlag je mm Höhe | B7: 0.1743 | C7: €/mm | D7: aus Δ H350→H500, B=750
A8: γ – Aufschlag je mm Tiefe | B8: 0.2483 | C8: €/mm | D8: aus Δ T350→T500, B=750
A10: Frontenaufschläge (Referenz: B=750 / H=350 / T=350)
A11: Offen | B11: 0 | C11: € Aufschlag | D11: Echtwert 510.86 €
A12: Klappe | B12: 220.53 | C12: € Aufschlag | D12: Echtwert 731.39 €
A13: Glastür | B13: 247.22 | C13: € Aufschlag | D13: Echtwert 758.08 €
A14: Schublade | B14: 387.97 | C14: € Aufschlag | D14: Echtwert 898.83 €
A16: Diskrete Breitenaufschläge (je Stufe, Offen / T350 / H175)
A17: Breite 250 mm | B17: 0 | C17: € Δ zur Vorstufe | D17: absolut: 398.62 €
A18: Breite 350 mm | B18: 16.35 | C18: € Δ zur Vorstufe | D18: absolut: 414.96 €
A19: Breite 395 mm | B19: 7.36 | C19: € Δ zur Vorstufe | D19: absolut: 422.32 €
A20: Breite 500 mm | B20: 17.16 | C20: € Δ zur Vorstufe | D20: absolut: 439.48 €
A21: Breite 750 mm | B21: 40.87 | C21: € Δ zur Vorstufe | D21: absolut: 480.35 €
A23: Diskrete Höhenaufschläge (je Stufe, Offen / T350 / B395)
A24: Höhe 100 mm | B24: 0 | C24: € Δ zur Vorstufe
A25: Höhe 175 mm | B25: 13.07 | C25: € Δ zur Vorstufe
A26: Höhe 250 mm | B26: 13.07 | C26: € Δ zur Vorstufe
A27: Höhe 350 mm | B27: 17.43 | C27: € Δ zur Vorstufe
A28: Höhe 395 mm | B28: 7.84 | C28: € Δ zur Vorstufe
A29: Höhe 500 mm | B29: 18.3 | C29: € Δ zur Vorstufe
A31: Echtwerte (Grundlage der Kalibrierung)
A32: B=395 / H=175 / T=350 / Offen | B32: 422.32 | C32: € Netto | D32: Konfigurator
A33: B=750 / H=350 / T=350 / Offen | B33: 510.86 | C33: € Netto | D33: Konfigurator
A34: B=750 / H=500 / T=350 / Offen | B34: 537.01 | C34: € Netto | D34: Konfigurator
A35: B=750 / H=350 / T=500 / Offen | B35: 548.1 | C35: € Netto | D35: Konfigurator
A36: B=750 / H=350 / T=350 / Klappe | B36: 731.39 | C36: € Netto | D36: Konfigurator
A37: B=750 / H=350 / T=350 / Glastür | B37: 758.08 | C37: € Netto | D37: Konfigurator
A38: B=750 / H=350 / T=350 / Schublade | B38: 898.83 | C38: € Netto | D38: Konfigurator
A40: Hinweise & Einschränkungen
A41: • Frontenaufschlag ist größenunabhängig modelliert (Vereinfachung)
A42: • In Realität: größere Fronten wahrscheinlich teurer als kleine
A43: • Modell basiert auf 7 Echtwerten — Genauigkeit ±10-15% geschätzt
A44: • Farbe (15 USM-Farben) nicht modelliert — kann Aufpreis bedeuten
A45: • Preise Stand: Konfigurator-Screenshots (Datum unbekannt)
A46: • MwSt. 19% = Netto × 1,19 → Sheet 3

Sheet Brutto-Übersicht (T=350)
A1: Bruttopreise inkl. 19% MwSt. | Tiefe 350 mm | Grün = Basis Echtwert (Netto×1,19)
A3: Offen
A4: Breite (mm) | B4: H 100 mm | C4: H 175 mm | D4: H 250 mm | E4: H 350 mm | F4: H 395 mm | G4: H 500 mm
A5: 250 | B5: 458.79 | C5: 474.36 | D5: 489.91 | E5: 510.66 | F5: 519.99 | G5: 541.78
A6: 350 | B6: 478.25 | C6: 493.8 | D6: 509.37 | E6: 530.11 | F6: 539.45 | G6: 561.23
A7: 395 | B7: 487.01 | C7: 502.56 | D7: 518.11 | E7: 538.87 | F7: 548.2 | G7: 569.99
A8: 500 | B8: 507.43 | C8: 522.98 | D8: 538.55 | E8: 559.29 | F8: 568.63 | G8: 590.41
A9: 750 | B9: 556.06 | C9: 571.62 | D9: 587.18 | E9: 607.92 | F9: 617.25 | G9: 639.04
A12: Klappe
A13: Breite (mm) | B13: H 100 mm | C13: H 175 mm | D13: H 250 mm | E13: H 350 mm | F13: H 395 mm | G13: H 500 mm
A14: 250 | B14: 721.22 | C14: 736.79 | D14: 752.34 | E14: 773.1 | F14: 782.42 | G14: 804.21
A15: 350 | B15: 740.68 | C15: 756.23 | D15: 771.8 | E15: 792.54 | F15: 801.88 | G15: 823.66
A16: 395 | B16: 749.43 | C16: 764.99 | D16: 780.54 | E16: 801.3 | F16: 810.63 | G16: 832.42
A17: 500 | B17: 769.86 | C17: 785.41 | D17: 800.98 | E17: 821.72 | F17: 831.06 | G17: 852.84
A18: 750 | B18: 818.49 | C18: 834.05 | D18: 849.61 | E18: 870.35 | F18: 879.68 | G18: 901.47
A21: Glastür
A22: Breite (mm) | B22: H 100 mm | C22: H 175 mm | D22: H 250 mm | E22: H 350 mm | F22: H 395 mm | G22: H 500 mm
A23: 250 | B23: 752.98 | C23: 768.55 | D23: 784.1 | E23: 804.86 | F23: 814.19 | G23: 835.97
A24: 350 | B24: 772.44 | C24: 787.99 | D24: 803.56 | E24: 824.3 | F24: 833.64 | G24: 855.42
A25: 395 | B25: 781.2 | C25: 796.75 | D25: 812.32 | E25: 833.06 | F25: 842.39 | G25: 864.18
A26: 500 | B26: 801.62 | C26: 817.17 | D26: 832.74 | E26: 853.48 | F26: 862.82 | G26: 884.6
A27: 750 | B27: 850.25 | C27: 865.81 | D27: 881.37 | E27: 902.12 | F27: 911.44 | G27: 933.23
A30: Schublade
A31: Breite (mm) | B31: H 100 mm | C31: H 175 mm | D31: H 250 mm | E31: H 350 mm | F31: H 395 mm | G31: H 500 mm
A32: 250 | B32: 920.48 | C32: 936.04 | D32: 951.6 | E32: 972.35 | F32: 981.68 | G32: 1003.47
A33: 350 | B33: 939.93 | C33: 955.49 | D33: 971.05 | E33: 991.79 | F33: 1001.14 | G33: 1022.91
A34: 395 | B34: 948.69 | C34: 964.25 | D34: 979.81 | E34: 1000.55 | F34: 1009.88 | G34: 1031.67
A35: 500 | B35: 969.11 | C35: 984.67 | D35: 1000.23 | E35: 1020.97 | F35: 1030.31 | G35: 1052.09
A36: 750 | B36: 1017.75 | C36: 1033.3 | D36: 1048.87 | E36: 1069.61 | F36: 1078.94 | G36: 1100.73

Sheet Preismodell_Artmodul_alt
A1: Artmodul – Preismodell aus Einzelteilpreisen (PG1 MDF, Netto €)
A3: Tiefe 360 mm
A4: Front | B4: Tiefe (mm) | C4: Breite (mm) | D4: H 180 mm | E4: H 360 mm | F4: H 720 mm | G4: H 1080 mm | H4: H 1440 mm | I4: H 1800 mm
A5: Offen | B5: 360 | C5: 420 | D5: =2*Artmodul_Einzelteilpreise_alt!G3+2*Artmodul_Einzelteilpreise_alt!G18+Artmodul_Einzelteilpreise_alt!G67+8*Artmodul_Einzelteilpreise_alt!G263+4*Artmodul_Einzelteilpreise_alt!G273+4*Artmodul_Einzelteilpreise_alt!G271+4*Artmodul_Einzelteilpreise_alt!G272 -> 458 | E5: =2*Artmodul_Einzelteilpreise_alt!G3+2*Artmodul_Einzelteilpreise_alt!G19+Artmodul_Einzelteilpreise_alt!G72+8*Artmodul_Einzelteilpreise_alt!G263+4*Artmodul_Einzelteilpreise_alt!G273+4*Artmodul_Einzelteilpreise_alt!G272+4*Artmodul_Einzelteilpreise_alt!G272 -> 458 | F5: =2*Artmodul_Einzelteilpreise_alt!G3+2*Artmodul_Einzelteilpreise_alt!G20+Artmodul_Einzelteilpreise_alt!G77+8*Artmodul_Einzelteilpreise_alt!G263+4*Artmodul_Einzelteilpreise_alt!G273+4*Artmodul_Einzelteilpreise_alt!G276+4*Artmodul_Einzelteilpreise_alt!G272 -> 540 | G5: =2*Artmodul_Einzelteilpreise_alt!G3+2*Artmodul_Einzelteilpreise_alt!G21+Artmodul_Einzelteilpreise_alt!G82+8*Artmodul_Einzelteilpreise_alt!G263+4*Artmodul_Einzelteilpreise_alt!G273+4*Artmodul_Einzelteilpreise_alt!G279+4*Artmodul_Einzelteilpreise_alt!G272 -> 632 | H5: =2*Artmodul_Einzelteilpreise_alt!G3+2*Artmodul_Einzelteilpreise_alt!G22+Artmodul_Einzelteilpreise_alt!G87+8*Artmodul_Einzelteilpreise_alt!G263+4*Artmodul_Einzelteilpreise_alt!G273+4*Artmodul_Einzelteilpreise_alt!G280+4*Artmodul_Einzelteilpreise_alt!G272 -> 731 | I5: =2*Artmodul_Einzelteilpreise_alt!G3+2*Artmodul_Einzelteilpreise_alt!G23+Artmodul_Einzelteilpreise_alt!G92+8*Artmodul_Einzelteilpreise_alt!G263+4*Artmodul_Einzelteilpreise_alt!G273+4*Artmodul_Einzelteilpreise_alt!G281+4*Artmodul_Einzelteilpreise_alt!G272 -> 825
C6: 580 | D6: =2*Artmodul_Einzelteilpreise_alt!G4+2*Artmodul_Einzelteilpreise_alt!G18+Artmodul_Einzelteilpreise_alt!G68+8*Artmodul_Einzelteilpreise_alt!G263+4*Artmodul_Einzelteilpreise_alt!G274+4*Artmodul_Einzelteilpreise_alt!G271+4*Artmodul_Einzelteilpreise_alt!G272 -> 493 | E6: =2*Artmodul_Einzelteilpreise_alt!G4+2*Artmodul_Einzelteilpreise_alt!G19+Artmodul_Einzelteilpreise_alt!G73+8*Artmodul_Einzelteilpreise_alt!G263+4*Artmodul_Einzelteilpreise_alt!G274+4*Artmodul_Einzelteilpreise_alt!G272+4*Artmodul_Einzelteilpreise_alt!G272 -> 493 | F6: =2*Artmodul_Einzelteilpreise_alt!G4+2*Artmodul_Einzelteilpreise_alt!G20+Artmodul_Einzelteilpreise_alt!G78+8*Artmodul_Einzelteilpreise_alt!G263+4*Artmodul_Einzelteilpreise_alt!G274+4*Artmodul_Einzelteilpreise_alt!G276+4*Artmodul_Einzelteilpreise_alt!G272 -> 588 | G6: =2*Artmodul_Einzelteilpreise_alt!G4+2*Artmodul_Einzelteilpreise_alt!G21+Artmodul_Einzelteilpreise_alt!G83+8*Artmodul_Einzelteilpreise_alt!G263+4*Artmodul_Einzelteilpreise_alt!G274+4*Artmodul_Einzelteilpreise_alt!G279+4*Artmodul_Einzelteilpreise_alt!G272 -> 689 | H6: =2*Artmodul_Einzelteilpreise_alt!G4+2*Artmodul_Einzelteilpreise_alt!G22+Artmodul_Einzelteilpreise_alt!G88+8*Artmodul_Einzelteilpreise_alt!G263+4*Artmodul_Einzelteilpreise_alt!G274+4*Artmodul_Einzelteilpreise_alt!G280+4*Artmodul_Einzelteilpreise_alt!G272 -> 800 | I6: =2*Artmodul_Einzelteilpreise_alt!G4+2*Artmodul_Einzelteilpreise_alt!G23+Artmodul_Einzelteilpreise_alt!G93+8*Artmodul_Einzelteilpreise_alt!G263+4*Artmodul_Einzelteilpreise_alt!G274+4*Artmodul_Einzelteilpreise_alt!G281+4*Artmodul_Einzelteilpreise_alt!G272 -> 905
C7: 780 | D7: =2*Artmodul_Einzelteilpreise_alt!G5+2*Artmodul_Einzelteilpreise_alt!G18+Artmodul_Einzelteilpreise_alt!G69+8*Artmodul_Einzelteilpreise_alt!G263+4*Artmodul_Einzelteilpreise_alt!G277+4*Artmodul_Einzelteilpreise_alt!G271+4*Artmodul_Einzelteilpreise_alt!G272 -> 544 | E7: =2*Artmodul_Einzelteilpreise_alt!G5+2*Artmodul_Einzelteilpreise_alt!G19+Artmodul_Einzelteilpreise_alt!G74+8*Artmodul_Einzelteilpreise_alt!G263+4*Artmodul_Einzelteilpreise_alt!G277+4*Artmodul_Einzelteilpreise_alt!G272+4*Artmodul_Einzelteilpreise_alt!G272 -> 544 | F7: =2*Artmodul_Einzelteilpreise_alt!G5+2*Artmodul_Einzelteilpreise_alt!G20+Artmodul_Einzelteilpreise_alt!G79+8*Artmodul_Einzelteilpreise_alt!G263+4*Artmodul_Einzelteilpreise_alt!G277+4*Artmodul_Einzelteilpreise_alt!G276+4*Artmodul_Einzelteilpreise_alt!G272 -> 651 | G7: =2*Artmodul_Einzelteilpreise_alt!G5+2*Artmodul_Einzelteilpreise_alt!G21+Artmodul_Einzelteilpreise_alt!G84+8*Artmodul_Einzelteilpreise_alt!G263+4*Artmodul_Einzelteilpreise_alt!G277+4*Artmodul_Einzelteilpreise_alt!G279+4*Artmodul_Einzelteilpreise_alt!G272 -> 769 | H7: =2*Artmodul_Einzelteilpreise_alt!G5+2*Artmodul_Einzelteilpreise_alt!G22+Artmodul_Einzelteilpreise_alt!G89+8*Artmodul_Einzelteilpreise_alt!G263+4*Artmodul_Einzelteilpreise_alt!G277+4*Artmodul_Einzelteilpreise_alt!G280+4*Artmodul_Einzelteilpreise_alt!G272 -> 891 | I7: =2*Artmodul_Einzelteilpreise_alt!G5+2*Artmodul_Einzelteilpreise_alt!G23+Artmodul_Einzelteilpreise_alt!G94+8*Artmodul_Einzelteilpreise_alt!G263+4*Artmodul_Einzelteilpreise_alt!G277+4*Artmodul_Einzelteilpreise_alt!G281+4*Artmodul_Einzelteilpreise_alt!G272 -> 1010
C8: 980 | D8: =2*Artmodul_Einzelteilpreise_alt!G6+2*Artmodul_Einzelteilpreise_alt!G18+Artmodul_Einzelteilpreise_alt!G70+8*Artmodul_Einzelteilpreise_alt!G263+4*Artmodul_Einzelteilpreise_alt!G278+4*Artmodul_Einzelteilpreise_alt!G271+4*Artmodul_Einzelteilpreise_alt!G272 -> 594 | E8: =2*Artmodul_Einzelteilpreise_alt!G6+2*Artmodul_Einzelteilpreise_alt!G19+Artmodul_Einzelteilpreise_alt!G75+8*Artmodul_Einzelteilpreise_alt!G263+4*Artmodul_Einzelteilpreise_alt!G278+4*Artmodul_Einzelteilpreise_alt!G272+4*Artmodul_Einzelteilpreise_alt!G272 -> 594 | F8: =2*Artmodul_Einzelteilpreise_alt!G6+2*Artmodul_Einzelteilpreise_alt!G20+Artmodul_Einzelteilpreise_alt!G80+8*Artmodul_Einzelteilpreise_alt!G263+4*Artmodul_Einzelteilpreise_alt!G278+4*Artmodul_Einzelteilpreise_alt!G276+4*Artmodul_Einzelteilpreise_alt!G272 -> 714 | G8: =2*Artmodul_Einzelteilpreise_alt!G6+2*Artmodul_Einzelteilpreise_alt!G21+Artmodul_Einzelteilpreise_alt!G85+8*Artmodul_Einzelteilpreise_alt!G263+4*Artmodul_Einzelteilpreise_alt!G278+4*Artmodul_Einzelteilpreise_alt!G279+4*Artmodul_Einzelteilpreise_alt!G272 -> 844 | H8: =2*Artmodul_Einzelteilpreise_alt!G6+2*Artmodul_Einzelteilpreise_alt!G22+Artmodul_Einzelteilpreise_alt!G90+8*Artmodul_Einzelteilpreise_alt!G263+4*Artmodul_Einzelteilpreise_alt!G278+4*Artmodul_Einzelteilpreise_alt!G280+4*Artmodul_Einzelteilpreise_alt!G272 -> 980 | I8: =2*Artmodul_Einzelteilpreise_alt!G6+2*Artmodul_Einzelteilpreise_alt!G23+Artmodul_Einzelteilpreise_alt!G95+8*Artmodul_Einzelteilpreise_alt!G263+4*Artmodul_Einzelteilpreise_alt!G278+4*Artmodul_Einzelteilpreise_alt!G281+4*Artmodul_Einzelteilpreise_alt!G272 -> 1111
A10: Klappe | B10: 360 | C10: 420 | D10: =2*Artmodul_Einzelteilpreise_alt!G3+2*Artmodul_Einzelteilpreise_alt!G18+Artmodul_Einzelteilpreise_alt!G67+8*Artmodul_Einzelteilpreise_alt!G263+4*Artmodul_Einzelteilpreise_alt!G273+4*Artmodul_Einzelteilpreise_alt!G271+4*Artmodul_Einzelteilpreise_alt!G272+Artmodul_Einzelteilpreise_alt!G191 -> 627 | E10: =2*Artmodul_Einzelteilpreise_alt!G3+2*Artmodul_Einzelteilpreise_alt!G19+Artmodul_Einzelteilpreise_alt!G72+8*Artmodul_Einzelteilpreise_alt!G263+4*Artmodul_Einzelteilpreise_alt!G273+4*Artmodul_Einzelteilpreise_alt!G272+4*Artmodul_Einzelteilpreise_alt!G272+Artmodul_Einzelteilpreise_alt!G192 -> 627
C11: 580 | D11: =2*Artmodul_Einzelteilpreise_alt!G4+2*Artmodul_Einzelteilpreise_alt!G18+Artmodul_Einzelteilpreise_alt!G68+8*Artmodul_Einzelteilpreise_alt!G263+4*Artmodul_Einzelteilpreise_alt!G274+4*Artmodul_Einzelteilpreise_alt!G271+4*Artmodul_Einzelteilpreise_alt!G272+Artmodul_Einzelteilpreise_alt!G193 -> 677 | E11: =2*Artmodul_Einzelteilpreise_alt!G4+2*Artmodul_Einzelteilpreise_alt!G19+Artmodul_Einzelteilpreise_alt!G73+8*Artmodul_Einzelteilpreise_alt!G263+4*Artmodul_Einzelteilpreise_alt!G274+4*Artmodul_Einzelteilpreise_alt!G272+4*Artmodul_Einzelteilpreise_alt!G272+Artmodul_Einzelteilpreise_alt!G194 -> 677
C12: 780 | D12: =2*Artmodul_Einzelteilpreise_alt!G5+2*Artmodul_Einzelteilpreise_alt!G18+Artmodul_Einzelteilpreise_alt!G69+8*Artmodul_Einzelteilpreise_alt!G263+4*Artmodul_Einzelteilpreise_alt!G277+4*Artmodul_Einzelteilpreise_alt!G271+4*Artmodul_Einzelteilpreise_alt!G272+Artmodul_Einzelteilpreise_alt!G195 -> 742 | E12: =2*Artmodul_Einzelteilpreise_alt!G5+2*Artmodul_Einzelteilpreise_alt!G19+Artmodul_Einzelteilpreise_alt!G74+8*Artmodul_Einzelteilpreise_alt!G263+4*Artmodul_Einzelteilpreise_alt!G277+4*Artmodul_Einzelteilpreise_alt!G272+4*Artmodul_Einzelteilpreise_alt!G272+Artmodul_Einzelteilpreise_alt!G196 -> 742
C13: 980 | D13: =2*Artmodul_Einzelteilpreise_alt!G6+2*Artmodul_Einzelteilpreise_alt!G18+Artmodul_Einzelteilpreise_alt!G70+8*Artmodul_Einzelteilpreise_alt!G263+4*Artmodul_Einzelteilpreise_alt!G278+4*Artmodul_Einzelteilpreise_alt!G271+4*Artmodul_Einzelteilpreise_alt!G272+Artmodul_Einzelteilpreise_alt!G197 -> 844 | E13: =2*Artmodul_Einzelteilpreise_alt!G6+2*Artmodul_Einzelteilpreise_alt!G19+Artmodul_Einzelteilpreise_alt!G75+8*Artmodul_Einzelteilpreise_alt!G263+4*Artmodul_Einzelteilpreise_alt!G278+4*Artmodul_Einzelteilpreise_alt!G272+4*Artmodul_Einzelteilpreise_alt!G272+Artmodul_Einzelteilpreise_alt!G198 -> 844
A15: Tür | B15: 360 | C15: 420 | E15: =2*Artmodul_Einzelteilpreise_alt!G3+2*Artmodul_Einzelteilpreise_alt!G19+Artmodul_Einzelteilpreise_alt!G72+8*Artmodul_Einzelteilpreise_alt!G263+4*Artmodul_Einzelteilpreise_alt!G273+4*Artmodul_Einzelteilpreise_alt!G272+4*Artmodul_Einzelteilpreise_alt!G272+Artmodul_Einzelteilpreise_alt!G202 -> 594 | F15: =2*Artmodul_Einzelteilpreise_alt!G3+2*Artmodul_Einzelteilpreise_alt!G20+Artmodul_Einzelteilpreise_alt!G77+8*Artmodul_Einzelteilpreise_alt!G263+4*Artmodul_Einzelteilpreise_alt!G273+4*Artmodul_Einzelteilpreise_alt!G276+4*Artmodul_Einzelteilpreise_alt!G272+Artmodul_Einzelteilpreise_alt!G203 -> 699 | G15: =2*Artmodul_Einzelteilpreise_alt!G3+2*Artmodul_Einzelteilpreise_alt!G21+Artmodul_Einzelteilpreise_alt!G82+8*Artmodul_Einzelteilpreise_alt!G263+4*Artmodul_Einzelteilpreise_alt!G273+4*Artmodul_Einzelteilpreise_alt!G279+4*Artmodul_Einzelteilpreise_alt!G272+Artmodul_Einzelteilpreise_alt!G204 -> 867 | H15: =2*Artmodul_Einzelteilpreise_alt!G3+2*Artmodul_Einzelteilpreise_alt!G22+Artmodul_Einzelteilpreise_alt!G87+8*Artmodul_Einzelteilpreise_alt!G263+4*Artmodul_Einzelteilpreise_alt!G273+4*Artmodul_Einzelteilpreise_alt!G280+4*Artmodul_Einzelteilpreise_alt!G272+Artmodul_Einzelteilpreise_alt!G205 -> 988 | I15: =2*Artmodul_Einzelteilpreise_alt!G3+2*Artmodul_Einzelteilpreise_alt!G23+Artmodul_Einzelteilpreise_alt!G92+8*Artmodul_Einzelteilpreise_alt!G263+4*Artmodul_Einzelteilpreise_alt!G273+4*Artmodul_Einzelteilpreise_alt!G281+4*Artmodul_Einzelteilpreise_alt!G272+Artmodul_Einzelteilpreise_alt!G206 -> 1165
C16: 580 | E16: =2*Artmodul_Einzelteilpreise_alt!G4+2*Artmodul_Einzelteilpreise_alt!G19+Artmodul_Einzelteilpreise_alt!G73+8*Artmodul_Einzelteilpreise_alt!G263+4*Artmodul_Einzelteilpreise_alt!G274+4*Artmodul_Einzelteilpreise_alt!G272+4*Artmodul_Einzelteilpreise_alt!G272+Artmodul_Einzelteilpreise_alt!G207 -> 646 | F16: =2*Artmodul_Einzelteilpreise_alt!G4+2*Artmodul_Einzelteilpreise_alt!G20+Artmodul_Einzelteilpreise_alt!G78+8*Artmodul_Einzelteilpreise_alt!G263+4*Artmodul_Einzelteilpreise_alt!G274+4*Artmodul_Einzelteilpreise_alt!G276+4*Artmodul_Einzelteilpreise_alt!G272+Artmodul_Einzelteilpreise_alt!G208 -> 798 | G16: =2*Artmodul_Einzelteilpreise_alt!G4+2*Artmodul_Einzelteilpreise_alt!G21+Artmodul_Einzelteilpreise_alt!G83+8*Artmodul_Einzelteilpreise_alt!G263+4*Artmodul_Einzelteilpreise_alt!G274+4*Artmodul_Einzelteilpreise_alt!G279+4*Artmodul_Einzelteilpreise_alt!G272+Artmodul_Einzelteilpreise_alt!G209 -> 967 | H16: =2*Artmodul_Einzelteilpreise_alt!G4+2*Artmodul_Einzelteilpreise_alt!G22+Artmodul_Einzelteilpreise_alt!G88+8*Artmodul_Einzelteilpreise_alt!G263+4*Artmodul_Einzelteilpreise_alt!G274+4*Artmodul_Einzelteilpreise_alt!G280+4*Artmodul_Einzelteilpreise_alt!G272+Artmodul_Einzelteilpreise_alt!G210 -> 1137 | I16: =2*Artmodul_Einzelteilpreise_alt!G4+2*Artmodul_Einzelteilpreise_alt!G23+Artmodul_Einzelteilpreise_alt!G93+8*Artmodul_Einzelteilpreise_alt!G263+4*Artmodul_Einzelteilpreise_alt!G274+4*Artmodul_Einzelteilpreise_alt!G281+4*Artmodul_Einzelteilpreise_alt!G272+Artmodul_Einzelteilpreise_alt!G211 -> 1322
C17: 780 | E17: =2*Artmodul_Einzelteilpreise_alt!G5+2*Artmodul_Einzelteilpreise_alt!G19+Artmodul_Einzelteilpreise_alt!G74+8*Artmodul_Einzelteilpreise_alt!G263+4*Artmodul_Einzelteilpreise_alt!G277+4*Artmodul_Einzelteilpreise_alt!G272+4*Artmodul_Einzelteilpreise_alt!G272+Artmodul_Einzelteilpreise_alt!G214 -> 799 | F17: =2*Artmodul_Einzelteilpreise_alt!G5+2*Artmodul_Einzelteilpreise_alt!G20+Artmodul_Einzelteilpreise_alt!G79+8*Artmodul_Einzelteilpreise_alt!G263+4*Artmodul_Einzelteilpreise_alt!G277+4*Artmodul_Einzelteilpreise_alt!G276+4*Artmodul_Einzelteilpreise_alt!G272+Artmodul_Einzelteilpreise_alt!G216 -> 965 | G17: =2*Artmodul_Einzelteilpreise_alt!G5+2*Artmodul_Einzelteilpreise_alt!G21+Artmodul_Einzelteilpreise_alt!G84+8*Artmodul_Einzelteilpreise_alt!G263+4*Artmodul_Einzelteilpreise_alt!G277+4*Artmodul_Einzelteilpreise_alt!G279+4*Artmodul_Einzelteilpreise_alt!G272+Artmodul_Einzelteilpreise_alt!G217 -> 1233 | H17: =2*Artmodul_Einzelteilpreise_alt!G5+2*Artmodul_Einzelteilpreise_alt!G22+Artmodul_Einzelteilpreise_alt!G89+8*Artmodul_Einzelteilpreise_alt!G263+4*Artmodul_Einzelteilpreise_alt!G277+4*Artmodul_Einzelteilpreise_alt!G280+4*Artmodul_Einzelteilpreise_alt!G272+Artmodul_Einzelteilpreise_alt!G218 -> 1433 | I17: =2*Artmodul_Einzelteilpreise_alt!G5+2*Artmodul_Einzelteilpreise_alt!G23+Artmodul_Einzelteilpreise_alt!G94+8*Artmodul_Einzelteilpreise_alt!G263+4*Artmodul_Einzelteilpreise_alt!G277+4*Artmodul_Einzelteilpreise_alt!G281+4*Artmodul_Einzelteilpreise_alt!G272+Artmodul_Einzelteilpreise_alt!G219 -> 1678
C18: 980 | E18: =2*Artmodul_Einzelteilpreise_alt!G6+2*Artmodul_Einzelteilpreise_alt!G19+Artmodul_Einzelteilpreise_alt!G75+8*Artmodul_Einzelteilpreise_alt!G263+4*Artmodul_Einzelteilpreise_alt!G278+4*Artmodul_Einzelteilpreise_alt!G272+4*Artmodul_Einzelteilpreise_alt!G272+Artmodul_Einzelteilpreise_alt!G220 -> 863 | F18: =2*Artmodul_Einzelteilpreise_alt!G6+2*Artmodul_Einzelteilpreise_alt!G20+Artmodul_Einzelteilpreise_alt!G80+8*Artmodul_Einzelteilpreise_alt!G263+4*Artmodul_Einzelteilpreise_alt!G278+4*Artmodul_Einzelteilpreise_alt!G276+4*Artmodul_Einzelteilpreise_alt!G272+Artmodul_Einzelteilpreise_alt!G221 -> 1089 | G18: =2*Artmodul_Einzelteilpreise_alt!G6+2*Artmodul_Einzelteilpreise_alt!G21+Artmodul_Einzelteilpreise_alt!G85+8*Artmodul_Einzelteilpreise_alt!G263+4*Artmodul_Einzelteilpreise_alt!G278+4*Artmodul_Einzelteilpreise_alt!G279+4*Artmodul_Einzelteilpreise_alt!G272+Artmodul_Einzelteilpreise_alt!G222 -> 1367 | H18: =2*Artmodul_Einzelteilpreise_alt!G6+2*Artmodul_Einzelteilpreise_alt!G22+Artmodul_Einzelteilpreise_alt!G90+8*Artmodul_Einzelteilpreise_alt!G263+4*Artmodul_Einzelteilpreise_alt!G278+4*Artmodul_Einzelteilpreise_alt!G280+4*Artmodul_Einzelteilpreise_alt!G272+Artmodul_Einzelteilpreise_alt!G223 -> 1605 | I18: =2*Artmodul_Einzelteilpreise_alt!G6+2*Artmodul_Einzelteilpreise_alt!G23+Artmodul_Einzelteilpreise_alt!G95+8*Artmodul_Einzelteilpreise_alt!G263+4*Artmodul_Einzelteilpreise_alt!G278+4*Artmodul_Einzelteilpreise_alt!G281+4*Artmodul_Einzelteilpreise_alt!G272+Artmodul_Einzelteilpreise_alt!G224 -> 1880
A20: Schublade | B20: 360 | C20: 420 | D20: =2*Artmodul_Einzelteilpreise_alt!G3+2*Artmodul_Einzelteilpreise_alt!G18+Artmodul_Einzelteilpreise_alt!G67+8*Artmodul_Einzelteilpreise_alt!G263+4*Artmodul_Einzelteilpreise_alt!G273+4*Artmodul_Einzelteilpreise_alt!G271+4*Artmodul_Einzelteilpreise_alt!G272+Artmodul_Einzelteilpreise_alt!G225 -> 743 | E20: =2*Artmodul_Einzelteilpreise_alt!G3+2*Artmodul_Einzelteilpreise_alt!G19+Artmodul_Einzelteilpreise_alt!G72+8*Artmodul_Einzelteilpreise_alt!G263+4*Artmodul_Einzelteilpreise_alt!G273+4*Artmodul_Einzelteilpreise_alt!G272+4*Artmodul_Einzelteilpreise_alt!G272+Artmodul_Einzelteilpreise_alt!G226 -> 810
C21: 580 | D21: =2*Artmodul_Einzelteilpreise_alt!G4+2*Artmodul_Einzelteilpreise_alt!G18+Artmodul_Einzelteilpreise_alt!G68+8*Artmodul_Einzelteilpreise_alt!G263+4*Artmodul_Einzelteilpreise_alt!G274+4*Artmodul_Einzelteilpreise_alt!G271+4*Artmodul_Einzelteilpreise_alt!G272+Artmodul_Einzelteilpreise_alt!G227 -> 791 | E21: =2*Artmodul_Einzelteilpreise_alt!G4+2*Artmodul_Einzelteilpreise_alt!G19+Artmodul_Einzelteilpreise_alt!G73+8*Artmodul_Einzelteilpreise_alt!G263+4*Artmodul_Einzelteilpreise_alt!G274+4*Artmodul_Einzelteilpreise_alt!G272+4*Artmodul_Einzelteilpreise_alt!G272+Artmodul_Einzelteilpreise_alt!G228 -> 846
C22: 780 | D22: =2*Artmodul_Einzelteilpreise_alt!G5+2*Artmodul_Einzelteilpreise_alt!G18+Artmodul_Einzelteilpreise_alt!G69+8*Artmodul_Einzelteilpreise_alt!G263+4*Artmodul_Einzelteilpreise_alt!G277+4*Artmodul_Einzelteilpreise_alt!G271+4*Artmodul_Einzelteilpreise_alt!G272+Artmodul_Einzelteilpreise_alt!G229 -> 853 | E22: =2*Artmodul_Einzelteilpreise_alt!G5+2*Artmodul_Einzelteilpreise_alt!G19+Artmodul_Einzelteilpreise_alt!G74+8*Artmodul_Einzelteilpreise_alt!G263+4*Artmodul_Einzelteilpreise_alt!G277+4*Artmodul_Einzelteilpreise_alt!G272+4*Artmodul_Einzelteilpreise_alt!G272+Artmodul_Einzelteilpreise_alt!G230 -> 900
C23: 980 | D23: =2*Artmodul_Einzelteilpreise_alt!G6+2*Artmodul_Einzelteilpreise_alt!G18+Artmodul_Einzelteilpreise_alt!G70+8*Artmodul_Einzelteilpreise_alt!G263+4*Artmodul_Einzelteilpreise_alt!G278+4*Artmodul_Einzelteilpreise_alt!G271+4*Artmodul_Einzelteilpreise_alt!G272+Artmodul_Einzelteilpreise_alt!G231 -> 942 | E23: =2*Artmodul_Einzelteilpreise_alt!G6+2*Artmodul_Einzelteilpreise_alt!G19+Artmodul_Einzelteilpreise_alt!G75+8*Artmodul_Einzelteilpreise_alt!G263+4*Artmodul_Einzelteilpreise_alt!G278+4*Artmodul_Einzelteilpreise_alt!G272+4*Artmodul_Einzelteilpreise_alt!G272+Artmodul_Einzelteilpreise_alt!G232 -> 1023
A26: Tiefe 580 mm
A27: Front | B27: Tiefe (mm) | C27: Breite (mm) | D27: H 180 mm | E27: H 360 mm | F27: H 720 mm | G27: H 1080 mm | H27: H 1440 mm | I27: H 1800 mm
A28: Offen | B28: 580 | C28: 420 | D28: =2*Artmodul_Einzelteilpreise_alt!G8+2*Artmodul_Einzelteilpreise_alt!G24+Artmodul_Einzelteilpreise_alt!G67+8*Artmodul_Einzelteilpreise_alt!G263+4*Artmodul_Einzelteilpreise_alt!G273+4*Artmodul_Einzelteilpreise_alt!G271+4*Artmodul_Einzelteilpreise_alt!G274 -> 514 | E28: =2*Artmodul_Einzelteilpreise_alt!G8+2*Artmodul_Einzelteilpreise_alt!G25+Artmodul_Einzelteilpreise_alt!G72+8*Artmodul_Einzelteilpreise_alt!G263+4*Artmodul_Einzelteilpreise_alt!G273+4*Artmodul_Einzelteilpreise_alt!G272+4*Artmodul_Einzelteilpreise_alt!G274 -> 514 | F28: =2*Artmodul_Einzelteilpreise_alt!G8+2*Artmodul_Einzelteilpreise_alt!G26+Artmodul_Einzelteilpreise_alt!G77+8*Artmodul_Einzelteilpreise_alt!G263+4*Artmodul_Einzelteilpreise_alt!G273+4*Artmodul_Einzelteilpreise_alt!G276+4*Artmodul_Einzelteilpreise_alt!G274 -> 638 | G28: =2*Artmodul_Einzelteilpreise_alt!G8+2*Artmodul_Einzelteilpreise_alt!G27+Artmodul_Einzelteilpreise_alt!G82+8*Artmodul_Einzelteilpreise_alt!G263+4*Artmodul_Einzelteilpreise_alt!G273+4*Artmodul_Einzelteilpreise_alt!G279+4*Artmodul_Einzelteilpreise_alt!G274 -> 756 | H28: =2*Artmodul_Einzelteilpreise_alt!G8+2*Artmodul_Einzelteilpreise_alt!G28+Artmodul_Einzelteilpreise_alt!G87+8*Artmodul_Einzelteilpreise_alt!G263+4*Artmodul_Einzelteilpreise_alt!G273+4*Artmodul_Einzelteilpreise_alt!G280+4*Artmodul_Einzelteilpreise_alt!G274 -> 885 | I28: =2*Artmodul_Einzelteilpreise_alt!G8+2*Artmodul_Einzelteilpreise_alt!G29+Artmodul_Einzelteilpreise_alt!G92+8*Artmodul_Einzelteilpreise_alt!G263+4*Artmodul_Einzelteilpreise_alt!G273+4*Artmodul_Einzelteilpreise_alt!G281+4*Artmodul_Einzelteilpreise_alt!G274 -> 1007
C29: 580 | D29: =2*Artmodul_Einzelteilpreise_alt!G9+2*Artmodul_Einzelteilpreise_alt!G24+Artmodul_Einzelteilpreise_alt!G68+8*Artmodul_Einzelteilpreise_alt!G263+4*Artmodul_Einzelteilpreise_alt!G274+4*Artmodul_Einzelteilpreise_alt!G271+4*Artmodul_Einzelteilpreise_alt!G274 -> 567 | E29: =2*Artmodul_Einzelteilpreise_alt!G9+2*Artmodul_Einzelteilpreise_alt!G25+Artmodul_Einzelteilpreise_alt!G73+8*Artmodul_Einzelteilpreise_alt!G263+4*Artmodul_Einzelteilpreise_alt!G274+4*Artmodul_Einzelteilpreise_alt!G272+4*Artmodul_Einzelteilpreise_alt!G274 -> 567 | F29: =2*Artmodul_Einzelteilpreise_alt!G9+2*Artmodul_Einzelteilpreise_alt!G26+Artmodul_Einzelteilpreise_alt!G78+8*Artmodul_Einzelteilpreise_alt!G263+4*Artmodul_Einzelteilpreise_alt!G274+4*Artmodul_Einzelteilpreise_alt!G276+4*Artmodul_Einzelteilpreise_alt!G274 -> 704 | G29: =2*Artmodul_Einzelteilpreise_alt!G9+2*Artmodul_Einzelteilpreise_alt!G27+Artmodul_Einzelteilpreise_alt!G83+8*Artmodul_Einzelteilpreise_alt!G263+4*Artmodul_Einzelteilpreise_alt!G274+4*Artmodul_Einzelteilpreise_alt!G279+4*Artmodul_Einzelteilpreise_alt!G274 -> 831 | H29: =2*Artmodul_Einzelteilpreise_alt!G9+2*Artmodul_Einzelteilpreise_alt!G28+Artmodul_Einzelteilpreise_alt!G88+8*Artmodul_Einzelteilpreise_alt!G263+4*Artmodul_Einzelteilpreise_alt!G274+4*Artmodul_Einzelteilpreise_alt!G280+4*Artmodul_Einzelteilpreise_alt!G274 -> 972 | I29: =2*Artmodul_Einzelteilpreise_alt!G9+2*Artmodul_Einzelteilpreise_alt!G29+Artmodul_Einzelteilpreise_alt!G93+8*Artmodul_Einzelteilpreise_alt!G263+4*Artmodul_Einzelteilpreise_alt!G274+4*Artmodul_Einzelteilpreise_alt!G281+4*Artmodul_Einzelteilpreise_alt!G274 -> 1105
C30: 780 | D30: =2*Artmodul_Einzelteilpreise_alt!G10+2*Artmodul_Einzelteilpreise_alt!G24+Artmodul_Einzelteilpreise_alt!G69+8*Artmodul_Einzelteilpreise_alt!G263+4*Artmodul_Einzelteilpreise_alt!G277+4*Artmodul_Einzelteilpreise_alt!G271+4*Artmodul_Einzelteilpreise_alt!G274 -> 632 | E30: =2*Artmodul_Einzelteilpreise_alt!G10+2*Artmodul_Einzelteilpreise_alt!G25+Artmodul_Einzelteilpreise_alt!G74+8*Artmodul_Einzelteilpreise_alt!G263+4*Artmodul_Einzelteilpreise_alt!G277+4*Artmodul_Einzelteilpreise_alt!G272+4*Artmodul_Einzelteilpreise_alt!G274 -> 632 | F30: =2*Artmodul_Einzelteilpreise_alt!G10+2*Artmodul_Einzelteilpreise_alt!G26+Artmodul_Einzelteilpreise_alt!G79+8*Artmodul_Einzelteilpreise_alt!G263+4*Artmodul_Einzelteilpreise_alt!G277+4*Artmodul_Einzelteilpreise_alt!G276+4*Artmodul_Einzelteilpreise_alt!G274 -> 781 | G30: =2*Artmodul_Einzelteilpreise_alt!G10+2*Artmodul_Einzelteilpreise_alt!G27+Artmodul_Einzelteilpreise_alt!G84+8*Artmodul_Einzelteilpreise_alt!G263+4*Artmodul_Einzelteilpreise_alt!G277+4*Artmodul_Einzelteilpreise_alt!G279+4*Artmodul_Einzelteilpreise_alt!G274 -> 925 | H30: =2*Artmodul_Einzelteilpreise_alt!G10+2*Artmodul_Einzelteilpreise_alt!G28+Artmodul_Einzelteilpreise_alt!G89+8*Artmodul_Einzelteilpreise_alt!G263+4*Artmodul_Einzelteilpreise_alt!G277+4*Artmodul_Einzelteilpreise_alt!G280+4*Artmodul_Einzelteilpreise_alt!G274 -> 1077 | I30: =2*Artmodul_Einzelteilpreise_alt!G10+2*Artmodul_Einzelteilpreise_alt!G29+Artmodul_Einzelteilpreise_alt!G94+8*Artmodul_Einzelteilpreise_alt!G263+4*Artmodul_Einzelteilpreise_alt!G277+4*Artmodul_Einzelteilpreise_alt!G281+4*Artmodul_Einzelteilpreise_alt!G274 -> 1224
C31: 980 | D31: =2*Artmodul_Einzelteilpreise_alt!G11+2*Artmodul_Einzelteilpreise_alt!G24+Artmodul_Einzelteilpreise_alt!G70+8*Artmodul_Einzelteilpreise_alt!G263+4*Artmodul_Einzelteilpreise_alt!G278+4*Artmodul_Einzelteilpreise_alt!G271+4*Artmodul_Einzelteilpreise_alt!G274 -> 700 | E31: =2*Artmodul_Einzelteilpreise_alt!G11+2*Artmodul_Einzelteilpreise_alt!G25+Artmodul_Einzelteilpreise_alt!G75+8*Artmodul_Einzelteilpreise_alt!G263+4*Artmodul_Einzelteilpreise_alt!G278+4*Artmodul_Einzelteilpreise_alt!G272+4*Artmodul_Einzelteilpreise_alt!G274 -> 700 | F31: =2*Artmodul_Einzelteilpreise_alt!G11+2*Artmodul_Einzelteilpreise_alt!G26+Artmodul_Einzelteilpreise_alt!G80+8*Artmodul_Einzelteilpreise_alt!G263+4*Artmodul_Einzelteilpreise_alt!G278+4*Artmodul_Einzelteilpreise_alt!G276+4*Artmodul_Einzelteilpreise_alt!G274 -> 862 | G31: =2*Artmodul_Einzelteilpreise_alt!G11+2*Artmodul_Einzelteilpreise_alt!G27+Artmodul_Einzelteilpreise_alt!G85+8*Artmodul_Einzelteilpreise_alt!G263+4*Artmodul_Einzelteilpreise_alt!G278+4*Artmodul_Einzelteilpreise_alt!G279+4*Artmodul_Einzelteilpreise_alt!G274 -> 1018 | H31: =2*Artmodul_Einzelteilpreise_alt!G11+2*Artmodul_Einzelteilpreise_alt!G28+Artmodul_Einzelteilpreise_alt!G90+8*Artmodul_Einzelteilpreise_alt!G263+4*Artmodul_Einzelteilpreise_alt!G278+4*Artmodul_Einzelteilpreise_alt!G280+4*Artmodul_Einzelteilpreise_alt!G274 -> 1184 | I31: =2*Artmodul_Einzelteilpreise_alt!G11+2*Artmodul_Einzelteilpreise_alt!G29+Artmodul_Einzelteilpreise_alt!G95+8*Artmodul_Einzelteilpreise_alt!G263+4*Artmodul_Einzelteilpreise_alt!G278+4*Artmodul_Einzelteilpreise_alt!G281+4*Artmodul_Einzelteilpreise_alt!G274 -> 1343
A33: Klappe | B33: 580 | C33: 420 | D33: =2*Artmodul_Einzelteilpreise_alt!G8+2*Artmodul_Einzelteilpreise_alt!G24+Artmodul_Einzelteilpreise_alt!G67+8*Artmodul_Einzelteilpreise_alt!G263+4*Artmodul_Einzelteilpreise_alt!G273+4*Artmodul_Einzelteilpreise_alt!G271+4*Artmodul_Einzelteilpreise_alt!G274+Artmodul_Einzelteilpreise_alt!G191 -> 683 | E33: =2*Artmodul_Einzelteilpreise_alt!G8+2*Artmodul_Einzelteilpreise_alt!G25+Artmodul_Einzelteilpreise_alt!G72+8*Artmodul_Einzelteilpreise_alt!G263+4*Artmodul_Einzelteilpreise_alt!G273+4*Artmodul_Einzelteilpreise_alt!G272+4*Artmodul_Einzelteilpreise_alt!G274+Artmodul_Einzelteilpreise_alt!G192 -> 683
C34: 580 | D34: =2*Artmodul_Einzelteilpreise_alt!G9+2*Artmodul_Einzelteilpreise_alt!G24+Artmodul_Einzelteilpreise_alt!G68+8*Artmodul_Einzelteilpreise_alt!G263+4*Artmodul_Einzelteilpreise_alt!G274+4*Artmodul_Einzelteilpreise_alt!G271+4*Artmodul_Einzelteilpreise_alt!G274+Artmodul_Einzelteilpreise_alt!G193 -> 751 | E34: =2*Artmodul_Einzelteilpreise_alt!G9+2*Artmodul_Einzelteilpreise_alt!G25+Artmodul_Einzelteilpreise_alt!G73+8*Artmodul_Einzelteilpreise_alt!G263+4*Artmodul_Einzelteilpreise_alt!G274+4*Artmodul_Einzelteilpreise_alt!G272+4*Artmodul_Einzelteilpreise_alt!G274+Artmodul_Einzelteilpreise_alt!G194 -> 751
C35: 780 | D35: =2*Artmodul_Einzelteilpreise_alt!G10+2*Artmodul_Einzelteilpreise_alt!G24+Artmodul_Einzelteilpreise_alt!G69+8*Artmodul_Einzelteilpreise_alt!G263+4*Artmodul_Einzelteilpreise_alt!G277+4*Artmodul_Einzelteilpreise_alt!G271+4*Artmodul_Einzelteilpreise_alt!G274+Artmodul_Einzelteilpreise_alt!G195 -> 830 | E35: =2*Artmodul_Einzelteilpreise_alt!G10+2*Artmodul_Einzelteilpreise_alt!G25+Artmodul_Einzelteilpreise_alt!G74+8*Artmodul_Einzelteilpreise_alt!G263+4*Artmodul_Einzelteilpreise_alt!G277+4*Artmodul_Einzelteilpreise_alt!G272+4*Artmodul_Einzelteilpreise_alt!G274+Artmodul_Einzelteilpreise_alt!G196 -> 830
C36: 980 | D36: =2*Artmodul_Einzelteilpreise_alt!G11+2*Artmodul_Einzelteilpreise_alt!G24+Artmodul_Einzelteilpreise_alt!G70+8*Artmodul_Einzelteilpreise_alt!G263+4*Artmodul_Einzelteilpreise_alt!G278+4*Artmodul_Einzelteilpreise_alt!G271+4*Artmodul_Einzelteilpreise_alt!G274+Artmodul_Einzelteilpreise_alt!G197 -> 950 | E36: =2*Artmodul_Einzelteilpreise_alt!G11+2*Artmodul_Einzelteilpreise_alt!G25+Artmodul_Einzelteilpreise_alt!G75+8*Artmodul_Einzelteilpreise_alt!G263+4*Artmodul_Einzelteilpreise_alt!G278+4*Artmodul_Einzelteilpreise_alt!G272+4*Artmodul_Einzelteilpreise_alt!G274+Artmodul_Einzelteilpreise_alt!G198 -> 950
A38: Tür | B38: 580 | C38: 420 | E38: =2*Artmodul_Einzelteilpreise_alt!G8+2*Artmodul_Einzelteilpreise_alt!G25+Artmodul_Einzelteilpreise_alt!G72+8*Artmodul_Einzelteilpreise_alt!G263+4*Artmodul_Einzelteilpreise_alt!G273+4*Artmodul_Einzelteilpreise_alt!G272+4*Artmodul_Einzelteilpreise_alt!G274+Artmodul_Einzelteilpreise_alt!G202 -> 650 | F38: =2*Artmodul_Einzelteilpreise_alt!G8+2*Artmodul_Einzelteilpreise_alt!G26+Artmodul_Einzelteilpreise_alt!G77+8*Artmodul_Einzelteilpreise_alt!G263+4*Artmodul_Einzelteilpreise_alt!G273+4*Artmodul_Einzelteilpreise_alt!G276+4*Artmodul_Einzelteilpreise_alt!G274+Artmodul_Einzelteilpreise_alt!G203 -> 797 | G38: =2*Artmodul_Einzelteilpreise_alt!G8+2*Artmodul_Einzelteilpreise_alt!G27+Artmodul_Einzelteilpreise_alt!G82+8*Artmodul_Einzelteilpreise_alt!G263+4*Artmodul_Einzelteilpreise_alt!G273+4*Artmodul_Einzelteilpreise_alt!G279+4*Artmodul_Einzelteilpreise_alt!G274+Artmodul_Einzelteilpreise_alt!G204 -> 991 | H38: =2*Artmodul_Einzelteilpreise_alt!G8+2*Artmodul_Einzelteilpreise_alt!G28+Artmodul_Einzelteilpreise_alt!G87+8*Artmodul_Einzelteilpreise_alt!G263+4*Artmodul_Einzelteilpreise_alt!G273+4*Artmodul_Einzelteilpreise_alt!G280+4*Artmodul_Einzelteilpreise_alt!G274+Artmodul_Einzelteilpreise_alt!G205 -> 1142 | I38: =2*Artmodul_Einzelteilpreise_alt!G8+2*Artmodul_Einzelteilpreise_alt!G29+Artmodul_Einzelteilpreise_alt!G92+8*Artmodul_Einzelteilpreise_alt!G263+4*Artmodul_Einzelteilpreise_alt!G273+4*Artmodul_Einzelteilpreise_alt!G281+4*Artmodul_Einzelteilpreise_alt!G274+Artmodul_Einzelteilpreise_alt!G206 -> 1347
C39: 580 | E39: =2*Artmodul_Einzelteilpreise_alt!G9+2*Artmodul_Einzelteilpreise_alt!G25+Artmodul_Einzelteilpreise_alt!G73+8*Artmodul_Einzelteilpreise_alt!G263+4*Artmodul_Einzelteilpreise_alt!G274+4*Artmodul_Einzelteilpreise_alt!G272+4*Artmodul_Einzelteilpreise_alt!G274+Artmodul_Einzelteilpreise_alt!G207 -> 720 | F39: =2*Artmodul_Einzelteilpreise_alt!G9+2*Artmodul_Einzelteilpreise_alt!G26+Artmodul_Einzelteilpreise_alt!G78+8*Artmodul_Einzelteilpreise_alt!G263+4*Artmodul_Einzelteilpreise_alt!G274+4*Artmodul_Einzelteilpreise_alt!G276+4*Artmodul_Einzelteilpreise_alt!G274+Artmodul_Einzelteilpreise_alt!G208 -> 914 | G39: =2*Artmodul_Einzelteilpreise_alt!G9+2*Artmodul_Einzelteilpreise_alt!G27+Artmodul_Einzelteilpreise_alt!G83+8*Artmodul_Einzelteilpreise_alt!G263+4*Artmodul_Einzelteilpreise_alt!G274+4*Artmodul_Einzelteilpreise_alt!G279+4*Artmodul_Einzelteilpreise_alt!G274+Artmodul_Einzelteilpreise_alt!G209 -> 1109 | H39: =2*Artmodul_Einzelteilpreise_alt!G9+2*Artmodul_Einzelteilpreise_alt!G28+Artmodul_Einzelteilpreise_alt!G88+8*Artmodul_Einzelteilpreise_alt!G263+4*Artmodul_Einzelteilpreise_alt!G274+4*Artmodul_Einzelteilpreise_alt!G280+4*Artmodul_Einzelteilpreise_alt!G274+Artmodul_Einzelteilpreise_alt!G210 -> 1309 | I39: =2*Artmodul_Einzelteilpreise_alt!G9+2*Artmodul_Einzelteilpreise_alt!G29+Artmodul_Einzelteilpreise_alt!G93+8*Artmodul_Einzelteilpreise_alt!G263+4*Artmodul_Einzelteilpreise_alt!G274+4*Artmodul_Einzelteilpreise_alt!G281+4*Artmodul_Einzelteilpreise_alt!G274+Artmodul_Einzelteilpreise_alt!G211 -> 1522
C40: 780 | E40: =2*Artmodul_Einzelteilpreise_alt!G10+2*Artmodul_Einzelteilpreise_alt!G25+Artmodul_Einzelteilpreise_alt!G74+8*Artmodul_Einzelteilpreise_alt!G263+4*Artmodul_Einzelteilpreise_alt!G277+4*Artmodul_Einzelteilpreise_alt!G272+4*Artmodul_Einzelteilpreise_alt!G274+Artmodul_Einzelteilpreise_alt!G214 -> 887 | F40: =2*Artmodul_Einzelteilpreise_alt!G10+2*Artmodul_Einzelteilpreise_alt!G26+Artmodul_Einzelteilpreise_alt!G79+8*Artmodul_Einzelteilpreise_alt!G263+4*Artmodul_Einzelteilpreise_alt!G277+4*Artmodul_Einzelteilpreise_alt!G276+4*Artmodul_Einzelteilpreise_alt!G274+Artmodul_Einzelteilpreise_alt!G216 -> 1095 | G40: =2*Artmodul_Einzelteilpreise_alt!G10+2*Artmodul_Einzelteilpreise_alt!G27+Artmodul_Einzelteilpreise_alt!G84+8*Artmodul_Einzelteilpreise_alt!G263+4*Artmodul_Einzelteilpreise_alt!G277+4*Artmodul_Einzelteilpreise_alt!G279+4*Artmodul_Einzelteilpreise_alt!G274+Artmodul_Einzelteilpreise_alt!G217 -> 1389 | H40: =2*Artmodul_Einzelteilpreise_alt!G10+2*Artmodul_Einzelteilpreise_alt!G28+Artmodul_Einzelteilpreise_alt!G89+8*Artmodul_Einzelteilpreise_alt!G263+4*Artmodul_Einzelteilpreise_alt!G277+4*Artmodul_Einzelteilpreise_alt!G280+4*Artmodul_Einzelteilpreise_alt!G274+Artmodul_Einzelteilpreise_alt!G218 -> 1619 | I40: =2*Artmodul_Einzelteilpreise_alt!G10+2*Artmodul_Einzelteilpreise_alt!G29+Artmodul_Einzelteilpreise_alt!G94+8*Artmodul_Einzelteilpreise_alt!G263+4*Artmodul_Einzelteilpreise_alt!G277+4*Artmodul_Einzelteilpreise_alt!G281+4*Artmodul_Einzelteilpreise_alt!G274+Artmodul_Einzelteilpreise_alt!G219 -> 1892
C41: 980 | E41: =2*Artmodul_Einzelteilpreise_alt!G11+2*Artmodul_Einzelteilpreise_alt!G25+Artmodul_Einzelteilpreise_alt!G75+8*Artmodul_Einzelteilpreise_alt!G263+4*Artmodul_Einzelteilpreise_alt!G278+4*Artmodul_Einzelteilpreise_alt!G272+4*Artmodul_Einzelteilpreise_alt!G274+Artmodul_Einzelteilpreise_alt!G220 -> 969 | F41: =2*Artmodul_Einzelteilpreise_alt!G11+2*Artmodul_Einzelteilpreise_alt!G26+Artmodul_Einzelteilpreise_alt!G80+8*Artmodul_Einzelteilpreise_alt!G263+4*Artmodul_Einzelteilpreise_alt!G278+4*Artmodul_Einzelteilpreise_alt!G276+4*Artmodul_Einzelteilpreise_alt!G274+Artmodul_Einzelteilpreise_alt!G221 -> 1237 | G41: =2*Artmodul_Einzelteilpreise_alt!G11+2*Artmodul_Einzelteilpreise_alt!G27+Artmodul_Einzelteilpreise_alt!G85+8*Artmodul_Einzelteilpreise_alt!G263+4*Artmodul_Einzelteilpreise_alt!G278+4*Artmodul_Einzelteilpreise_alt!G279+4*Artmodul_Einzelteilpreise_alt!G274+Artmodul_Einzelteilpreise_alt!G222 -> 1541 | H41: =2*Artmodul_Einzelteilpreise_alt!G11+2*Artmodul_Einzelteilpreise_alt!G28+Artmodul_Einzelteilpreise_alt!G90+8*Artmodul_Einzelteilpreise_alt!G263+4*Artmodul_Einzelteilpreise_alt!G278+4*Artmodul_Einzelteilpreise_alt!G280+4*Artmodul_Einzelteilpreise_alt!G274+Artmodul_Einzelteilpreise_alt!G223 -> 1809 | I41: =2*Artmodul_Einzelteilpreise_alt!G11+2*Artmodul_Einzelteilpreise_alt!G29+Artmodul_Einzelteilpreise_alt!G95+8*Artmodul_Einzelteilpreise_alt!G263+4*Artmodul_Einzelteilpreise_alt!G278+4*Artmodul_Einzelteilpreise_alt!G281+4*Artmodul_Einzelteilpreise_alt!G274+Artmodul_Einzelteilpreise_alt!G224 -> 2112
A43: Schublade | B43: 580 | C43: 420 | D43: =2*Artmodul_Einzelteilpreise_alt!G8+2*Artmodul_Einzelteilpreise_alt!G24+Artmodul_Einzelteilpreise_alt!G67+8*Artmodul_Einzelteilpreise_alt!G263+4*Artmodul_Einzelteilpreise_alt!G273+4*Artmodul_Einzelteilpreise_alt!G271+4*Artmodul_Einzelteilpreise_alt!G274+Artmodul_Einzelteilpreise_alt!G225 -> 799 | E43: =2*Artmodul_Einzelteilpreise_alt!G8+2*Artmodul_Einzelteilpreise_alt!G25+Artmodul_Einzelteilpreise_alt!G72+8*Artmodul_Einzelteilpreise_alt!G263+4*Artmodul_Einzelteilpreise_alt!G273+4*Artmodul_Einzelteilpreise_alt!G272+4*Artmodul_Einzelteilpreise_alt!G274+Artmodul_Einzelteilpreise_alt!G226 -> 866
C44: 580 | D44: =2*Artmodul_Einzelteilpreise_alt!G9+2*Artmodul_Einzelteilpreise_alt!G24+Artmodul_Einzelteilpreise_alt!G68+8*Artmodul_Einzelteilpreise_alt!G263+4*Artmodul_Einzelteilpreise_alt!G274+4*Artmodul_Einzelteilpreise_alt!G271+4*Artmodul_Einzelteilpreise_alt!G274+Artmodul_Einzelteilpreise_alt!G227 -> 865 | E44: =2*Artmodul_Einzelteilpreise_alt!G9+2*Artmodul_Einzelteilpreise_alt!G25+Artmodul_Einzelteilpreise_alt!G73+8*Artmodul_Einzelteilpreise_alt!G263+4*Artmodul_Einzelteilpreise_alt!G274+4*Artmodul_Einzelteilpreise_alt!G272+4*Artmodul_Einzelteilpreise_alt!G274+Artmodul_Einzelteilpreise_alt!G228 -> 920
C45: 780 | D45: =2*Artmodul_Einzelteilpreise_alt!G10+2*Artmodul_Einzelteilpreise_alt!G24+Artmodul_Einzelteilpreise_alt!G69+8*Artmodul_Einzelteilpreise_alt!G263+4*Artmodul_Einzelteilpreise_alt!G277+4*Artmodul_Einzelteilpreise_alt!G271+4*Artmodul_Einzelteilpreise_alt!G274+Artmodul_Einzelteilpreise_alt!G229 -> 941 | E45: =2*Artmodul_Einzelteilpreise_alt!G10+2*Artmodul_Einzelteilpreise_alt!G25+Artmodul_Einzelteilpreise_alt!G74+8*Artmodul_Einzelteilpreise_alt!G263+4*Artmodul_Einzelteilpreise_alt!G277+4*Artmodul_Einzelteilpreise_alt!G272+4*Artmodul_Einzelteilpreise_alt!G274+Artmodul_Einzelteilpreise_alt!G230 -> 988
C46: 980 | D46: =2*Artmodul_Einzelteilpreise_alt!G11+2*Artmodul_Einzelteilpreise_alt!G24+Artmodul_Einzelteilpreise_alt!G70+8*Artmodul_Einzelteilpreise_alt!G263+4*Artmodul_Einzelteilpreise_alt!G278+4*Artmodul_Einzelteilpreise_alt!G271+4*Artmodul_Einzelteilpreise_alt!G274+Artmodul_Einzelteilpreise_alt!G231 -> 1048 | E46: =2*Artmodul_Einzelteilpreise_alt!G11+2*Artmodul_Einzelteilpreise_alt!G25+Artmodul_Einzelteilpreise_alt!G75+8*Artmodul_Einzelteilpreise_alt!G263+4*Artmodul_Einzelteilpreise_alt!G278+4*Artmodul_Einzelteilpreise_alt!G272+4*Artmodul_Einzelteilpreise_alt!G274+Artmodul_Einzelteilpreise_alt!G232 -> 1129

Sheet Artmodul_Einzelteilpreise_alt
A1: Art_Nr | B1: Typ | C1: Kategorie | D1: Bezeichnung | E1: Breite_mm | F1: Tiefe_mm | G1: PG1_MDF_EUR | H1: PG2_Alu_EUR | I1: PG3_Furnier_EUR | J1: PG4_Glas_EUR | K1: Warnung | L1: PG1_MDF_CHF | M1: PG2_Alu_CHF | N1: PG3_Furnier_CHF | O1: PG4_Glas_CHF | Q1: KONFIGURATOR EXPORT
A2: 3000 | B2: Platte | C2: Boden | D2: Boden (360x360) | E2: 360 | F2: 360 | G2: 34 | H2: 114 | I2: 89 | J2: 177 | L2: =IF(G2="","",ROUND(G2*1.15,0)) -> 39 | M2: =IF(H2="","",ROUND(H2*1.15,0)) -> 131 | N2: =IF(I2="","",ROUND(I2*1.15,0)) -> 102 | O2: =IF(J2="","",ROUND(J2*1.15,0)) -> 204 | Q2: Datei | R2: Verkaufspreise_V07.xlsx
A3: 3001 | B3: Platte | C3: Boden | D3: Boden (420x360) | E3: 420 | F3: 360 | G3: 34 | H3: 121 | I3: 92 | J3: 178 | L3: =IF(G3="","",ROUND(G3*1.15,0)) -> 39 | M3: =IF(H3="","",ROUND(H3*1.15,0)) -> 139 | N3: =IF(I3="","",ROUND(I3*1.15,0)) -> 106 | O3: =IF(J3="","",ROUND(J3*1.15,0)) -> 205 | Q3: Platten-Artikel | R3: =COUNTIF(B:B,"Platte") -> 258
A4: 3002 | B4: Platte | C4: Boden | D4: Boden (580x360) | E4: 580 | F4: 360 | G4: 43 | H4: 161 | I4: 130 | J4: 185 | L4: =IF(G4="","",ROUND(G4*1.15,0)) -> 49 | M4: =IF(H4="","",ROUND(H4*1.15,0)) -> 185 | N4: =IF(I4="","",ROUND(I4*1.15,0)) -> 150 | O4: =IF(J4="","",ROUND(J4*1.15,0)) -> 213 | Q4: Zubehör-Artikel | R4: =COUNTIF(B:B,"Zubehör") -> 47
A5: 3003 | B5: Platte | C5: Boden | D5: Boden (780x360) | E5: 780 | F5: 360 | G5: 56 | H5: 185 | I5: 144 | J5: 190 | L5: =IF(G5="","",ROUND(G5*1.15,0)) -> 64 | M5: =IF(H5="","",ROUND(H5*1.15,0)) -> 213 | N5: =IF(I5="","",ROUND(I5*1.15,0)) -> 166 | O5: =IF(J5="","",ROUND(J5*1.15,0)) -> 219 | Q5: Duplikate | R5: ✅ 0 – bereinigt
A6: 3004 | B6: Platte | C6: Boden | D6: Boden (980x360) | E6: 980 | F6: 360 | G6: 70 | H6: 223 | I6: 174 | J6: 209 | L6: =IF(G6="","",ROUND(G6*1.15,0)) -> 81 | M6: =IF(H6="","",ROUND(H6*1.15,0)) -> 256 | N6: =IF(I6="","",ROUND(I6*1.15,0)) -> 200 | O6: =IF(J6="","",ROUND(J6*1.15,0)) -> 240 | Q6: Warnungen | R6: =COUNTIF(K:K,"*nicht OK*") -> 10
A7: 3005 | B7: Platte | C7: Boden | D7: Boden (360x580) | E7: 360 | F7: 580 | G7: 43 | H7: 161 | I7: 130 | J7: 185 | L7: =IF(G7="","",ROUND(G7*1.15,0)) -> 49 | M7: =IF(H7="","",ROUND(H7*1.15,0)) -> 185 | N7: =IF(I7="","",ROUND(I7*1.15,0)) -> 150 | O7: =IF(J7="","",ROUND(J7*1.15,0)) -> 213 | Q7: CHF-Faktor | R7: 1.15
A8: 3006 | B8: Platte | C8: Boden | D8: Boden (420x580) | E8: 420 | F8: 580 | G8: 49 | H8: 181 | I8: 147 | J8: 186 | L8: =IF(G8="","",ROUND(G8*1.15,0)) -> 56 | M8: =IF(H8="","",ROUND(H8*1.15,0)) -> 208 | N8: =IF(I8="","",ROUND(I8*1.15,0)) -> 169 | O8: =IF(J8="","",ROUND(J8*1.15,0)) -> 214 | Q8: Preisgruppen | R8: PG1=MDF, PG2=Alu, PG3=Furnier, PG4=Glas
A9: 3007 | B9: Platte | C9: Boden | D9: Boden (580x580) | E9: 580 | F9: 580 | G9: 67 | H9: 228 | I9: 183 | J9: 191 | L9: =IF(G9="","",ROUND(G9*1.15,0)) -> 77 | M9: =IF(H9="","",ROUND(H9*1.15,0)) -> 262 | N9: =IF(I9="","",ROUND(I9*1.15,0)) -> 210 | O9: =IF(J9="","",ROUND(J9*1.15,0)) -> 220
A10: 3008 | B10: Platte | C10: Boden | D10: Boden (780x580) | E10: 780 | F10: 580 | G10: 87 | H10: 275 | I10: 225 | J10: 237 | L10: =IF(G10="","",ROUND(G10*1.15,0)) -> 100 | M10: =IF(H10="","",ROUND(H10*1.15,0)) -> 316 | N10: =IF(I10="","",ROUND(I10*1.15,0)) -> 259 | O10: =IF(J10="","",ROUND(J10*1.15,0)) -> 273
A11: 3009 | B11: Platte | C11: Boden | D11: Boden (980x580) | E11: 980 | F11: 580 | G11: 110 | H11: 355 | I11: 286 | J11: 276 | L11: =IF(G11="","",ROUND(G11*1.15,0)) -> 127 | M11: =IF(H11="","",ROUND(H11*1.15,0)) -> 408 | N11: =IF(I11="","",ROUND(I11*1.15,0)) -> 329 | O11: =IF(J11="","",ROUND(J11*1.15,0)) -> 317
A12: 3010 | B12: Platte | C12: Boden | D12: Boden (780x780) | E12: 780 | F12: 780 | G12: 113 | H12: 302 | I12: 272 | J12: 295 | L12: =IF(G12="","",ROUND(G12*1.15,0)) -> 130 | M12: =IF(H12="","",ROUND(H12*1.15,0)) -> 347 | N12: =IF(I12="","",ROUND(I12*1.15,0)) -> 313 | O12: =IF(J12="","",ROUND(J12*1.15,0)) -> 339
A13: 3011 | B13: Platte | C13: Boden | D13: Boden (980x780) | E13: 980 | F13: 780 | G13: 139 | H13: 416 | I13: 216 | J13: 406 | L13: =IF(G13="","",ROUND(G13*1.15,0)) -> 160 | M13: =IF(H13="","",ROUND(H13*1.15,0)) -> 478 | N13: =IF(I13="","",ROUND(I13*1.15,0)) -> 248 | O13: =IF(J13="","",ROUND(J13*1.15,0)) -> 467
A14: 3012 | B14: Platte | C14: Boden | D14: Boden (980x980) | E14: 980 | F14: 980 | G14: 180 | H14: 496 | I14: 257 | J14: 483 | L14: =IF(G14="","",ROUND(G14*1.15,0)) -> 207 | M14: =IF(H14="","",ROUND(H14*1.15,0)) -> 570 | N14: =IF(I14="","",ROUND(I14*1.15,0)) -> 296 | O14: =IF(J14="","",ROUND(J14*1.15,0)) -> 555
A15: 3013 | B15: Platte | C15: Boden | D15: Boden (420x780) | E15: 420 | F15: 780 | G15: 71 | H15: 219 | I15: 113 | J15: 213 | L15: =IF(G15="","",ROUND(G15*1.15,0)) -> 82 | M15: =IF(H15="","",ROUND(H15*1.15,0)) -> 252 | N15: =IF(I15="","",ROUND(I15*1.15,0)) -> 130 | O15: =IF(J15="","",ROUND(J15*1.15,0)) -> 245
A16: 3014 | B16: Platte | C16: Boden | D16: Boden (420x980) | E16: 420 | F16: 980 | G16: 88 | H16: 247 | I16: 128 | J16: 241 | L16: =IF(G16="","",ROUND(G16*1.15,0)) -> 101 | M16: =IF(H16="","",ROUND(H16*1.15,0)) -> 284 | N16: =IF(I16="","",ROUND(I16*1.15,0)) -> 147 | O16: =IF(J16="","",ROUND(J16*1.15,0)) -> 277
A17: S_0003 | B17: Platte | C17: Boden | D17: Boden (420x420) | E17: 420 | F17: 420 | G17: 56 | H17: 134 | I17: 69 | J17: 130 | L17: =IF(G17="","",ROUND(G17*1.15,0)) -> 64 | M17: =IF(H17="","",ROUND(H17*1.15,0)) -> 154 | N17: =IF(I17="","",ROUND(I17*1.15,0)) -> 79 | O17: =IF(J17="","",ROUND(J17*1.15,0)) -> 150
A18: 3100 | B18: Platte | C18: Seite außen | D18: Seite außen (360x180) | E18: 360 | F18: 180 | G18: 34 | H18: 114 | I18: 89 | J18: 201 | L18: =IF(G18="","",ROUND(G18*1.15,0)) -> 39 | M18: =IF(H18="","",ROUND(H18*1.15,0)) -> 131 | N18: =IF(I18="","",ROUND(I18*1.15,0)) -> 102 | O18: =IF(J18="","",ROUND(J18*1.15,0)) -> 231
A19: 3101 | B19: Platte | C19: Seite außen | D19: Seite außen (360x360) | E19: 360 | F19: 360 | G19: 34 | H19: 114 | I19: 89 | J19: 177 | L19: =IF(G19="","",ROUND(G19*1.15,0)) -> 39 | M19: =IF(H19="","",ROUND(H19*1.15,0)) -> 131 | N19: =IF(I19="","",ROUND(I19*1.15,0)) -> 102 | O19: =IF(J19="","",ROUND(J19*1.15,0)) -> 204
A20: 3102 | B20: Platte | C20: Seite außen | D20: Seite außen (360x720) | E20: 360 | F20: 720 | G20: 52 | H20: 181 | I20: 143 | J20: 212 | L20: =IF(G20="","",ROUND(G20*1.15,0)) -> 60 | M20: =IF(H20="","",ROUND(H20*1.15,0)) -> 208 | N20: =IF(I20="","",ROUND(I20*1.15,0)) -> 164 | O20: =IF(J20="","",ROUND(J20*1.15,0)) -> 244
A21: 3103 | B21: Platte | C21: Seite außen | D21: Seite außen (360x1080) | E21: 360 | F21: 1080 | G21: 76 | H21: 267 | I21: 222 | J21: 240 | L21: =IF(G21="","",ROUND(G21*1.15,0)) -> 87 | M21: =IF(H21="","",ROUND(H21*1.15,0)) -> 307 | N21: =IF(I21="","",ROUND(I21*1.15,0)) -> 255 | O21: =IF(J21="","",ROUND(J21*1.15,0)) -> 276
A22: 3104 | B22: Platte | C22: Seite außen | D22: Seite außen (360x1440) | E22: 360 | F22: 1440 | G22: 100 | H22: 336 | I22: 281 | J22: 529 | L22: =IF(G22="","",ROUND(G22*1.15,0)) -> 115 | M22: =IF(H22="","",ROUND(H22*1.15,0)) -> 386 | N22: =IF(I22="","",ROUND(I22*1.15,0)) -> 323 | O22: =IF(J22="","",ROUND(J22*1.15,0)) -> 608
A23: 3105 | B23: Platte | C23: Seite außen | D23: Seite außen (360x1800) | E23: 360 | F23: 1800 | G23: 125 | H23: 246 | I23: 343 | J23: 645 | L23: =IF(G23="","",ROUND(G23*1.15,0)) -> 144 | M23: =IF(H23="","",ROUND(H23*1.15,0)) -> 283 | N23: =IF(I23="","",ROUND(I23*1.15,0)) -> 394 | O23: =IF(J23="","",ROUND(J23*1.15,0)) -> 742
A24: 3106 | B24: Platte | C24: Seite außen | D24: Seite außen (580x180) | E24: 580 | F24: 180 | G24: 43 | H24: 161 | I24: 130 | J24: 208 | L24: =IF(G24="","",ROUND(G24*1.15,0)) -> 49 | M24: =IF(H24="","",ROUND(H24*1.15,0)) -> 185 | N24: =IF(I24="","",ROUND(I24*1.15,0)) -> 150 | O24: =IF(J24="","",ROUND(J24*1.15,0)) -> 239
A25: 3107 | B25: Platte | C25: Seite außen | D25: Seite außen (580x360) | E25: 580 | F25: 360 | G25: 43 | H25: 161 | I25: 130 | J25: 185 | L25: =IF(G25="","",ROUND(G25*1.15,0)) -> 49 | M25: =IF(H25="","",ROUND(H25*1.15,0)) -> 185 | N25: =IF(I25="","",ROUND(I25*1.15,0)) -> 150 | O25: =IF(J25="","",ROUND(J25*1.15,0)) -> 213
A26: 3108 | B26: Platte | C26: Seite außen | D26: Seite außen (580x720) | E26: 580 | F26: 720 | G26: 82 | H26: 262 | I26: 216 | J26: 245 | L26: =IF(G26="","",ROUND(G26*1.15,0)) -> 94 | M26: =IF(H26="","",ROUND(H26*1.15,0)) -> 301 | N26: =IF(I26="","",ROUND(I26*1.15,0)) -> 248 | O26: =IF(J26="","",ROUND(J26*1.15,0)) -> 282
A27: 3109 | B27: Platte | C27: Seite außen | D27: Seite außen (580x1080) | E27: 580 | F27: 1080 | G27: 119 | H27: 377 | I27: 300 | J27: 307 | L27: =IF(G27="","",ROUND(G27*1.15,0)) -> 137 | M27: =IF(H27="","",ROUND(H27*1.15,0)) -> 434 | N27: =IF(I27="","",ROUND(I27*1.15,0)) -> 345 | O27: =IF(J27="","",ROUND(J27*1.15,0)) -> 353
A28: 3110 | B28: Platte | C28: Seite außen | D28: Seite außen (580x1440) | E28: 580 | F28: 1440 | G28: 158 | H28: 484 | I28: 400 | J28: 752 | L28: =IF(G28="","",ROUND(G28*1.15,0)) -> 182 | M28: =IF(H28="","",ROUND(H28*1.15,0)) -> 557 | N28: =IF(I28="","",ROUND(I28*1.15,0)) -> 460 | O28: =IF(J28="","",ROUND(J28*1.15,0)) -> 865
A29: 3111 | B29: Platte | C29: Seite außen | D29: Seite außen (580x1800) | E29: 580 | F29: 1800 | G29: 197 | H29: 388 | I29: 467 | J29: 879 | L29: =IF(G29="","",ROUND(G29*1.15,0)) -> 227 | M29: =IF(H29="","",ROUND(H29*1.15,0)) -> 446 | N29: =IF(I29="","",ROUND(I29*1.15,0)) -> 537 | O29: =IF(J29="","",ROUND(J29*1.15,0)) -> 1011
... A42: 3124 | B42: Platte | C42: Seite außen | D42: Seite außen (580x580) | E42: 580 | F42: 580 | G42: 67 | H42: 228 | I42: 183 | J42: 191 | L42: =IF(G42="","",ROUND(G42*1.15,0)) -> 77 | M42: =IF(H42="","",ROUND(H42*1.15,0)) -> 262 | N42: =IF(I42="","",ROUND(I42*1.15,0)) -> 210 | O42: =IF(J42="","",ROUND(J42*1.15,0)) -> 220
