Workbook
Name Analyse: #REF!
Name ANZ_Breite: [1]Bestellvorlage_neu!$F$24
Name ANZ_Elemente: [1]Bestellvorlage_neu!$F$27
Name ANZ_Höhe: [1]Bestellvorlage_neu!$F$25
Name ANZ_Tiefe: [1]Bestellvorlage_neu!$F$26
Name Bericht: '[2]Bericht gesamt'!$B$4:$DG$59
Name Einkauf: #REF!
Name Ertragssicherung: #REF!
Name EXT: #REF!
Name F_Doppeltür_PG1: #REF!
Name F_Doppeltür_PG1: #REF!
Name F_Doppeltür_PG2_3: #REF!
Name F_Doppeltür_PG2_3: #REF!
Name F_Doppeltür_PG4: #REF!
Name F_Doppeltür_PG4: #REF!
Name F_Klappe_PG1: #REF!
Name F_Klappe_PG1: #REF!
Name F_Klappe_PG2_3: #REF!
Name F_Klappe_PG2_3: #REF!
Name F_Klappe_PG4: #REF!
Name F_Klappe_PG4: #REF!
Name F_Platten_PG1: #REF!
Name F_Platten_PG1: #REF!
Name F_Platten_PG2_3: #REF!
Name F_Platten_PG2_3: #REF!
Name F_Platten_PG4: #REF!
Name F_Platten_PG4: #REF!
Name F_Schublade_PG1: #REF!
Name F_Schublade_PG1: #REF!
Name F_Schublade_PG2_3: #REF!
Name F_Schublade_PG2_3: #REF!
Name F_Schublade_PG4: #REF!
Name F_Schublade_PG4: #REF!
Name F_Tür_PG1: #REF!
Name F_Tür_PG1: #REF!
Name F_Tür_PG2_3: #REF!
Name F_Tür_PG2_3: #REF!
Name F_Tür_PG4: #REF!
Name F_Tür_PG4: #REF!
Name Freigabe: #REF!
Name Ideen: #REF!
Name Innovations__prozeß: #REF!
Name Komminikation: #REF!
Name Kommunikation: #REF!
Name Kompetenz: #REF!
Name Konfektion: [4]Orga!$U$41:$AF$46
Name Konstruktion: #REF!
Name Kreativpotential: #REF!
Name LPU: #REF!
Name Ludwig: #REF!
Name Marketing: #REF!
Name Organisation: #REF!
Name Preisniveau: #REF!
Name Produkt__und_Preissystematik: #REF!
Name SkriptBeschreibung: #REF!
Name Telephonmarketing: #REF!
Name TEST: #REF!
Name Tiefe: [1]Bestellvorlage_neu!$C$4
Name Umsetzung: #REF!
Name Vertrieb: [4]Orga!$U$48:$AE$56

Sheet Preislisten
B1: EURO | J1: CHF | R1: Auchschlag CHF | T1: PG1 | U1: PG2 | V1: PG3 | W1: PG4
R2: 0.15 | T2: MDF | U2: Alu | V2: Furnier | W2: Glas
B3: Panel | C3: Art. Nr. | D3: Breite / Tiefe | E3: PG1 | F3: PG2 | G3: PG3 | H3: PG4 | J3: Panel | K3: Art. Nr. | L3: Breite / Tiefe | M3: PG1 | N3: PG2 | O3: PG3 | P3: PG4
B4: Boden | C4: 3000 | D4: =VLOOKUP($C4,Kalkulation_Platten!$C$6:$F$611,3,FALSE)&" / "&VLOOKUP($C4,Kalkulation_Platten!$C$6:$F$611,4,FALSE) -> 360 / 360 | E4: =INDEX(Kalkulation_Platten!$C$3:$AM$1001,MATCH($C4,Kalkulation_Platten!$C$3:$C$1001,0),MATCH(E$3,Kalkulation_Platten!$C$3:$AM$3,0)) -> 34 | F4: =INDEX(Kalkulation_Platten!$C$3:$AM$1001,MATCH($C4,Kalkulation_Platten!$C$3:$C$1001,0),MATCH(F$3,Kalkulation_Platten!$C$3:$AM$3,0)) -> 114 | G4: =INDEX(Kalkulation_Platten!$C$3:$AM$1001,MATCH($C4,Kalkulation_Platten!$C$3:$C$1001,0),MATCH(G$3,Kalkulation_Platten!$C$3:$AM$3,0)) -> 89 | H4: =INDEX(Kalkulation_Platten!$C$3:$AM$1001,MATCH($C4,Kalkulation_Platten!$C$3:$C$1001,0),MATCH(H$3,Kalkulation_Platten!$C$3:$AM$3,0)) -> 177 | J4: Boden | K4: 3000 | L4: =VLOOKUP($C4,Kalkulation_Platten!$C$6:$F$611,3,FALSE)&" / "&VLOOKUP($C4,Kalkulation_Platten!$C$6:$F$611,4,FALSE) -> 360 / 360 | M4: =IFERROR(ROUND(E4*(1+$R$2),0),"-") -> 39 | N4: =IFERROR(ROUND(F4*(1+$R$2),0),"-") -> 131 | O4: =IFERROR(ROUND(G4*(1+$R$2),0),"-") -> 102 | P4: =IFERROR(ROUND(H4*(1+$R$2),0),"-") -> 204 | T4: =IFERROR(F4-E4,"") -> 80 | U4: =IFERROR(G4-F4,"") -> -25 | V4: =IFERROR(H4-G4,"") -> 88
B5: Boden | C5: 3001 | D5: =VLOOKUP($C5,Kalkulation_Platten!$C$6:$F$611,3,FALSE)&" / "&VLOOKUP($C5,Kalkulation_Platten!$C$6:$F$611,4,FALSE) -> 420 / 360 | E5: =INDEX(Kalkulation_Platten!$C$3:$AM$1001,MATCH($C5,Kalkulation_Platten!$C$3:$C$1001,0),MATCH(E$3,Kalkulation_Platten!$C$3:$AM$3,0)) -> 34 | F5: =INDEX(Kalkulation_Platten!$C$3:$AM$1001,MATCH($C5,Kalkulation_Platten!$C$3:$C$1001,0),MATCH(F$3,Kalkulation_Platten!$C$3:$AM$3,0)) -> 121 | G5: =INDEX(Kalkulation_Platten!$C$3:$AM$1001,MATCH($C5,Kalkulation_Platten!$C$3:$C$1001,0),MATCH(G$3,Kalkulation_Platten!$C$3:$AM$3,0)) -> 92 | H5: =INDEX(Kalkulation_Platten!$C$3:$AM$1001,MATCH($C5,Kalkulation_Platten!$C$3:$C$1001,0),MATCH(H$3,Kalkulation_Platten!$C$3:$AM$3,0)) -> 178 | J5: Boden | K5: 3001 | L5: =VLOOKUP($C5,Kalkulation_Platten!$C$6:$F$611,3,FALSE)&" / "&VLOOKUP($C5,Kalkulation_Platten!$C$6:$F$611,4,FALSE) -> 420 / 360 | M5: =IFERROR(ROUND(E5*(1+$R$2),0),"-") -> 39 | N5: =IFERROR(ROUND(F5*(1+$R$2),0),"-") -> 139 | O5: =IFERROR(ROUND(G5*(1+$R$2),0),"-") -> 106 | P5: =IFERROR(ROUND(H5*(1+$R$2),0),"-") -> 205 | T5: =IFERROR(F5-E5,"") -> 87 | U5: =IFERROR(G5-F5,"") -> -29 | V5: =IFERROR(H5-G5,"") -> 86
B6: Boden | C6: 3002 | D6: =VLOOKUP($C6,Kalkulation_Platten!$C$6:$F$611,3,FALSE)&" / "&VLOOKUP($C6,Kalkulation_Platten!$C$6:$F$611,4,FALSE) -> 580 / 360 | E6: =INDEX(Kalkulation_Platten!$C$3:$AM$1001,MATCH($C6,Kalkulation_Platten!$C$3:$C$1001,0),MATCH(E$3,Kalkulation_Platten!$C$3:$AM$3,0)) -> 43 | F6: =INDEX(Kalkulation_Platten!$C$3:$AM$1001,MATCH($C6,Kalkulation_Platten!$C$3:$C$1001,0),MATCH(F$3,Kalkulation_Platten!$C$3:$AM$3,0)) -> 161 | G6: =INDEX(Kalkulation_Platten!$C$3:$AM$1001,MATCH($C6,Kalkulation_Platten!$C$3:$C$1001,0),MATCH(G$3,Kalkulation_Platten!$C$3:$AM$3,0)) -> 130 | H6: =INDEX(Kalkulation_Platten!$C$3:$AM$1001,MATCH($C6,Kalkulation_Platten!$C$3:$C$1001,0),MATCH(H$3,Kalkulation_Platten!$C$3:$AM$3,0)) -> 185 | J6: Boden | K6: 3002 | L6: =VLOOKUP($C6,Kalkulation_Platten!$C$6:$F$611,3,FALSE)&" / "&VLOOKUP($C6,Kalkulation_Platten!$C$6:$F$611,4,FALSE) -> 580 / 360 | M6: =IFERROR(ROUND(E6*(1+$R$2),0),"-") -> 49 | N6: =IFERROR(ROUND(F6*(1+$R$2),0),"-") -> 185 | O6: =IFERROR(ROUND(G6*(1+$R$2),0),"-") -> 150 | P6: =IFERROR(ROUND(H6*(1+$R$2),0),"-") -> 213 | T6: =IFERROR(F6-E6,"") -> 118 | U6: =IFERROR(G6-F6,"") -> -31 | V6: =IFERROR(H6-G6,"") -> 55
B7: Boden | C7: 3003 | D7: =VLOOKUP($C7,Kalkulation_Platten!$C$6:$F$611,3,FALSE)&" / "&VLOOKUP($C7,Kalkulation_Platten!$C$6:$F$611,4,FALSE) -> 780 / 360 | E7: =INDEX(Kalkulation_Platten!$C$3:$AM$1001,MATCH($C7,Kalkulation_Platten!$C$3:$C$1001,0),MATCH(E$3,Kalkulation_Platten!$C$3:$AM$3,0)) -> 56 | F7: =INDEX(Kalkulation_Platten!$C$3:$AM$1001,MATCH($C7,Kalkulation_Platten!$C$3:$C$1001,0),MATCH(F$3,Kalkulation_Platten!$C$3:$AM$3,0)) -> 185 | G7: =INDEX(Kalkulation_Platten!$C$3:$AM$1001,MATCH($C7,Kalkulation_Platten!$C$3:$C$1001,0),MATCH(G$3,Kalkulation_Platten!$C$3:$AM$3,0)) -> 144 | H7: =INDEX(Kalkulation_Platten!$C$3:$AM$1001,MATCH($C7,Kalkulation_Platten!$C$3:$C$1001,0),MATCH(H$3,Kalkulation_Platten!$C$3:$AM$3,0)) -> 190 | J7: Boden | K7: 3003 | L7: =VLOOKUP($C7,Kalkulation_Platten!$C$6:$F$611,3,FALSE)&" / "&VLOOKUP($C7,Kalkulation_Platten!$C$6:$F$611,4,FALSE) -> 780 / 360 | M7: =IFERROR(ROUND(E7*(1+$R$2),0),"-") -> 64 | N7: =IFERROR(ROUND(F7*(1+$R$2),0),"-") -> 213 | O7: =IFERROR(ROUND(G7*(1+$R$2),0),"-") -> 166 | P7: =IFERROR(ROUND(H7*(1+$R$2),0),"-") -> 219 | T7: =IFERROR(F7-E7,"") -> 129 | U7: =IFERROR(G7-F7,"") -> -41 | V7: =IFERROR(H7-G7,"") -> 46
B8: Boden | C8: 3004 | D8: =VLOOKUP($C8,Kalkulation_Platten!$C$6:$F$611,3,FALSE)&" / "&VLOOKUP($C8,Kalkulation_Platten!$C$6:$F$611,4,FALSE) -> 980 / 360 | E8: =INDEX(Kalkulation_Platten!$C$3:$AM$1001,MATCH($C8,Kalkulation_Platten!$C$3:$C$1001,0),MATCH(E$3,Kalkulation_Platten!$C$3:$AM$3,0)) -> 70 | F8: =INDEX(Kalkulation_Platten!$C$3:$AM$1001,MATCH($C8,Kalkulation_Platten!$C$3:$C$1001,0),MATCH(F$3,Kalkulation_Platten!$C$3:$AM$3,0)) -> 223 | G8: =INDEX(Kalkulation_Platten!$C$3:$AM$1001,MATCH($C8,Kalkulation_Platten!$C$3:$C$1001,0),MATCH(G$3,Kalkulation_Platten!$C$3:$AM$3,0)) -> 174 | H8: =INDEX(Kalkulation_Platten!$C$3:$AM$1001,MATCH($C8,Kalkulation_Platten!$C$3:$C$1001,0),MATCH(H$3,Kalkulation_Platten!$C$3:$AM$3,0)) -> 209 | J8: Boden | K8: 3004 | L8: =VLOOKUP($C8,Kalkulation_Platten!$C$6:$F$611,3,FALSE)&" / "&VLOOKUP($C8,Kalkulation_Platten!$C$6:$F$611,4,FALSE) -> 980 / 360 | M8: =IFERROR(ROUND(E8*(1+$R$2),0),"-") -> 81 | N8: =IFERROR(ROUND(F8*(1+$R$2),0),"-") -> 256 | O8: =IFERROR(ROUND(G8*(1+$R$2),0),"-") -> 200 | P8: =IFERROR(ROUND(H8*(1+$R$2),0),"-") -> 240 | T8: =IFERROR(F8-E8,"") -> 153 | U8: =IFERROR(G8-F8,"") -> -49 | V8: =IFERROR(H8-G8,"") -> 35
B9: Boden | C9: 3005 | D9: =VLOOKUP($C9,Kalkulation_Platten!$C$6:$F$611,3,FALSE)&" / "&VLOOKUP($C9,Kalkulation_Platten!$C$6:$F$611,4,FALSE) -> 360 / 580 | E9: =INDEX(Kalkulation_Platten!$C$3:$AM$1001,MATCH($C9,Kalkulation_Platten!$C$3:$C$1001,0),MATCH(E$3,Kalkulation_Platten!$C$3:$AM$3,0)) -> 43 | F9: =INDEX(Kalkulation_Platten!$C$3:$AM$1001,MATCH($C9,Kalkulation_Platten!$C$3:$C$1001,0),MATCH(F$3,Kalkulation_Platten!$C$3:$AM$3,0)) -> 161 | G9: =INDEX(Kalkulation_Platten!$C$3:$AM$1001,MATCH($C9,Kalkulation_Platten!$C$3:$C$1001,0),MATCH(G$3,Kalkulation_Platten!$C$3:$AM$3,0)) -> 130 | H9: =INDEX(Kalkulation_Platten!$C$3:$AM$1001,MATCH($C9,Kalkulation_Platten!$C$3:$C$1001,0),MATCH(H$3,Kalkulation_Platten!$C$3:$AM$3,0)) -> 185 | J9: Boden | K9: 3005 | L9: 580 / 360 | M9: =IFERROR(ROUND(E9*(1+$R$2),0),"-") -> 49 | N9: =IFERROR(ROUND(F9*(1+$R$2),0),"-") -> 185 | O9: =IFERROR(ROUND(G9*(1+$R$2),0),"-") -> 150 | P9: =IFERROR(ROUND(H9*(1+$R$2),0),"-") -> 213 | T9: =IFERROR(F9-E9,"") -> 118 | U9: =IFERROR(G9-F9,"") -> -31 | V9: =IFERROR(H9-G9,"") -> 55
B10: Boden | C10: 3006 | D10: =VLOOKUP($C10,Kalkulation_Platten!$C$6:$F$611,3,FALSE)&" / "&VLOOKUP($C10,Kalkulation_Platten!$C$6:$F$611,4,FALSE) -> 420 / 580 | E10: =INDEX(Kalkulation_Platten!$C$3:$AM$1001,MATCH($C10,Kalkulation_Platten!$C$3:$C$1001,0),MATCH(E$3,Kalkulation_Platten!$C$3:$AM$3,0)) -> 49 | F10: =INDEX(Kalkulation_Platten!$C$3:$AM$1001,MATCH($C10,Kalkulation_Platten!$C$3:$C$1001,0),MATCH(F$3,Kalkulation_Platten!$C$3:$AM$3,0)) -> 181 | G10: =INDEX(Kalkulation_Platten!$C$3:$AM$1001,MATCH($C10,Kalkulation_Platten!$C$3:$C$1001,0),MATCH(G$3,Kalkulation_Platten!$C$3:$AM$3,0)) -> 147 | H10: =INDEX(Kalkulation_Platten!$C$3:$AM$1001,MATCH($C10,Kalkulation_Platten!$C$3:$C$1001,0),MATCH(H$3,Kalkulation_Platten!$C$3:$AM$3,0)) -> 186 | J10: Boden | K10: 3006 | L10: =VLOOKUP($C10,Kalkulation_Platten!$C$6:$F$611,3,FALSE)&" / "&VLOOKUP($C10,Kalkulation_Platten!$C$6:$F$611,4,FALSE) -> 420 / 580 | M10: =IFERROR(ROUND(E10*(1+$R$2),0),"-") -> 56 | N10: =IFERROR(ROUND(F10*(1+$R$2),0),"-") -> 208 | O10: =IFERROR(ROUND(G10*(1+$R$2),0),"-") -> 169 | P10: =IFERROR(ROUND(H10*(1+$R$2),0),"-") -> 214 | T10: =IFERROR(F10-E10,"") -> 132 | U10: =IFERROR(G10-F10,"") -> -34 | V10: =IFERROR(H10-G10,"") -> 39
B11: Boden | C11: 3007 | D11: =VLOOKUP($C11,Kalkulation_Platten!$C$6:$F$611,3,FALSE)&" / "&VLOOKUP($C11,Kalkulation_Platten!$C$6:$F$611,4,FALSE) -> 580 / 580 | E11: =INDEX(Kalkulation_Platten!$C$3:$AM$1001,MATCH($C11,Kalkulation_Platten!$C$3:$C$1001,0),MATCH(E$3,Kalkulation_Platten!$C$3:$AM$3,0)) -> 67 | F11: =INDEX(Kalkulation_Platten!$C$3:$AM$1001,MATCH($C11,Kalkulation_Platten!$C$3:$C$1001,0),MATCH(F$3,Kalkulation_Platten!$C$3:$AM$3,0)) -> 228 | G11: =INDEX(Kalkulation_Platten!$C$3:$AM$1001,MATCH($C11,Kalkulation_Platten!$C$3:$C$1001,0),MATCH(G$3,Kalkulation_Platten!$C$3:$AM$3,0)) -> 183 | H11: =INDEX(Kalkulation_Platten!$C$3:$AM$1001,MATCH($C11,Kalkulation_Platten!$C$3:$C$1001,0),MATCH(H$3,Kalkulation_Platten!$C$3:$AM$3,0)) -> 191 | J11: Boden | K11: 3007 | L11: =VLOOKUP($C11,Kalkulation_Platten!$C$6:$F$611,3,FALSE)&" / "&VLOOKUP($C11,Kalkulation_Platten!$C$6:$F$611,4,FALSE) -> 580 / 580 | M11: =IFERROR(ROUND(E11*(1+$R$2),0),"-") -> 77 | N11: =IFERROR(ROUND(F11*(1+$R$2),0),"-") -> 262 | O11: =IFERROR(ROUND(G11*(1+$R$2),0),"-") -> 210 | P11: =IFERROR(ROUND(H11*(1+$R$2),0),"-") -> 220 | T11: =IFERROR(F11-E11,"") -> 161 | U11: =IFERROR(G11-F11,"") -> -45 | V11: =IFERROR(H11-G11,"") -> 8
B12: Boden | C12: 3008 | D12: =VLOOKUP($C12,Kalkulation_Platten!$C$6:$F$611,3,FALSE)&" / "&VLOOKUP($C12,Kalkulation_Platten!$C$6:$F$611,4,FALSE) -> 780 / 580 | E12: =INDEX(Kalkulation_Platten!$C$3:$AM$1001,MATCH($C12,Kalkulation_Platten!$C$3:$C$1001,0),MATCH(E$3,Kalkulation_Platten!$C$3:$AM$3,0)) -> 87 | F12: =INDEX(Kalkulation_Platten!$C$3:$AM$1001,MATCH($C12,Kalkulation_Platten!$C$3:$C$1001,0),MATCH(F$3,Kalkulation_Platten!$C$3:$AM$3,0)) -> 275 | G12: =INDEX(Kalkulation_Platten!$C$3:$AM$1001,MATCH($C12,Kalkulation_Platten!$C$3:$C$1001,0),MATCH(G$3,Kalkulation_Platten!$C$3:$AM$3,0)) -> 225 | H12: =INDEX(Kalkulation_Platten!$C$3:$AM$1001,MATCH($C12,Kalkulation_Platten!$C$3:$C$1001,0),MATCH(H$3,Kalkulation_Platten!$C$3:$AM$3,0)) -> 237 | J12: Boden | K12: 3008 | L12: =VLOOKUP($C12,Kalkulation_Platten!$C$6:$F$611,3,FALSE)&" / "&VLOOKUP($C12,Kalkulation_Platten!$C$6:$F$611,4,FALSE) -> 780 / 580 | M12: =IFERROR(ROUND(E12*(1+$R$2),0),"-") -> 100 | N12: =IFERROR(ROUND(F12*(1+$R$2),0),"-") -> 316 | O12: =IFERROR(ROUND(G12*(1+$R$2),0),"-") -> 259 | P12: =IFERROR(ROUND(H12*(1+$R$2),0),"-") -> 273 | T12: =IFERROR(F12-E12,"") -> 188 | U12: =IFERROR(G12-F12,"") -> -50 | V12: =IFERROR(H12-G12,"") -> 12
B13: Boden | C13: 3009 | D13: =VLOOKUP($C13,Kalkulation_Platten!$C$6:$F$611,3,FALSE)&" / "&VLOOKUP($C13,Kalkulation_Platten!$C$6:$F$611,4,FALSE) -> 980 / 580 | E13: =INDEX(Kalkulation_Platten!$C$3:$AM$1001,MATCH($C13,Kalkulation_Platten!$C$3:$C$1001,0),MATCH(E$3,Kalkulation_Platten!$C$3:$AM$3,0)) -> 110 | F13: =INDEX(Kalkulation_Platten!$C$3:$AM$1001,MATCH($C13,Kalkulation_Platten!$C$3:$C$1001,0),MATCH(F$3,Kalkulation_Platten!$C$3:$AM$3,0)) -> 355 | G13: =INDEX(Kalkulation_Platten!$C$3:$AM$1001,MATCH($C13,Kalkulation_Platten!$C$3:$C$1001,0),MATCH(G$3,Kalkulation_Platten!$C$3:$AM$3,0)) -> 286 | H13: =INDEX(Kalkulation_Platten!$C$3:$AM$1001,MATCH($C13,Kalkulation_Platten!$C$3:$C$1001,0),MATCH(H$3,Kalkulation_Platten!$C$3:$AM$3,0)) -> 276 | J13: Boden | K13: 3009 | L13: =VLOOKUP($C13,Kalkulation_Platten!$C$6:$F$611,3,FALSE)&" / "&VLOOKUP($C13,Kalkulation_Platten!$C$6:$F$611,4,FALSE) -> 980 / 580 | M13: =IFERROR(ROUND(E13*(1+$R$2),0),"-") -> 127 | N13: =IFERROR(ROUND(F13*(1+$R$2),0),"-") -> 408 | O13: =IFERROR(ROUND(G13*(1+$R$2),0),"-") -> 329 | P13: =IFERROR(ROUND(H13*(1+$R$2),0),"-") -> 317 | T13: =IFERROR(F13-E13,"") -> 245 | U13: =IFERROR(G13-F13,"") -> -69 | V13: =IFERROR(H13-G13,"") -> -10
B14: Boden | C14: 3010 | D14: =VLOOKUP($C14,Kalkulation_Platten!$C$6:$F$611,3,FALSE)&" / "&VLOOKUP($C14,Kalkulation_Platten!$C$6:$F$611,4,FALSE) -> 780 / 780 | E14: =INDEX(Kalkulation_Platten!$C$3:$AM$1001,MATCH($C14,Kalkulation_Platten!$C$3:$C$1001,0),MATCH(E$3,Kalkulation_Platten!$C$3:$AM$3,0)) -> 113 | F14: =INDEX(Kalkulation_Platten!$C$3:$AM$1001,MATCH($C14,Kalkulation_Platten!$C$3:$C$1001,0),MATCH(F$3,Kalkulation_Platten!$C$3:$AM$3,0)) -> 302 | G14: =INDEX(Kalkulation_Platten!$C$3:$AM$1001,MATCH($C14,Kalkulation_Platten!$C$3:$C$1001,0),MATCH(G$3,Kalkulation_Platten!$C$3:$AM$3,0)) -> 272 | H14: =INDEX(Kalkulation_Platten!$C$3:$AM$1001,MATCH($C14,Kalkulation_Platten!$C$3:$C$1001,0),MATCH(H$3,Kalkulation_Platten!$C$3:$AM$3,0)) -> 295 | J14: Boden | K14: 3010 | L14: =VLOOKUP($C14,Kalkulation_Platten!$C$6:$F$611,3,FALSE)&" / "&VLOOKUP($C14,Kalkulation_Platten!$C$6:$F$611,4,FALSE) -> 780 / 780 | M14: =IFERROR(ROUND(E14*(1+$R$2),0),"-") -> 130 | N14: =IFERROR(ROUND(F14*(1+$R$2),0),"-") -> 347 | O14: =IFERROR(ROUND(G14*(1+$R$2),0),"-") -> 313 | P14: =IFERROR(ROUND(H14*(1+$R$2),0),"-") -> 339 | T14: =IFERROR(F14-E14,"") -> 189 | U14: =IFERROR(G14-F14,"") -> -30 | V14: =IFERROR(H14-G14,"") -> 23
B15: Boden | C15: 3011 | D15: =VLOOKUP($C15,Kalkulation_Platten!$C$6:$F$611,3,FALSE)&" / "&VLOOKUP($C15,Kalkulation_Platten!$C$6:$F$611,4,FALSE) -> 980 / 780 | E15: =INDEX(Kalkulation_Platten!$C$3:$AM$1001,MATCH($C15,Kalkulation_Platten!$C$3:$C$1001,0),MATCH(E$3,Kalkulation_Platten!$C$3:$AM$3,0)) -> 139 | F15: =INDEX(Kalkulation_Platten!$C$3:$AM$1001,MATCH($C15,Kalkulation_Platten!$C$3:$C$1001,0),MATCH(F$3,Kalkulation_Platten!$C$3:$AM$3,0)) -> 416 | G15: =INDEX(Kalkulation_Platten!$C$3:$AM$1001,MATCH($C15,Kalkulation_Platten!$C$3:$C$1001,0),MATCH(G$3,Kalkulation_Platten!$C$3:$AM$3,0)) -> 216 | H15: =INDEX(Kalkulation_Platten!$C$3:$AM$1001,MATCH($C15,Kalkulation_Platten!$C$3:$C$1001,0),MATCH(H$3,Kalkulation_Platten!$C$3:$AM$3,0)) -> 406 | J15: Boden | K15: 3011 | L15: =VLOOKUP($C15,Kalkulation_Platten!$C$6:$F$611,3,FALSE)&" / "&VLOOKUP($C15,Kalkulation_Platten!$C$6:$F$611,4,FALSE) -> 980 / 780 | M15: =IFERROR(ROUND(E15*(1+$R$2),0),"-") -> 160 | N15: =IFERROR(ROUND(F15*(1+$R$2),0),"-") -> 478 | O15: =IFERROR(ROUND(G15*(1+$R$2),0),"-") -> 248 | P15: =IFERROR(ROUND(H15*(1+$R$2),0),"-") -> 467 | T15: =IFERROR(F15-E15,"") -> 277 | U15: =IFERROR(G15-F15,"") -> -200 | V15: =IFERROR(H15-G15,"") -> 190
B16: Boden | C16: 3012 | D16: =VLOOKUP($C16,Kalkulation_Platten!$C$6:$F$611,3,FALSE)&" / "&VLOOKUP($C16,Kalkulation_Platten!$C$6:$F$611,4,FALSE) -> 980 / 980 | E16: =INDEX(Kalkulation_Platten!$C$3:$AM$1001,MATCH($C16,Kalkulation_Platten!$C$3:$C$1001,0),MATCH(E$3,Kalkulation_Platten!$C$3:$AM$3,0)) -> 180 | F16: =INDEX(Kalkulation_Platten!$C$3:$AM$1001,MATCH($C16,Kalkulation_Platten!$C$3:$C$1001,0),MATCH(F$3,Kalkulation_Platten!$C$3:$AM$3,0)) -> 496 | G16: =INDEX(Kalkulation_Platten!$C$3:$AM$1001,MATCH($C16,Kalkulation_Platten!$C$3:$C$1001,0),MATCH(G$3,Kalkulation_Platten!$C$3:$AM$3,0)) -> 257 | H16: =INDEX(Kalkulation_Platten!$C$3:$AM$1001,MATCH($C16,Kalkulation_Platten!$C$3:$C$1001,0),MATCH(H$3,Kalkulation_Platten!$C$3:$AM$3,0)) -> 483 | J16: Boden | K16: 3012 | L16: =VLOOKUP($C16,Kalkulation_Platten!$C$6:$F$611,3,FALSE)&" / "&VLOOKUP($C16,Kalkulation_Platten!$C$6:$F$611,4,FALSE) -> 980 / 980 | M16: =IFERROR(ROUND(E16*(1+$R$2),0),"-") -> 207 | N16: =IFERROR(ROUND(F16*(1+$R$2),0),"-") -> 570 | O16: =IFERROR(ROUND(G16*(1+$R$2),0),"-") -> 296 | P16: =IFERROR(ROUND(H16*(1+$R$2),0),"-") -> 555 | T16: =IFERROR(F16-E16,"") -> 316 | U16: =IFERROR(G16-F16,"") -> -239 | V16: =IFERROR(H16-G16,"") -> 226
B17: Boden | C17: 3013 | D17: =VLOOKUP($C17,Kalkulation_Platten!$C$6:$F$611,3,FALSE)&" / "&VLOOKUP($C17,Kalkulation_Platten!$C$6:$F$611,4,FALSE) -> 420 / 780 | E17: =INDEX(Kalkulation_Platten!$C$3:$AM$1001,MATCH($C17,Kalkulation_Platten!$C$3:$C$1001,0),MATCH(E$3,Kalkulation_Platten!$C$3:$AM$3,0)) -> 71 | F17: =INDEX(Kalkulation_Platten!$C$3:$AM$1001,MATCH($C17,Kalkulation_Platten!$C$3:$C$1001,0),MATCH(F$3,Kalkulation_Platten!$C$3:$AM$3,0)) -> 219 | G17: =INDEX(Kalkulation_Platten!$C$3:$AM$1001,MATCH($C17,Kalkulation_Platten!$C$3:$C$1001,0),MATCH(G$3,Kalkulation_Platten!$C$3:$AM$3,0)) -> 113 | H17: =INDEX(Kalkulation_Platten!$C$3:$AM$1001,MATCH($C17,Kalkulation_Platten!$C$3:$C$1001,0),MATCH(H$3,Kalkulation_Platten!$C$3:$AM$3,0)) -> 213 | J17: Boden | K17: 3013 | L17: =VLOOKUP($C17,Kalkulation_Platten!$C$6:$F$611,3,FALSE)&" / "&VLOOKUP($C17,Kalkulation_Platten!$C$6:$F$611,4,FALSE) -> 420 / 780 | M17: =IFERROR(ROUND(E17*(1+$R$2),0),"-") -> 82 | N17: =IFERROR(ROUND(F17*(1+$R$2),0),"-") -> 252 | O17: =IFERROR(ROUND(G17*(1+$R$2),0),"-") -> 130 | P17: =IFERROR(ROUND(H17*(1+$R$2),0),"-") -> 245 | T17: =IFERROR(F17-E17,"") -> 148 | U17: =IFERROR(G17-F17,"") -> -106 | V17: =IFERROR(H17-G17,"") -> 100
B18: Boden | C18: 3014 | D18: =VLOOKUP($C18,Kalkulation_Platten!$C$6:$F$611,3,FALSE)&" / "&VLOOKUP($C18,Kalkulation_Platten!$C$6:$F$611,4,FALSE) -> 420 / 980 | E18: =INDEX(Kalkulation_Platten!$C$3:$AM$1001,MATCH($C18,Kalkulation_Platten!$C$3:$C$1001,0),MATCH(E$3,Kalkulation_Platten!$C$3:$AM$3,0)) -> 88 | F18: =INDEX(Kalkulation_Platten!$C$3:$AM$1001,MATCH($C18,Kalkulation_Platten!$C$3:$C$1001,0),MATCH(F$3,Kalkulation_Platten!$C$3:$AM$3,0)) -> 247 | G18: =INDEX(Kalkulation_Platten!$C$3:$AM$1001,MATCH($C18,Kalkulation_Platten!$C$3:$C$1001,0),MATCH(G$3,Kalkulation_Platten!$C$3:$AM$3,0)) -> 128 | H18: =INDEX(Kalkulation_Platten!$C$3:$AM$1001,MATCH($C18,Kalkulation_Platten!$C$3:$C$1001,0),MATCH(H$3,Kalkulation_Platten!$C$3:$AM$3,0)) -> 241 | J18: Boden | K18: 3014 | L18: =VLOOKUP($C18,Kalkulation_Platten!$C$6:$F$611,3,FALSE)&" / "&VLOOKUP($C18,Kalkulation_Platten!$C$6:$F$611,4,FALSE) -> 420 / 980 | M18: =IFERROR(ROUND(E18*(1+$R$2),0),"-") -> 101 | N18: =IFERROR(ROUND(F18*(1+$R$2),0),"-") -> 284 | O18: =IFERROR(ROUND(G18*(1+$R$2),0),"-") -> 147 | P18: =IFERROR(ROUND(H18*(1+$R$2),0),"-") -> 277 | T18: =IFERROR(F18-E18,"") -> 159 | U18: =IFERROR(G18-F18,"") -> -119 | V18: =IFERROR(H18-G18,"") -> 113
T19: =IFERROR(F19-E19,"") -> 0 | U19: =IFERROR(G19-F19,"") -> 0 | V19: =IFERROR(H19-G19,"") -> 0
B20: Panel | C20: Art. Nr. | D20: Breite / Tiefe | E20: PG1 | F20: PG2 | G20: PG3 | H20: PG4 | J20: Panel | K20: Art. Nr. | L20: Breite / Tiefe | M20: PG1 | N20: PG2 | O20: PG3 | P20: PG4 | T20: =IFERROR(F20-E20,"") | U20: =IFERROR(G20-F20,"") | V20: =IFERROR(H20-G20,"")
B21: Seite | C21: 3100 | D21: =VLOOKUP($C21,Kalkulation_Platten!$C$6:$F$611,3,FALSE)&" / "&VLOOKUP($C21,Kalkulation_Platten!$C$6:$F$611,4,FALSE) -> 360 / 180 | E21: =INDEX(Kalkulation_Platten!$C$3:$AM$1001,MATCH($C21,Kalkulation_Platten!$C$3:$C$1001,0),MATCH(E$3,Kalkulation_Platten!$C$3:$AM$3,0)) -> 34 | F21: =INDEX(Kalkulation_Platten!$C$3:$AM$1001,MATCH($C21,Kalkulation_Platten!$C$3:$C$1001,0),MATCH(F$3,Kalkulation_Platten!$C$3:$AM$3,0)) -> 114 | G21: =INDEX(Kalkulation_Platten!$C$3:$AM$1001,MATCH($C21,Kalkulation_Platten!$C$3:$C$1001,0),MATCH(G$3,Kalkulation_Platten!$C$3:$AM$3,0)) -> 89 | H21: =INDEX(Kalkulation_Platten!$C$3:$AM$1001,MATCH($C21,Kalkulation_Platten!$C$3:$C$1001,0),MATCH(H$3,Kalkulation_Platten!$C$3:$AM$3,0)) -> 201 | J21: Seite | K21: 3100 | L21: =VLOOKUP($C21,Kalkulation_Platten!$C$6:$F$611,3,FALSE)&" / "&VLOOKUP($C21,Kalkulation_Platten!$C$6:$F$611,4,FALSE) -> 360 / 180 | M21: =IFERROR(ROUND(E21*(1+$R$2),0),"-") -> 39 | N21: =IFERROR(ROUND(F21*(1+$R$2),0),"-") -> 131 | O21: =IFERROR(ROUND(G21*(1+$R$2),0),"-") -> 102 | P21: =IFERROR(ROUND(H21*(1+$R$2),0),"-") -> 231 | T21: =IFERROR(F21-E21,"") -> 80 | U21: =IFERROR(G21-F21,"") -> -25 | V21: =IFERROR(H21-G21,"") -> 112
B22: Seite | C22: 3101 | D22: =VLOOKUP($C22,Kalkulation_Platten!$C$6:$F$611,3,FALSE)&" / "&VLOOKUP($C22,Kalkulation_Platten!$C$6:$F$611,4,FALSE) -> 360 / 360 | E22: =INDEX(Kalkulation_Platten!$C$3:$AM$1001,MATCH($C22,Kalkulation_Platten!$C$3:$C$1001,0),MATCH(E$3,Kalkulation_Platten!$C$3:$AM$3,0)) -> 34 | F22: =INDEX(Kalkulation_Platten!$C$3:$AM$1001,MATCH($C22,Kalkulation_Platten!$C$3:$C$1001,0),MATCH(F$3,Kalkulation_Platten!$C$3:$AM$3,0)) -> 114 | G22: =INDEX(Kalkulation_Platten!$C$3:$AM$1001,MATCH($C22,Kalkulation_Platten!$C$3:$C$1001,0),MATCH(G$3,Kalkulation_Platten!$C$3:$AM$3,0)) -> 89 | H22: =INDEX(Kalkulation_Platten!$C$3:$AM$1001,MATCH($C22,Kalkulation_Platten!$C$3:$C$1001,0),MATCH(H$3,Kalkulation_Platten!$C$3:$AM$3,0)) -> 177 | J22: Seite | K22: 3101 | L22: =VLOOKUP($C22,Kalkulation_Platten!$C$6:$F$611,3,FALSE)&" / "&VLOOKUP($C22,Kalkulation_Platten!$C$6:$F$611,4,FALSE) -> 360 / 360 | M22: =IFERROR(ROUND(E22*(1+$R$2),0),"-") -> 39 | N22: =IFERROR(ROUND(F22*(1+$R$2),0),"-") -> 131 | O22: =IFERROR(ROUND(G22*(1+$R$2),0),"-") -> 102 | P22: =IFERROR(ROUND(H22*(1+$R$2),0),"-") -> 204 | T22: =IFERROR(F22-E22,"") -> 80 | U22: =IFERROR(G22-F22,"") -> -25 | V22: =IFERROR(H22-G22,"") -> 88
B23: Seite | C23: 3102 | D23: =VLOOKUP($C23,Kalkulation_Platten!$C$6:$F$611,3,FALSE)&" / "&VLOOKUP($C23,Kalkulation_Platten!$C$6:$F$611,4,FALSE) -> 360 / 720 | E23: =INDEX(Kalkulation_Platten!$C$3:$AM$1001,MATCH($C23,Kalkulation_Platten!$C$3:$C$1001,0),MATCH(E$3,Kalkulation_Platten!$C$3:$AM$3,0)) -> 52 | F23: =INDEX(Kalkulation_Platten!$C$3:$AM$1001,MATCH($C23,Kalkulation_Platten!$C$3:$C$1001,0),MATCH(F$3,Kalkulation_Platten!$C$3:$AM$3,0)) -> 181 | G23: =INDEX(Kalkulation_Platten!$C$3:$AM$1001,MATCH($C23,Kalkulation_Platten!$C$3:$C$1001,0),MATCH(G$3,Kalkulation_Platten!$C$3:$AM$3,0)) -> 143 | H23: =INDEX(Kalkulation_Platten!$C$3:$AM$1001,MATCH($C23,Kalkulation_Platten!$C$3:$C$1001,0),MATCH(H$3,Kalkulation_Platten!$C$3:$AM$3,0)) -> 212 | J23: Seite | K23: 3102 | L23: =VLOOKUP($C23,Kalkulation_Platten!$C$6:$F$611,3,FALSE)&" / "&VLOOKUP($C23,Kalkulation_Platten!$C$6:$F$611,4,FALSE) -> 360 / 720 | M23: =IFERROR(ROUND(E23*(1+$R$2),0),"-") -> 60 | N23: =IFERROR(ROUND(F23*(1+$R$2),0),"-") -> 208 | O23: =IFERROR(ROUND(G23*(1+$R$2),0),"-") -> 164 | P23: =IFERROR(ROUND(H23*(1+$R$2),0),"-") -> 244 | T23: =IFERROR(F23-E23,"") -> 129 | U23: =IFERROR(G23-F23,"") -> -38 | V23: =IFERROR(H23-G23,"") -> 69
B24: Seite | C24: 3103 | D24: =VLOOKUP($C24,Kalkulation_Platten!$C$6:$F$611,3,FALSE)&" / "&VLOOKUP($C24,Kalkulation_Platten!$C$6:$F$611,4,FALSE) -> 360 / 1080 | E24: =INDEX(Kalkulation_Platten!$C$3:$AM$1001,MATCH($C24,Kalkulation_Platten!$C$3:$C$1001,0),MATCH(E$3,Kalkulation_Platten!$C$3:$AM$3,0)) -> 76 | F24: =INDEX(Kalkulation_Platten!$C$3:$AM$1001,MATCH($C24,Kalkulation_Platten!$C$3:$C$1001,0),MATCH(F$3,Kalkulation_Platten!$C$3:$AM$3,0)) -> 267 | G24: =INDEX(Kalkulation_Platten!$C$3:$AM$1001,MATCH($C24,Kalkulation_Platten!$C$3:$C$1001,0),MATCH(G$3,Kalkulation_Platten!$C$3:$AM$3,0)) -> 222 | H24: =INDEX(Kalkulation_Platten!$C$3:$AM$1001,MATCH($C24,Kalkulation_Platten!$C$3:$C$1001,0),MATCH(H$3,Kalkulation_Platten!$C$3:$AM$3,0)) -> 240 | J24: Seite | K24: 3103 | L24: =VLOOKUP($C24,Kalkulation_Platten!$C$6:$F$611,3,FALSE)&" / "&VLOOKUP($C24,Kalkulation_Platten!$C$6:$F$611,4,FALSE) -> 360 / 1080 | M24: =IFERROR(ROUND(E24*(1+$R$2),0),"-") -> 87 | N24: =IFERROR(ROUND(F24*(1+$R$2),0),"-") -> 307 | O24: =IFERROR(ROUND(G24*(1+$R$2),0),"-") -> 255 | P24: =IFERROR(ROUND(H24*(1+$R$2),0),"-") -> 276 | T24: =IFERROR(F24-E24,"") -> 191 | U24: =IFERROR(G24-F24,"") -> -45 | V24: =IFERROR(H24-G24,"") -> 18
B25: Seite | C25: 3104 | D25: =VLOOKUP($C25,Kalkulation_Platten!$C$6:$F$611,3,FALSE)&" / "&VLOOKUP($C25,Kalkulation_Platten!$C$6:$F$611,4,FALSE) -> 360 / 1440 | E25: =INDEX(Kalkulation_Platten!$C$3:$AM$1001,MATCH($C25,Kalkulation_Platten!$C$3:$C$1001,0),MATCH(E$3,Kalkulation_Platten!$C$3:$AM$3,0)) -> 100 | F25: =INDEX(Kalkulation_Platten!$C$3:$AM$1001,MATCH($C25,Kalkulation_Platten!$C$3:$C$1001,0),MATCH(F$3,Kalkulation_Platten!$C$3:$AM$3,0)) -> 336 | G25: =INDEX(Kalkulation_Platten!$C$3:$AM$1001,MATCH($C25,Kalkulation_Platten!$C$3:$C$1001,0),MATCH(G$3,Kalkulation_Platten!$C$3:$AM$3,0)) -> 281 | H25: =INDEX(Kalkulation_Platten!$C$3:$AM$1001,MATCH($C25,Kalkulation_Platten!$C$3:$C$1001,0),MATCH(H$3,Kalkulation_Platten!$C$3:$AM$3,0)) -> 529 | J25: Seite | K25: 3104 | L25: =VLOOKUP($C25,Kalkulation_Platten!$C$6:$F$611,3,FALSE)&" / "&VLOOKUP($C25,Kalkulation_Platten!$C$6:$F$611,4,FALSE) -> 360 / 1440 | M25: =IFERROR(ROUND(E25*(1+$R$2),0),"-") -> 115 | N25: =IFERROR(ROUND(F25*(1+$R$2),0),"-") -> 386 | O25: =IFERROR(ROUND(G25*(1+$R$2),0),"-") -> 323 | P25: =IFERROR(ROUND(H25*(1+$R$2),0),"-") -> 608 | T25: =IFERROR(F25-E25,"") -> 236 | U25: =IFERROR(G25-F25,"") -> -55 | V25: =IFERROR(H25-G25,"") -> 248
B26: Seite | C26: 3105 | D26: =VLOOKUP($C26,Kalkulation_Platten!$C$6:$F$611,3,FALSE)&" / "&VLOOKUP($C26,Kalkulation_Platten!$C$6:$F$611,4,FALSE) -> 360 / 1800 | E26: =INDEX(Kalkulation_Platten!$C$3:$AM$1001,MATCH($C26,Kalkulation_Platten!$C$3:$C$1001,0),MATCH(E$3,Kalkulation_Platten!$C$3:$AM$3,0)) -> 125 | F26: =INDEX(Kalkulation_Platten!$C$3:$AM$1001,MATCH($C26,Kalkulation_Platten!$C$3:$C$1001,0),MATCH(F$3,Kalkulation_Platten!$C$3:$AM$3,0)) -> 246 | G26: =INDEX(Kalkulation_Platten!$C$3:$AM$1001,MATCH($C26,Kalkulation_Platten!$C$3:$C$1001,0),MATCH(G$3,Kalkulation_Platten!$C$3:$AM$3,0)) -> 343 | H26: =INDEX(Kalkulation_Platten!$C$3:$AM$1001,MATCH($C26,Kalkulation_Platten!$C$3:$C$1001,0),MATCH(H$3,Kalkulation_Platten!$C$3:$AM$3,0)) -> 645 | J26: Seite | K26: 3105 | L26: =VLOOKUP($C26,Kalkulation_Platten!$C$6:$F$611,3,FALSE)&" / "&VLOOKUP($C26,Kalkulation_Platten!$C$6:$F$611,4,FALSE) -> 360 / 1800 | M26: =IFERROR(ROUND(E26*(1+$R$2),0),"-") -> 144 | N26: =IFERROR(ROUND(F26*(1+$R$2),0),"-") -> 283 | O26: =IFERROR(ROUND(G26*(1+$R$2),0),"-") -> 394 | P26: =IFERROR(ROUND(H26*(1+$R$2),0),"-") -> 742 | T26: =IFERROR(F26-E26,"") -> 121 | U26: =IFERROR(G26-F26,"") -> 97 | V26: =IFERROR(H26-G26,"") -> 302
B27: Seite | C27: 3106 | D27: =VLOOKUP($C27,Kalkulation_Platten!$C$6:$F$611,3,FALSE)&" / "&VLOOKUP($C27,Kalkulation_Platten!$C$6:$F$611,4,FALSE) -> 580 / 180 | E27: =INDEX(Kalkulation_Platten!$C$3:$AM$1001,MATCH($C27,Kalkulation_Platten!$C$3:$C$1001,0),MATCH(E$3,Kalkulation_Platten!$C$3:$AM$3,0)) -> 43 | F27: =INDEX(Kalkulation_Platten!$C$3:$AM$1001,MATCH($C27,Kalkulation_Platten!$C$3:$C$1001,0),MATCH(F$3,Kalkulation_Platten!$C$3:$AM$3,0)) -> 161 | G27: =INDEX(Kalkulation_Platten!$C$3:$AM$1001,MATCH($C27,Kalkulation_Platten!$C$3:$C$1001,0),MATCH(G$3,Kalkulation_Platten!$C$3:$AM$3,0)) -> 130 | H27: =INDEX(Kalkulation_Platten!$C$3:$AM$1001,MATCH($C27,Kalkulation_Platten!$C$3:$C$1001,0),MATCH(H$3,Kalkulation_Platten!$C$3:$AM$3,0)) -> 208 | J27: Seite | K27: 3106 | L27: =VLOOKUP($C27,Kalkulation_Platten!$C$6:$F$611,3,FALSE)&" / "&VLOOKUP($C27,Kalkulation_Platten!$C$6:$F$611,4,FALSE) -> 580 / 180 | M27: =IFERROR(ROUND(E27*(1+$R$2),0),"-") -> 49 | N27: =IFERROR(ROUND(F27*(1+$R$2),0),"-") -> 185 | O27: =IFERROR(ROUND(G27*(1+$R$2),0),"-") -> 150 | P27: =IFERROR(ROUND(H27*(1+$R$2),0),"-") -> 239 | T27: =IFERROR(F27-E27,"") -> 118 | U27: =IFERROR(G27-F27,"") -> -31 | V27: =IFERROR(H27-G27,"") -> 78
B28: Seite | C28: 3107 | D28: =VLOOKUP($C28,Kalkulation_Platten!$C$6:$F$611,3,FALSE)&" / "&VLOOKUP($C28,Kalkulation_Platten!$C$6:$F$611,4,FALSE) -> 580 / 360 | E28: =INDEX(Kalkulation_Platten!$C$3:$AM$1001,MATCH($C28,Kalkulation_Platten!$C$3:$C$1001,0),MATCH(E$3,Kalkulation_Platten!$C$3:$AM$3,0)) -> 43 | F28: =INDEX(Kalkulation_Platten!$C$3:$AM$1001,MATCH($C28,Kalkulation_Platten!$C$3:$C$1001,0),MATCH(F$3,Kalkulation_Platten!$C$3:$AM$3,0)) -> 161 | G28: =INDEX(Kalkulation_Platten!$C$3:$AM$1001,MATCH($C28,Kalkulation_Platten!$C$3:$C$1001,0),MATCH(G$3,Kalkulation_Platten!$C$3:$AM$3,0)) -> 130 | H28: =INDEX(Kalkulation_Platten!$C$3:$AM$1001,MATCH($C28,Kalkulation_Platten!$C$3:$C$1001,0),MATCH(H$3,Kalkulation_Platten!$C$3:$AM$3,0)) -> 185 | J28: Seite | K28: 3107 | L28: =VLOOKUP($C28,Kalkulation_Platten!$C$6:$F$611,3,FALSE)&" / "&VLOOKUP($C28,Kalkulation_Platten!$C$6:$F$611,4,FALSE) -> 580 / 360 | M28: =IFERROR(ROUND(E28*(1+$R$2),0),"-") -> 49 | N28: =IFERROR(ROUND(F28*(1+$R$2),0),"-") -> 185 | O28: =IFERROR(ROUND(G28*(1+$R$2),0),"-") -> 150 | P28: =IFERROR(ROUND(H28*(1+$R$2),0),"-") -> 213 | T28: =IFERROR(F28-E28,"") -> 118 | U28: =IFERROR(G28-F28,"") -> -31 | V28: =IFERROR(H28-G28,"") -> 55
B29: Seite | C29: 3108 | D29: =VLOOKUP($C29,Kalkulation_Platten!$C$6:$F$611,3,FALSE)&" / "&VLOOKUP($C29,Kalkulation_Platten!$C$6:$F$611,4,FALSE) -> 580 / 720 | E29: =INDEX(Kalkulation_Platten!$C$3:$AM$1001,MATCH($C29,Kalkulation_Platten!$C$3:$C$1001,0),MATCH(E$3,Kalkulation_Platten!$C$3:$AM$3,0)) -> 82 | F29: =INDEX(Kalkulation_Platten!$C$3:$AM$1001,MATCH($C29,Kalkulation_Platten!$C$3:$C$1001,0),MATCH(F$3,Kalkulation_Platten!$C$3:$AM$3,0)) -> 262 | G29: =INDEX(Kalkulation_Platten!$C$3:$AM$1001,MATCH($C29,Kalkulation_Platten!$C$3:$C$1001,0),MATCH(G$3,Kalkulation_Platten!$C$3:$AM$3,0)) -> 216 | H29: =INDEX(Kalkulation_Platten!$C$3:$AM$1001,MATCH($C29,Kalkulation_Platten!$C$3:$C$1001,0),MATCH(H$3,Kalkulation_Platten!$C$3:$AM$3,0)) -> 245 | J29: Seite | K29: 3108 | L29: =VLOOKUP($C29,Kalkulation_Platten!$C$6:$F$611,3,FALSE)&" / "&VLOOKUP($C29,Kalkulation_Platten!$C$6:$F$611,4,FALSE) -> 580 / 720 | M29: =IFERROR(ROUND(E29*(1+$R$2),0),"-") -> 94 | N29: =IFERROR(ROUND(F29*(1+$R$2),0),"-") -> 301 | O29: =IFERROR(ROUND(G29*(1+$R$2),0),"-") -> 248 | P29: =IFERROR(ROUND(H29*(1+$R$2),0),"-") -> 282 | T29: =IFERROR(F29-E29,"") -> 180 | U29: =IFERROR(G29-F29,"") -> -46 | V29: =IFERROR(H29-G29,"") -> 29
B30: Seite | C30: 3109 | D30: =VLOOKUP($C30,Kalkulation_Platten!$C$6:$F$611,3,FALSE)&" / "&VLOOKUP($C30,Kalkulation_Platten!$C$6:$F$611,4,FALSE) -> 580 / 1080 | E30: =INDEX(Kalkulation_Platten!$C$3:$AM$1001,MATCH($C30,Kalkulation_Platten!$C$3:$C$1001,0),MATCH(E$3,Kalkulation_Platten!$C$3:$AM$3,0)) -> 119 | F30: =INDEX(Kalkulation_Platten!$C$3:$AM$1001,MATCH($C30,Kalkulation_Platten!$C$3:$C$1001,0),MATCH(F$3,Kalkulation_Platten!$C$3:$AM$3,0)) -> 377 | G30: =INDEX(Kalkulation_Platten!$C$3:$AM$1001,MATCH($C30,Kalkulation_Platten!$C$3:$C$1001,0),MATCH(G$3,Kalkulation_Platten!$C$3:$AM$3,0)) -> 300 | H30: =INDEX(Kalkulation_Platten!$C$3:$AM$1001,MATCH($C30,Kalkulation_Platten!$C$3:$C$1001,0),MATCH(H$3,Kalkulation_Platten!$C$3:$AM$3,0)) -> 307 | J30: Seite | K30: 3109 | L30: =VLOOKUP($C30,Kalkulation_Platten!$C$6:$F$611,3,FALSE)&" / "&VLOOKUP($C30,Kalkulation_Platten!$C$6:$F$611,4,FALSE) -> 580 / 1080 | M30: =IFERROR(ROUND(E30*(1+$R$2),0),"-") -> 137 | N30: =IFERROR(ROUND(F30*(1+$R$2),0),"-") -> 434 | O30: =IFERROR(ROUND(G30*(1+$R$2),0),"-") -> 345 | P30: =IFERROR(ROUND(H30*(1+$R$2),0),"-") -> 353 | T30: =IFERROR(F30-E30,"") -> 258 | U30: =IFERROR(G30-F30,"") -> -77 | V30: =IFERROR(H30-G30,"") -> 7
B31: Seite | C31: 3110 | D31: =VLOOKUP($C31,Kalkulation_Platten!$C$6:$F$611,3,FALSE)&" / "&VLOOKUP($C31,Kalkulation_Platten!$C$6:$F$611,4,FALSE) -> 580 / 1440 | E31: =INDEX(Kalkulation_Platten!$C$3:$AM$1001,MATCH($C31,Kalkulation_Platten!$C$3:$C$1001,0),MATCH(E$3,Kalkulation_Platten!$C$3:$AM$3,0)) -> 158 | F31: =INDEX(Kalkulation_Platten!$C$3:$AM$1001,MATCH($C31,Kalkulation_Platten!$C$3:$C$1001,0),MATCH(F$3,Kalkulation_Platten!$C$3:$AM$3,0)) -> 484 | G31: =INDEX(Kalkulation_Platten!$C$3:$AM$1001,MATCH($C31,Kalkulation_Platten!$C$3:$C$1001,0),MATCH(G$3,Kalkulation_Platten!$C$3:$AM$3,0)) -> 400 | H31: =INDEX(Kalkulation_Platten!$C$3:$AM$1001,MATCH($C31,Kalkulation_Platten!$C$3:$C$1001,0),MATCH(H$3,Kalkulation_Platten!$C$3:$AM$3,0)) -> 752 | J31: Seite | K31: 3110 | L31: =VLOOKUP($C31,Kalkulation_Platten!$C$6:$F$611,3,FALSE)&" / "&VLOOKUP($C31,Kalkulation_Platten!$C$6:$F$611,4,FALSE) -> 580 / 1440 | M31: =IFERROR(ROUND(E31*(1+$R$2),0),"-") -> 182 | N31: =IFERROR(ROUND(F31*(1+$R$2),0),"-") -> 557 | O31: =IFERROR(ROUND(G31*(1+$R$2),0),"-") -> 460 | P31: =IFERROR(ROUND(H31*(1+$R$2),0),"-") -> 865 | T31: =IFERROR(F31-E31,"") -> 326 | U31: =IFERROR(G31-F31,"") -> -84 | V31: =IFERROR(H31-G31,"") -> 352
B32: Seite | C32: 3111 | D32: =VLOOKUP($C32,Kalkulation_Platten!$C$6:$F$611,3,FALSE)&" / "&VLOOKUP($C32,Kalkulation_Platten!$C$6:$F$611,4,FALSE) -> 580 / 1800 | E32: =INDEX(Kalkulation_Platten!$C$3:$AM$1001,MATCH($C32,Kalkulation_Platten!$C$3:$C$1001,0),MATCH(E$3,Kalkulation_Platten!$C$3:$AM$3,0)) -> 197 | F32: =INDEX(Kalkulation_Platten!$C$3:$AM$1001,MATCH($C32,Kalkulation_Platten!$C$3:$C$1001,0),MATCH(F$3,Kalkulation_Platten!$C$3:$AM$3,0)) -> 388 | G32: =INDEX(Kalkulation_Platten!$C$3:$AM$1001,MATCH($C32,Kalkulation_Platten!$C$3:$C$1001,0),MATCH(G$3,Kalkulation_Platten!$C$3:$AM$3,0)) -> 467 | H32: =INDEX(Kalkulation_Platten!$C$3:$AM$1001,MATCH($C32,Kalkulation_Platten!$C$3:$C$1001,0),MATCH(H$3,Kalkulation_Platten!$C$3:$AM$3,0)) -> 879 | J32: Seite | K32: 3111 | L32: =VLOOKUP($C32,Kalkulation_Platten!$C$6:$F$611,3,FALSE)&" / "&VLOOKUP($C32,Kalkulation_Platten!$C$6:$F$611,4,FALSE) -> 580 / 1800 | M32: =IFERROR(ROUND(E32*(1+$R$2),0),"-") -> 227 | N32: =IFERROR(ROUND(F32*(1+$R$2),0),"-") -> 446 | O32: =IFERROR(ROUND(G32*(1+$R$2),0),"-") -> 537 | P32: =IFERROR(ROUND(H32*(1+$R$2),0),"-") -> 1011 | T32: =IFERROR(F32-E32,"") -> 191 | U32: =IFERROR(G32-F32,"") -> 79 | V32: =IFERROR(H32-G32,"") -> 412
... B45: Seite | C45: 3124 | D45: =VLOOKUP($C45,Kalkulation_Platten!$C$6:$F$611,3,FALSE)&" / "&VLOOKUP($C45,Kalkulation_Platten!$C$6:$F$611,4,FALSE) -> 580 / 580 | E45: =INDEX(Kalkulation_Platten!$C$3:$AM$1001,MATCH($C45,Kalkulation_Platten!$C$3:$C$1001,0),MATCH(E$3,Kalkulation_Platten!$C$3:$AM$3,0)) -> 67 | F45: =INDEX(Kalkulation_Platten!$C$3:$AM$1001,MATCH($C45,Kalkulation_Platten!$C$3:$C$1001,0),MATCH(F$3,Kalkulation_Platten!$C$3:$AM$3,0)) -> 228 | G45: =INDEX(Kalkulation_Platten!$C$3:$AM$1001,MATCH($C45,Kalkulation_Platten!$C$3:$C$1001,0),MATCH(G$3,Kalkulation_Platten!$C$3:$AM$3,0)) -> 183 | H45: =INDEX(Kalkulation_Platten!$C$3:$AM$1001,MATCH($C45,Kalkulation_Platten!$C$3:$C$1001,0),MATCH(H$3,Kalkulation_Platten!$C$3:$AM$3,0)) -> 191 | J45: Seite | K45: 3124 | L45: =VLOOKUP($C45,Kalkulation_Platten!$C$6:$F$611,3,FALSE)&" / "&VLOOKUP($C45,Kalkulation_Platten!$C$6:$F$611,4,FALSE) -> 580 / 580 | M45: =IFERROR(ROUND(E45*(1+$R$2),0),"-") -> 77 | N45: =IFERROR(ROUND(F45*(1+$R$2),0),"-") -> 262 | O45: =IFERROR(ROUND(G45*(1+$R$2),0),"-") -> 210 | P45: =IFERROR(ROUND(H45*(1+$R$2),0),"-") -> 220 | T45: =IFERROR(F45-E45,"") -> 161 | U45: =IFERROR(G45-F45,"") -> -45 | V45: =IFERROR(H45-G45,"") -> 8
T46: =IFERROR(F46-E46,"") -> 0 | U46: =IFERROR(G46-F46,"") -> 0 | V46: =IFERROR(H46-G46,"") -> 0
B47: Panel | C47: Art. Nr. | D47: Breite / Tiefe | E47: PG1 | F47: PG2 | G47: PG3 | H47: PG4 | J47: Panel | K47: Art. Nr. | L47: Breite / Tiefe | M47: PG1 | N47: PG2 | O47: PG3 | P47: PG4 | T47: =IFERROR(F47-E47,"") | U47: =IFERROR(G47-F47,"") | V47: =IFERROR(H47-G47,"")
B48: Rücken | C48: 3302 | D48: =VLOOKUP($C48,Kalkulation_Platten!$C$6:$F$611,3,FALSE)&" / "&VLOOKUP($C48,Kalkulation_Platten!$C$6:$F$611,4,FALSE) -> 580 / 180 | E48: =INDEX(Kalkulation_Platten!$C$3:$AM$1001,MATCH($C48,Kalkulation_Platten!$C$3:$C$1001,0),MATCH(E$3,Kalkulation_Platten!$C$3:$AM$3,0)) -> 43 | F48: =INDEX(Kalkulation_Platten!$C$3:$AM$1001,MATCH($C48,Kalkulation_Platten!$C$3:$C$1001,0),MATCH(F$3,Kalkulation_Platten!$C$3:$AM$3,0)) -> 161 | G48: =INDEX(Kalkulation_Platten!$C$3:$AM$1001,MATCH($C48,Kalkulation_Platten!$C$3:$C$1001,0),MATCH(G$3,Kalkulation_Platten!$C$3:$AM$3,0)) -> 130 | H48: =INDEX(Kalkulation_Platten!$C$3:$AM$1001,MATCH($C48,Kalkulation_Platten!$C$3:$C$1001,0),MATCH(H$3,Kalkulation_Platten!$C$3:$AM$3,0)) -> 208 | J48: Rück. | K48: 3302 | L48: =VLOOKUP($C48,Kalkulation_Platten!$C$6:$F$611,3,FALSE)&" / "&VLOOKUP($C48,Kalkulation_Platten!$C$6:$F$611,4,FALSE) -> 580 / 180 | M48: =IFERROR(ROUND(E48*(1+$R$2),0),"-") -> 49 | N48: =IFERROR(ROUND(F48*(1+$R$2),0),"-") -> 185 | O48: =IFERROR(ROUND(G48*(1+$R$2),0),"-") -> 150 | P48: =IFERROR(ROUND(H48*(1+$R$2),0),"-") -> 239 | T48: =IFERROR(F48-E48,"") -> 118 | U48: =IFERROR(G48-F48,"") -> -31 | V48: =IFERROR(H48-G48,"") -> 78
B49: Rücken | C49: 3303 | D49: =VLOOKUP($C49,Kalkulation_Platten!$C$6:$F$611,3,FALSE)&" / "&VLOOKUP($C49,Kalkulation_Platten!$C$6:$F$611,4,FALSE) -> 780 / 180 | E49: =INDEX(Kalkulation_Platten!$C$3:$AM$1001,MATCH($C49,Kalkulation_Platten!$C$3:$C$1001,0),MATCH(E$3,Kalkulation_Platten!$C$3:$AM$3,0)) -> 56 | F49: =INDEX(Kalkulation_Platten!$C$3:$AM$1001,MATCH($C49,Kalkulation_Platten!$C$3:$C$1001,0),MATCH(F$3,Kalkulation_Platten!$C$3:$AM$3,0)) -> 185 | G49: =INDEX(Kalkulation_Platten!$C$3:$AM$1001,MATCH($C49,Kalkulation_Platten!$C$3:$C$1001,0),MATCH(G$3,Kalkulation_Platten!$C$3:$AM$3,0)) -> 144 | H49: =INDEX(Kalkulation_Platten!$C$3:$AM$1001,MATCH($C49,Kalkulation_Platten!$C$3:$C$1001,0),MATCH(H$3,Kalkulation_Platten!$C$3:$AM$3,0)) -> 212 | J49: Rück. | K49: 3303 | L49: =VLOOKUP($C49,Kalkulation_Platten!$C$6:$F$611,3,FALSE)&" / "&VLOOKUP($C49,Kalkulation_Platten!$C$6:$F$611,4,FALSE) -> 780 / 180 | M49: =IFERROR(ROUND(E49*(1+$R$2),0),"-") -> 64 | N49: =IFERROR(ROUND(F49*(1+$R$2),0),"-") -> 213 | O49: =IFERROR(ROUND(G49*(1+$R$2),0),"-") -> 166 | P49: =IFERROR(ROUND(H49*(1+$R$2),0),"-") -> 244 | T49: =IFERROR(F49-E49,"") -> 129 | U49: =IFERROR(G49-F49,"") -> -41 | V49: =IFERROR(H49-G49,"") -> 68
B50: Rücken | C50: 3304 | D50: =VLOOKUP($C50,Kalkulation_Platten!$C$6:$F$611,3,FALSE)&" / "&VLOOKUP($C50,Kalkulation_Platten!$C$6:$F$611,4,FALSE) -> 980 / 180 | E50: =INDEX(Kalkulation_Platten!$C$3:$AM$1001,MATCH($C50,Kalkulation_Platten!$C$3:$C$1001,0),MATCH(E$3,Kalkulation_Platten!$C$3:$AM$3,0)) -> 70 | F50: =INDEX(Kalkulation_Platten!$C$3:$AM$1001,MATCH($C50,Kalkulation_Platten!$C$3:$C$1001,0),MATCH(F$3,Kalkulation_Platten!$C$3:$AM$3,0)) -> 223 | G50: =INDEX(Kalkulation_Platten!$C$3:$AM$1001,MATCH($C50,Kalkulation_Platten!$C$3:$C$1001,0),MATCH(G$3,Kalkulation_Platten!$C$3:$AM$3,0)) -> 174 | H50: =INDEX(Kalkulation_Platten!$C$3:$AM$1001,MATCH($C50,Kalkulation_Platten!$C$3:$C$1001,0),MATCH(H$3,Kalkulation_Platten!$C$3:$AM$3,0)) -> 229 | J50: Rück. | K50: 3304 | L50: =VLOOKUP($C50,Kalkulation_Platten!$C$6:$F$611,3,FALSE)&" / "&VLOOKUP($C50,Kalkulation_Platten!$C$6:$F$611,4,FALSE) -> 980 / 180 | M50: =IFERROR(ROUND(E50*(1+$R$2),0),"-") -> 81 | N50: =IFERROR(ROUND(F50*(1+$R$2),0),"-") -> 256 | O50: =IFERROR(ROUND(G50*(1+$R$2),0),"-") -> 200 | P50: =IFERROR(ROUND(H50*(1+$R$2),0),"-") -> 263 | T50: =IFERROR(F50-E50,"") -> 153 | U50: =IFERROR(G50-F50,"") -> -49 | V50: =IFERROR(H50-G50,"") -> 55
B51: Rücken | C51: 3305 | D51: =VLOOKUP($C51,Kalkulation_Platten!$C$6:$F$611,3,FALSE)&" / "&VLOOKUP($C51,Kalkulation_Platten!$C$6:$F$611,4,FALSE) -> 360 / 360 | E51: =INDEX(Kalkulation_Platten!$C$3:$AM$1001,MATCH($C51,Kalkulation_Platten!$C$3:$C$1001,0),MATCH(E$3,Kalkulation_Platten!$C$3:$AM$3,0)) -> 34 | F51: =INDEX(Kalkulation_Platten!$C$3:$AM$1001,MATCH($C51,Kalkulation_Platten!$C$3:$C$1001,0),MATCH(F$3,Kalkulation_Platten!$C$3:$AM$3,0)) -> 114 | G51: =INDEX(Kalkulation_Platten!$C$3:$AM$1001,MATCH($C51,Kalkulation_Platten!$C$3:$C$1001,0),MATCH(G$3,Kalkulation_Platten!$C$3:$AM$3,0)) -> 89 | H51: =INDEX(Kalkulation_Platten!$C$3:$AM$1001,MATCH($C51,Kalkulation_Platten!$C$3:$C$1001,0),MATCH(H$3,Kalkulation_Platten!$C$3:$AM$3,0)) -> 177 | J51: Rück. | K51: 3305 | L51: =VLOOKUP($C51,Kalkulation_Platten!$C$6:$F$611,3,FALSE)&" / "&VLOOKUP($C51,Kalkulation_Platten!$C$6:$F$611,4,FALSE) -> 360 / 360 | M51: =IFERROR(ROUND(E51*(1+$R$2),0),"-") -> 39 | N51: =IFERROR(ROUND(F51*(1+$R$2),0),"-") -> 131 | O51: =IFERROR(ROUND(G51*(1+$R$2),0),"-") -> 102 | P51: =IFERROR(ROUND(H51*(1+$R$2),0),"-") -> 204 | T51: =IFERROR(F51-E51,"") -> 80 | U51: =IFERROR(G51-F51,"") -> -25 | V51: =IFERROR(H51-G51,"") -> 88
B52: Rücken | C52: 3306 | D52: =VLOOKUP($C52,Kalkulation_Platten!$C$6:$F$611,3,FALSE)&" / "&VLOOKUP($C52,Kalkulation_Platten!$C$6:$F$611,4,FALSE) -> 420 / 360 | E52: =INDEX(Kalkulation_Platten!$C$3:$AM$1001,MATCH($C52,Kalkulation_Platten!$C$3:$C$1001,0),MATCH(E$3,Kalkulation_Platten!$C$3:$AM$3,0)) -> 34 | F52: =INDEX(Kalkulation_Platten!$C$3:$AM$1001,MATCH($C52,Kalkulation_Platten!$C$3:$C$1001,0),MATCH(F$3,Kalkulation_Platten!$C$3:$AM$3,0)) -> 121 | G52: =INDEX(Kalkulation_Platten!$C$3:$AM$1001,MATCH($C52,Kalkulation_Platten!$C$3:$C$1001,0),MATCH(G$3,Kalkulation_Platten!$C$3:$AM$3,0)) -> 92 | H52: =INDEX(Kalkulation_Platten!$C$3:$AM$1001,MATCH($C52,Kalkulation_Platten!$C$3:$C$1001,0),MATCH(H$3,Kalkulation_Platten!$C$3:$AM$3,0)) -> 178 | J52: Rück. | K52: 3306 | L52: =VLOOKUP($C52,Kalkulation_Platten!$C$6:$F$611,3,FALSE)&" / "&VLOOKUP($C52,Kalkulation_Platten!$C$6:$F$611,4,FALSE) -> 420 / 360 | M52: =IFERROR(ROUND(E52*(1+$R$2),0),"-") -> 39 | N52: =IFERROR(ROUND(F52*(1+$R$2),0),"-") -> 139 | O52: =IFERROR(ROUND(G52*(1+$R$2),0),"-") -> 106 | P52: =IFERROR(ROUND(H52*(1+$R$2),0),"-") -> 205 | T52: =IFERROR(F52-E52,"") -> 87 | U52: =IFERROR(G52-F52,"") -> -29 | V52: =IFERROR(H52-G52,"") -> 86
...

Sheet Kalkulation_Platten
A1: 1 | B1: 2 | C1: 3 | D1: 4 | E1: 5 | F1: 6 | G1: 7 | H1: 8 | I1: 9 | J1: 10 | K1: 12 | L1: 13 | M1: 14 | N1: 15 | O1: 16 | P1: 17 | Q1: 21 | R1: 22 | S1: 23 | T1: 24 | U1: 25 | V1: 26 | W1: 30 | X1: 31 | Y1: 32 | Z1: 33 | AA1: 34 | AB1: 35 | AC1: 36 | AD1: 37 | AE1: 38 | AF1: 39 | AG1: 40 | AH1: 41 | AI1: 42 | AJ1: 43 | AK1: 44 | AL1: 45 | AM1: 46 | AN1: 47
I2: min | J2: 5 | K2: Inflation | L2: 0.03 | M2: Jahre | N2: 10 | P2: min | Q2: 20 | R2: Inflation | S2: 0.03 | T2: Jahre | U2: 10 | V2: min | W2: 10 | X2: Inflation | Y2: 0.03 | Z2: Jahre | AA2: 10 | AB2: min | AC2: 10 | AD2: Inflation | AE2: 0.03 | AF2: Jahre | AG2: 10 | AJ2: 0.1 | AK2: 0.1 | AL2: 0.1 | AM2: 0.1
K3: PG1 | L3: MDF | Q3: PG2 | R3: Aluminium | W3: PG3 | X3: Furnier | AC3: PG4 | AD3: Glas | AJ3: CHF | AK3: CHF | AL3: CHF | AM3: CHF
A4: Bez. | B4: Bezeichnung VPM | C4: Nummer | D4: Bez. Kurz | E4: M1 | F4: M2 | I4: m2 | J4: lfm | K4: Preis | L4: Preis alt | M4: Delta rel. | N4: Delta abs. | O4: Status | Q4: Preis | R4: Preis alt | S4: Delta rel. | T4: Delta abs. | U4: Status | V4: =AVERAGE(R6:R611)/AVERAGE(L6:L611) -> 1.9682652 | W4: Preis | X4: Preis alt | Y4: Delta rel. | Z4: Delta abs. | AA4: Status | AB4: =AVERAGE(X6:X611)/AVERAGE(R6:R611) -> 0.51822193 | AC4: Preis | AD4: Preis alt | AE4: Delta rel. | AF4: Delta abs. | AG4: Status | AH4: =AVERAGE(AD6:AD611)/AVERAGE(X6:X611) -> 1.8811601 | AJ4: PG1 | AK4: PG2 | AL4: PG3 | AM4: PG4
B5: Boden | I5: =AVERAGE(I$6:I$56) -> 0.38635 | J5: 34 | K5: =AVERAGE(K$6:K$56) -> 24.313725 | M5: =AVERAGE(M6:M56) -> 0.4886483 | S5: =AVERAGE(S6:S56) -> 0.49431021 | Y5: =AVERAGE(Y6:Y56) -> 0.44184309 | AC5: 0.45
A6: Boden | B6: =IF(OR(E6="-",F6="-"),"-",D6&" ("&E6&"x"&F6&")") -> Boden (360x360) | C6: 3000 | D6: Boden | E6: 360 | F6: 360 | I6: =+IF($E6="","",MAX($E6,360)/1000*MAX($F6,360)/1000) -> 0.1296 | J6: =IF($F6="","",2*MAX($E6,360)/1000+2*MAX($F6,360)/1000) -> 1.44 | K6: =+IFERROR(MAX($J$5,ROUND(L6*(1+L$2)^N$2+J$2,0)),0) -> 34 | L6: 18 | M6: =IFERROR(K6/L6-1,"-") -> 0.88888889 | N6: =IFERROR(K6-L6,"-") -> 16 | O6: OK | Q6: =+IFERROR(IF(AND(R6="-",K6>0),ROUND(V$4*K6,0),ROUND(R6*(1+S$2)^U$2+Q$2,0)),0) -> 114 | R6: 70 | S6: =IFERROR(Q6/R6-1,"-") -> 0.62857143 | T6: =IFERROR(Q6-R6,"-") -> 44 | U6: OK | W6: =+IFERROR(IF(AND(X6="-",Q6>0),ROUND(AB$4*Q6,0),ROUND(X6*(1+Y$2)^AA$2+W$2,0)),0) -> 89 | X6: 59 | Y6: =IFERROR(W6/X6-1,"-") -> 0.50847458 | Z6: =IFERROR(W6-X6,"-") -> 30 | AA6: OK | AB6: =+AC6-W6 -> 88 | AC6: =+IFERROR(IF(AND(AD6="-",W6>0),ROUND(AH$4*W6,0),ROUND(AD6*(1+AE$2)^AG$2+AC$2,0)),0) -> 177 | AD6: 124 | AE6: =IFERROR(AC6/AD6-1,"-") -> 0.42741935 | AF6: =IFERROR(AC6-AD6,"-") -> 53 | AG6: OK | AJ6: =+IFERROR(ROUND(K6*(1+AJ$2),0),"-") -> 37 | AK6: =+IFERROR(ROUND(Q6*(1+AK$2),0),"-") -> 125 | AL6: =+IFERROR(ROUND(AC6*(1+AL$2),0),"-") -> 195 | AM6: =+IFERROR(ROUND(W6*(1+AM$2),0),"-") -> 98
A7: Boden | B7: =IF(OR(E7="-",F7="-"),"-",D7&" ("&E7&"x"&F7&")") -> Boden (420x360) | C7: 3001 | D7: Boden | E7: 420 | F7: 360 | I7: =+IF($E7="","",MAX($E7,360)/1000*MAX($F7,360)/1000) -> 0.1512 | J7: =IF($F7="","",2*MAX($E7,360)/1000+2*MAX($F7,360)/1000) -> 1.56 | K7: =+IFERROR(MAX($J$5,ROUND(L7*(1+L$2)^N$2+J$2,0)),0) -> 34 | L7: 21 | M7: =IFERROR(K7/L7-1,"-") -> 0.61904762 | N7: =IFERROR(K7-L7,"-") -> 13 | O7: OK | Q7: =+IFERROR(IF(AND(R7="-",K7>0),ROUND(V$4*K7,0),ROUND(R7*(1+S$2)^U$2+Q$2,0)),0) -> 121 | R7: 75 | S7: =IFERROR(Q7/R7-1,"-") -> 0.61333333 | T7: =IFERROR(Q7-R7,"-") -> 46 | U7: OK | W7: =+IFERROR(IF(AND(X7="-",Q7>0),ROUND(AB$4*Q7,0),ROUND(X7*(1+Y$2)^AA$2+W$2,0)),0) -> 92 | X7: 61 | Y7: =IFERROR(W7/X7-1,"-") -> 0.50819672 | Z7: =IFERROR(W7-X7,"-") -> 31 | AA7: OK | AB7: =+AC7-W7 -> 86 | AC7: =+IFERROR(IF(AND(AD7="-",W7>0),ROUND(AH$4*W7,0),ROUND(AD7*(1+AE$2)^AG$2+AC$2,0)),0) -> 178 | AD7: 125 | AE7: =IFERROR(AC7/AD7-1,"-") -> 0.424 | AF7: =IFERROR(AC7-AD7,"-") -> 53 | AG7: OK | AJ7: =+IFERROR(ROUND(K7*(1+AJ$2),0),"-") -> 37 | AK7: =+IFERROR(ROUND(Q7*(1+AK$2),0),"-") -> 133 | AL7: =+IFERROR(ROUND(AC7*(1+AL$2),0),"-") -> 196 | AM7: =+IFERROR(ROUND(W7*(1+AM$2),0),"-") -> 101
A8: Boden | B8: =IF(OR(E8="-",F8="-"),"-",D8&" ("&E8&"x"&F8&")") -> Boden (580x360) | C8: 3002 | D8: Boden | E8: 580 | F8: 360 | I8: =+IF($E8="","",MAX($E8,360)/1000*MAX($F8,360)/1000) -> 0.2088 | J8: =IF($F8="","",2*MAX($E8,360)/1000+2*MAX($F8,360)/1000) -> 1.88 | K8: =+IFERROR(MAX($J$5,ROUND(L8*(1+L$2)^N$2+J$2,0)),0) -> 43 | L8: 28 | M8: =IFERROR(K8/L8-1,"-") -> 0.53571429 | N8: =IFERROR(K8-L8,"-") -> 15 | O8: OK | Q8: =+IFERROR(IF(AND(R8="-",K8>0),ROUND(V$4*K8,0),ROUND(R8*(1+S$2)^U$2+Q$2,0)),0) -> 161 | R8: 105 | S8: =IFERROR(Q8/R8-1,"-") -> 0.53333333 | T8: =IFERROR(Q8-R8,"-") -> 56 | U8: OK | W8: =+IFERROR(IF(AND(X8="-",Q8>0),ROUND(AB$4*Q8,0),ROUND(X8*(1+Y$2)^AA$2+W$2,0)),0) -> 130 | X8: 89 | Y8: =IFERROR(W8/X8-1,"-") -> 0.46067416 | Z8: =IFERROR(W8-X8,"-") -> 41 | AA8: OK | AB8: =+AC8-W8 -> 55 | AC8: =+IFERROR(IF(AND(AD8="-",W8>0),ROUND(AH$4*W8,0),ROUND(AD8*(1+AE$2)^AG$2+AC$2,0)),0) -> 185 | AD8: 130 | AE8: =IFERROR(AC8/AD8-1,"-") -> 0.42307692 | AF8: =IFERROR(AC8-AD8,"-") -> 55 | AG8: OK | AJ8: =+IFERROR(ROUND(K8*(1+AJ$2),0),"-") -> 47 | AK8: =+IFERROR(ROUND(Q8*(1+AK$2),0),"-") -> 177 | AL8: =+IFERROR(ROUND(AC8*(1+AL$2),0),"-") -> 204 | AM8: =+IFERROR(ROUND(W8*(1+AM$2),0),"-") -> 143
A9: Boden | B9: =IF(OR(E9="-",F9="-"),"-",D9&" ("&E9&"x"&F9&")") -> Boden (780x360) | C9: 3003 | D9: Boden | E9: 780 | F9: 360 | I9: =+IF($E9="","",MAX($E9,360)/1000*MAX($F9,360)/1000) -> 0.2808 | J9: =IF($F9="","",2*MAX($E9,360)/1000+2*MAX($F9,360)/1000) -> 2.28 | K9: =+IFERROR(MAX($J$5,ROUND(L9*(1+L$2)^N$2+J$2,0)),0) -> 56 | L9: 38 | M9: =IFERROR(K9/L9-1,"-") -> 0.47368421 | N9: =IFERROR(K9-L9,"-") -> 18 | O9: OK | Q9: =+IFERROR(IF(AND(R9="-",K9>0),ROUND(V$4*K9,0),ROUND(R9*(1+S$2)^U$2+Q$2,0)),0) -> 185 | R9: 123 | S9: =IFERROR(Q9/R9-1,"-") -> 0.50406504 | T9: =IFERROR(Q9-R9,"-") -> 62 | U9: OK | W9: =+IFERROR(IF(AND(X9="-",Q9>0),ROUND(AB$4*Q9,0),ROUND(X9*(1+Y$2)^AA$2+W$2,0)),0) -> 144 | X9: 100 | Y9: =IFERROR(W9/X9-1,"-") -> 0.44 | Z9: =IFERROR(W9-X9,"-") -> 44 | AA9: OK | AB9: =+AC9-W9 -> 46 | AC9: =+IFERROR(IF(AND(AD9="-",W9>0),ROUND(AH$4*W9,0),ROUND(AD9*(1+AE$2)^AG$2+AC$2,0)),0) -> 190 | AD9: 134 | AE9: =IFERROR(AC9/AD9-1,"-") -> 0.41791045 | AF9: =IFERROR(AC9-AD9,"-") -> 56 | AG9: OK | AJ9: =+IFERROR(ROUND(K9*(1+AJ$2),0),"-") -> 62 | AK9: =+IFERROR(ROUND(Q9*(1+AK$2),0),"-") -> 204 | AL9: =+IFERROR(ROUND(AC9*(1+AL$2),0),"-") -> 209 | AM9: =+IFERROR(ROUND(W9*(1+AM$2),0),"-") -> 158
A10: Boden | B10: =IF(OR(E10="-",F10="-"),"-",D10&" ("&E10&"x"&F10&")") -> Boden (980x360) | C10: 3004 | D10: Boden | E10: 980 | F10: 360 | I10: =+IF($E10="","",MAX($E10,360)/1000*MAX($F10,360)/1000) -> 0.3528 | J10: =IF($F10="","",2*MAX($E10,360)/1000+2*MAX($F10,360)/1000) -> 2.68 | K10: =+IFERROR(MAX($J$5,ROUND(L10*(1+L$2)^N$2+J$2,0)),0) -> 70 | L10: 48 | M10: =IFERROR(K10/L10-1,"-") -> 0.45833333 | N10: =IFERROR(K10-L10,"-") -> 22 | O10: OK | Q10: =+IFERROR(IF(AND(R10="-",K10>0),ROUND(V$4*K10,0),ROUND(R10*(1+S$2)^U$2+Q$2,0)),0) -> 223 | R10: 151 | S10: =IFERROR(Q10/R10-1,"-") -> 0.47682119 | T10: =IFERROR(Q10-R10,"-") -> 72 | U10: OK | W10: =+IFERROR(IF(AND(X10="-",Q10>0),ROUND(AB$4*Q10,0),ROUND(X10*(1+Y$2)^AA$2+W$2,0)),0) -> 174 | X10: 122 | Y10: =IFERROR(W10/X10-1,"-") -> 0.42622951 | Z10: =IFERROR(W10-X10,"-") -> 52 | AA10: OK | AB10: =+AC10-W10 -> 35 | AC10: =+IFERROR(IF(AND(AD10="-",W10>0),ROUND(AH$4*W10,0),ROUND(AD10*(1+AE$2)^AG$2+AC$2,0)),0) -> 209 | AD10: 148 | AE10: =IFERROR(AC10/AD10-1,"-") -> 0.41216216 | AF10: =IFERROR(AC10-AD10,"-") -> 61 | AG10: OK | AJ10: =+IFERROR(ROUND(K10*(1+AJ$2),0),"-") -> 77 | AK10: =+IFERROR(ROUND(Q10*(1+AK$2),0),"-") -> 245 | AL10: =+IFERROR(ROUND(AC10*(1+AL$2),0),"-") -> 230 | AM10: =+IFERROR(ROUND(W10*(1+AM$2),0),"-") -> 191
A11: Boden | B11: =IF(OR(E11="-",F11="-"),"-",D11&" ("&E11&"x"&F11&")") -> Boden (360x580) | C11: 3005 | D11: Boden | E11: 360 | F11: 580 | I11: =+IF($E11="","",MAX($E11,360)/1000*MAX($F11,360)/1000) -> 0.2088 | J11: =IF($F11="","",2*MAX($E11,360)/1000+2*MAX($F11,360)/1000) -> 1.88 | K11: =+IFERROR(MAX($J$5,ROUND(L11*(1+L$2)^N$2+J$2,0)),0) -> 43 | L11: 28 | M11: =IFERROR(K11/L11-1,"-") -> 0.53571429 | N11: =IFERROR(K11-L11,"-") -> 15 | O11: OK | Q11: =+IFERROR(IF(AND(R11="-",K11>0),ROUND(V$4*K11,0),ROUND(R11*(1+S$2)^U$2+Q$2,0)),0) -> 161 | R11: 105 | S11: =IFERROR(Q11/R11-1,"-") -> 0.53333333 | T11: =IFERROR(Q11-R11,"-") -> 56 | U11: OK | W11: =+IFERROR(IF(AND(X11="-",Q11>0),ROUND(AB$4*Q11,0),ROUND(X11*(1+Y$2)^AA$2+W$2,0)),0) -> 130 | X11: 89 | Y11: =IFERROR(W11/X11-1,"-") -> 0.46067416 | Z11: =IFERROR(W11-X11,"-") -> 41 | AA11: OK | AB11: =+AC11-W11 -> 55 | AC11: =+IFERROR(IF(AND(AD11="-",W11>0),ROUND(AH$4*W11,0),ROUND(AD11*(1+AE$2)^AG$2+AC$2,0)),0) -> 185 | AD11: 130 | AE11: =IFERROR(AC11/AD11-1,"-") -> 0.42307692 | AF11: =IFERROR(AC11-AD11,"-") -> 55 | AG11: OK | AJ11: =+IFERROR(ROUND(K11*(1+AJ$2),0),"-") -> 47 | AK11: =+IFERROR(ROUND(Q11*(1+AK$2),0),"-") -> 177 | AL11: =+IFERROR(ROUND(AC11*(1+AL$2),0),"-") -> 204 | AM11: =+IFERROR(ROUND(W11*(1+AM$2),0),"-") -> 143
A12: Boden | B12: =IF(OR(E12="-",F12="-"),"-",D12&" ("&E12&"x"&F12&")") -> Boden (420x580) | C12: 3006 | D12: Boden | E12: 420 | F12: 580 | I12: =+IF($E12="","",MAX($E12,360)/1000*MAX($F12,360)/1000) -> 0.2436 | J12: =IF($F12="","",2*MAX($E12,360)/1000+2*MAX($F12,360)/1000) -> 2 | K12: =+IFERROR(MAX($J$5,ROUND(L12*(1+L$2)^N$2+J$2,0)),0) -> 49 | L12: 33 | M12: =IFERROR(K12/L12-1,"-") -> 0.48484848 | N12: =IFERROR(K12-L12,"-") -> 16 | O12: OK | Q12: =+IFERROR(IF(AND(R12="-",K12>0),ROUND(V$4*K12,0),ROUND(R12*(1+S$2)^U$2+Q$2,0)),0) -> 181 | R12: 120 | S12: =IFERROR(Q12/R12-1,"-") -> 0.50833333 | T12: =IFERROR(Q12-R12,"-") -> 61 | U12: OK | W12: =+IFERROR(IF(AND(X12="-",Q12>0),ROUND(AB$4*Q12,0),ROUND(X12*(1+Y$2)^AA$2+W$2,0)),0) -> 147 | X12: 102 | Y12: =IFERROR(W12/X12-1,"-") -> 0.44117647 | Z12: =IFERROR(W12-X12,"-") -> 45 | AA12: OK | AB12: =+AC12-W12 -> 39 | AC12: =+IFERROR(IF(AND(AD12="-",W12>0),ROUND(AH$4*W12,0),ROUND(AD12*(1+AE$2)^AG$2+AC$2,0)),0) -> 186 | AD12: 131 | AE12: =IFERROR(AC12/AD12-1,"-") -> 0.41984733 | AF12: =IFERROR(AC12-AD12,"-") -> 55 | AG12: OK | AJ12: =+IFERROR(ROUND(K12*(1+AJ$2),0),"-") -> 54 | AK12: =+IFERROR(ROUND(Q12*(1+AK$2),0),"-") -> 199 | AL12: =+IFERROR(ROUND(AC12*(1+AL$2),0),"-") -> 205 | AM12: =+IFERROR(ROUND(W12*(1+AM$2),0),"-") -> 162
A13: Boden | B13: =IF(OR(E13="-",F13="-"),"-",D13&" ("&E13&"x"&F13&")") -> Boden (580x580) | C13: 3007 | D13: Boden | E13: 580 | F13: 580 | I13: =+IF($E13="","",MAX($E13,360)/1000*MAX($F13,360)/1000) -> 0.3364 | J13: =IF($F13="","",2*MAX($E13,360)/1000+2*MAX($F13,360)/1000) -> 2.32 | K13: =+IFERROR(MAX($J$5,ROUND(L13*(1+L$2)^N$2+J$2,0)),0) -> 67 | L13: 46 | M13: =IFERROR(K13/L13-1,"-") -> 0.45652174 | N13: =IFERROR(K13-L13,"-") -> 21 | O13: OK | Q13: =+IFERROR(IF(AND(R13="-",K13>0),ROUND(V$4*K13,0),ROUND(R13*(1+S$2)^U$2+Q$2,0)),0) -> 228 | R13: 155 | S13: =IFERROR(Q13/R13-1,"-") -> 0.47096774 | T13: =IFERROR(Q13-R13,"-") -> 73 | U13: OK | W13: =+IFERROR(IF(AND(X13="-",Q13>0),ROUND(AB$4*Q13,0),ROUND(X13*(1+Y$2)^AA$2+W$2,0)),0) -> 183 | X13: 129 | Y13: =IFERROR(W13/X13-1,"-") -> 0.41860465 | Z13: =IFERROR(W13-X13,"-") -> 54 | AA13: OK | AB13: =+AC13-W13 -> 8 | AC13: =+IFERROR(IF(AND(AD13="-",W13>0),ROUND(AH$4*W13,0),ROUND(AD13*(1+AE$2)^AG$2+AC$2,0)),0) -> 191 | AD13: 135 | AE13: =IFERROR(AC13/AD13-1,"-") -> 0.41481481 | AF13: =IFERROR(AC13-AD13,"-") -> 56 | AG13: OK | AJ13: =+IFERROR(ROUND(K13*(1+AJ$2),0),"-") -> 74 | AK13: =+IFERROR(ROUND(Q13*(1+AK$2),0),"-") -> 251 | AL13: =+IFERROR(ROUND(AC13*(1+AL$2),0),"-") -> 210 | AM13: =+IFERROR(ROUND(W13*(1+AM$2),0),"-") -> 201
A14: Boden | B14: =IF(OR(E14="-",F14="-"),"-",D14&" ("&E14&"x"&F14&")") -> Boden (780x580) | C14: 3008 | D14: Boden | E14: 780 | F14: 580 | I14: =+IF($E14="","",MAX($E14,360)/1000*MAX($F14,360)/1000) -> 0.4524 | J14: =IF($F14="","",2*MAX($E14,360)/1000+2*MAX($F14,360)/1000) -> 2.72 | K14: =+IFERROR(MAX($J$5,ROUND(L14*(1+L$2)^N$2+J$2,0)),0) -> 87 | L14: 61 | M14: =IFERROR(K14/L14-1,"-") -> 0.42622951 | N14: =IFERROR(K14-L14,"-") -> 26 | O14: OK | Q14: =+IFERROR(IF(AND(R14="-",K14>0),ROUND(V$4*K14,0),ROUND(R14*(1+S$2)^U$2+Q$2,0)),0) -> 275 | R14: 190 | S14: =IFERROR(Q14/R14-1,"-") -> 0.44736842 | T14: =IFERROR(Q14-R14,"-") -> 85 | U14: OK | W14: =+IFERROR(IF(AND(X14="-",Q14>0),ROUND(AB$4*Q14,0),ROUND(X14*(1+Y$2)^AA$2+W$2,0)),0) -> 225 | X14: 160 | Y14: =IFERROR(W14/X14-1,"-") -> 0.40625 | Z14: =IFERROR(W14-X14,"-") -> 65 | AA14: OK | AB14: =+AC14-W14 -> 12 | AC14: =+IFERROR(IF(AND(AD14="-",W14>0),ROUND(AH$4*W14,0),ROUND(AD14*(1+AE$2)^AG$2+AC$2,0)),0) -> 237 | AD14: 169 | AE14: =IFERROR(AC14/AD14-1,"-") -> 0.40236686 | AF14: =IFERROR(AC14-AD14,"-") -> 68 | AG14: OK | AJ14: =+IFERROR(ROUND(K14*(1+AJ$2),0),"-") -> 96 | AK14: =+IFERROR(ROUND(Q14*(1+AK$2),0),"-") -> 303 | AL14: =+IFERROR(ROUND(AC14*(1+AL$2),0),"-") -> 261 | AM14: =+IFERROR(ROUND(W14*(1+AM$2),0),"-") -> 248
A15: Boden | B15: =IF(OR(E15="-",F15="-"),"-",D15&" ("&E15&"x"&F15&")") -> Boden (980x580) | C15: 3009 | D15: Boden | E15: 980 | F15: 580 | I15: =+IF($E15="","",MAX($E15,360)/1000*MAX($F15,360)/1000) -> 0.5684 | J15: =IF($F15="","",2*MAX($E15,360)/1000+2*MAX($F15,360)/1000) -> 3.12 | K15: =+IFERROR(MAX($J$5,ROUND(L15*(1+L$2)^N$2+J$2,0)),0) -> 110 | L15: 78 | M15: =IFERROR(K15/L15-1,"-") -> 0.41025641 | N15: =IFERROR(K15-L15,"-") -> 32 | O15: OK | Q15: =+IFERROR(IF(AND(R15="-",K15>0),ROUND(V$4*K15,0),ROUND(R15*(1+S$2)^U$2+Q$2,0)),0) -> 355 | R15: 249 | S15: =IFERROR(Q15/R15-1,"-") -> 0.42570281 | T15: =IFERROR(Q15-R15,"-") -> 106 | U15: OK | W15: =+IFERROR(IF(AND(X15="-",Q15>0),ROUND(AB$4*Q15,0),ROUND(X15*(1+Y$2)^AA$2+W$2,0)),0) -> 286 | X15: 205 | Y15: =IFERROR(W15/X15-1,"-") -> 0.39512195 | Z15: =IFERROR(W15-X15,"-") -> 81 | AA15: OK | AB15: =+AC15-W15 -> -10 | AC15: =+IFERROR(IF(AND(AD15="-",W15>0),ROUND(AH$4*W15,0),ROUND(AD15*(1+AE$2)^AG$2+AC$2,0)),0) -> 276 | AD15: 198 | AE15: =IFERROR(AC15/AD15-1,"-") -> 0.39393939 | AF15: =IFERROR(AC15-AD15,"-") -> 78 | AG15: OK | AJ15: =+IFERROR(ROUND(K15*(1+AJ$2),0),"-") -> 121 | AK15: =+IFERROR(ROUND(Q15*(1+AK$2),0),"-") -> 391 | AL15: =+IFERROR(ROUND(AC15*(1+AL$2),0),"-") -> 304 | AM15: =+IFERROR(ROUND(W15*(1+AM$2),0),"-") -> 315
A16: Boden | B16: =IF(OR(E16="-",F16="-"),"-",D16&" ("&E16&"x"&F16&")") -> Boden (780x780) | C16: 3010 | D16: Boden | E16: 780 | F16: 780 | I16: =+IF($E16="","",MAX($E16,360)/1000*MAX($F16,360)/1000) -> 0.6084 | J16: =IF($F16="","",2*MAX($E16,360)/1000+2*MAX($F16,360)/1000) -> 3.12 | K16: =+IFERROR(MAX($J$5,ROUND(L16*(1+L$2)^N$2+J$2,0)),0) -> 113 | L16: 80 | M16: =IFERROR(K16/L16-1,"-") -> 0.4125 | N16: =IFERROR(K16-L16,"-") -> 33 | O16: OK | Q16: =+IFERROR(IF(AND(R16="-",K16>0),ROUND(V$4*K16,0),ROUND(R16*(1+S$2)^U$2+Q$2,0)),0) -> 302 | R16: 210 | S16: =IFERROR(Q16/R16-1,"-") -> 0.43809524 | T16: =IFERROR(Q16-R16,"-") -> 92 | U16: OK | W16: =+IFERROR(IF(AND(X16="-",Q16>0),ROUND(AB$4*Q16,0),ROUND(X16*(1+Y$2)^AA$2+W$2,0)),0) -> 272 | X16: 195 | Y16: =IFERROR(W16/X16-1,"-") -> 0.39487179 | Z16: =IFERROR(W16-X16,"-") -> 77 | AA16: OK | AB16: =+AC16-W16 -> 23 | AC16: =+IFERROR(IF(AND(AD16="-",W16>0),ROUND(AH$4*W16,0),ROUND(AD16*(1+AE$2)^AG$2+AC$2,0)),0) -> 295 | AD16: 212 | AE16: =IFERROR(AC16/AD16-1,"-") -> 0.39150943 | AF16: =IFERROR(AC16-AD16,"-") -> 83 | AJ16: =+IFERROR(ROUND(K16*(1+AJ$2),0),"-") -> 124 | AK16: =+IFERROR(ROUND(Q16*(1+AK$2),0),"-") -> 332 | AL16: =+IFERROR(ROUND(AC16*(1+AL$2),0),"-") -> 325 | AM16: =+IFERROR(ROUND(W16*(1+AM$2),0),"-") -> 299
A17: Boden | B17: =IF(OR(E17="-",F17="-"),"-",D17&" ("&E17&"x"&F17&")") -> Boden (980x780) | C17: 3011 | D17: Boden | E17: 980 | F17: 780 | I17: =+IF($E17="","",MAX($E17,360)/1000*MAX($F17,360)/1000) -> 0.7644 | J17: =IF($F17="","",2*MAX($E17,360)/1000+2*MAX($F17,360)/1000) -> 3.52 | K17: =+IFERROR(MAX($J$5,ROUND(L17*(1+L$2)^N$2+J$2,0)),0) -> 139 | L17: 100 | M17: =IFERROR(K17/L17-1,"-") -> 0.39 | N17: =IFERROR(K17-L17,"-") -> 39 | O17: OK | Q17: =+IFERROR(IF(AND(R17="-",K17>0),ROUND(V$4*K17,0),ROUND(R17*(1+S$2)^U$2+Q$2,0)),0) -> 416 | R17: 295 | S17: =IFERROR(Q17/R17-1,"-") -> 0.41016949 | T17: =IFERROR(Q17-R17,"-") -> 121 | U17: OK | W17: =+IFERROR(IF(AND(X17="-",Q17>0),ROUND(AB$4*Q17,0),ROUND(X17*(1+Y$2)^AA$2+W$2,0)),0) -> 216 | X17: - | Y17: =IFERROR(W17/X17-1,"-") -> - | Z17: =IFERROR(W17-X17,"-") -> - | AA17: OK | AB17: =+AC17-W17 -> 190 | AC17: =+IFERROR(IF(AND(AD17="-",W17>0),ROUND(AH$4*W17,0),ROUND(AD17*(1+AE$2)^AG$2+AC$2,0)),0) -> 406 | AD17: - | AE17: =IFERROR(AC17/AD17-1,"-") -> - | AF17: =IFERROR(AC17-AD17,"-") -> - | AJ17: =+IFERROR(ROUND(K17*(1+AJ$2),0),"-") -> 153 | AK17: =+IFERROR(ROUND(Q17*(1+AK$2),0),"-") -> 458 | AL17: =+IFERROR(ROUND(AC17*(1+AL$2),0),"-") -> 447 | AM17: =+IFERROR(ROUND(W17*(1+AM$2),0),"-") -> 238
