Workbook
Name ANZ_Breite: #REF!
Name ANZ_Elemente: #REF!
Name ANZ_Höhe: #REF!
Name ANZ_Tiefe: #REF!
Name Bericht: #REF!
Name Gewicht_Klappe: #REF!
Name Gewicht_Platte: #REF!
Name Gewicht_Profil: #REF!
Name Gewicht_Scharnier: #REF!
Name Gewicht_Schubkasten: #REF!
Name Konfektion: #REF!
Name PL_CHF_Faktor: Preisliste_Tische!$G$2
Name PL_Inflation: Preisliste_Tische!$C$2
Name PL_Jahre: Preisliste_Tische!$E$2
Name Preise_Profil46: Preisliste_Tische!$B$6:$H$18
Name Preise_Tischplatten: Preisliste_Tische!$B$22:$L$32
Name Rabatt: #REF!
Name Tiefe: #REF!
Name Tischnamen: Preisliste_Tische!$C$22:$C$32
Name Vertrieb: #REF!
Name Zusatzrabatt: #REF!

Sheet Statistik
A1: Preisvergleich nach Preisgruppe – Typ: Platte (EUR)
A2: Alle Preise in EUR exkl. MwSt. | PG1 = MDF | PG2 = Furnier | PG3 = Alu | PG4 = Glas
A4: Art.-Nr. | B4: Kategorie | C4: Bezeichnung | D4: Breite (mm) | E4: Tiefe (mm) | F4: PG1 MDF | G4: PG2 Furnier | H4: PG3 Alu | I4: PG4 Glas | J4: PG2/PG1 (Furnier vs. MDF) | K4: PG3/PG1 (Alu vs. MDF) | L4: PG4/PG1 (Glas vs. MDF) | M4: PG3/PG2 (Alu vs. Furnier) | N4: PG4/PG2 (Glas vs. Furnier) | O4: PG4/PG3 (Glas vs. Alu) | P4: Ø Preis EUR
A5: 3000 | B5: =IFERROR(_xlfn.XLOOKUP(A5,Aktiv!$A:$A,Aktiv!$C:$C,"–"),"") -> Boden | C5: =IFERROR(_xlfn.XLOOKUP(A5,Aktiv!$A:$A,Aktiv!$D:$D,"–"),"") -> Boden (360x360) | D5: =IFERROR(_xlfn.XLOOKUP(A5,Aktiv!$A:$A,Aktiv!$E:$E,"–"),"") -> 360 | E5: =IFERROR(_xlfn.XLOOKUP(A5,Aktiv!$A:$A,Aktiv!$F:$F,"–"),"") -> 360 | F5: =IFERROR(_xlfn.XLOOKUP(A5,Aktiv!$A:$A,Aktiv!$G:$G,"–"),"") -> 25 | G5: =IFERROR(_xlfn.XLOOKUP(A5,Aktiv!$A:$A,Aktiv!$H:$H,"–"),"") -> 103 | H5: =IFERROR(_xlfn.XLOOKUP(A5,Aktiv!$A:$A,Aktiv!$I:$I,"–"),"") -> 120 | I5: =IFERROR(_xlfn.XLOOKUP(A5,Aktiv!$A:$A,Aktiv!$J:$J,"–"),"") -> 145 | J5: =IFERROR(IF(OR(F5=0,G5=0,F5="",G5=""),"-",(G5-F5)/F5),"–") -> 3.12 | K5: =IFERROR(IF(OR(F5=0,H5=0,F5="",H5=""),"-",(H5-F5)/F5),"–") -> 3.8 | L5: =IFERROR(IF(OR(F5=0,I5=0,F5="",I5=""),"-",(I5-F5)/F5),"–") -> 4.8 | M5: =IFERROR(IF(OR(G5=0,H5=0,G5="",H5=""),"-",(H5-G5)/G5),"–") -> 0.16504854 | N5: =IFERROR(IF(OR(G5=0,I5=0,G5="",I5=""),"-",(I5-G5)/G5),"–") -> 0.40776699 | O5: =IFERROR(IF(OR(H5=0,I5=0,H5="",I5=""),"-",(I5-H5)/H5),"–") -> 0.20833333 | P5: =IFERROR(ROUND(AVERAGEIF(F5:I5,"<>0"),0),"–") -> 98
A6: 3001 | B6: =IFERROR(_xlfn.XLOOKUP(A6,Aktiv!$A:$A,Aktiv!$C:$C,"–"),"") -> Boden | C6: =IFERROR(_xlfn.XLOOKUP(A6,Aktiv!$A:$A,Aktiv!$D:$D,"–"),"") -> Boden (420x360) | D6: =IFERROR(_xlfn.XLOOKUP(A6,Aktiv!$A:$A,Aktiv!$E:$E,"–"),"") -> 420 | E6: =IFERROR(_xlfn.XLOOKUP(A6,Aktiv!$A:$A,Aktiv!$F:$F,"–"),"") -> 360 | F6: =IFERROR(_xlfn.XLOOKUP(A6,Aktiv!$A:$A,Aktiv!$G:$G,"–"),"") -> 27 | G6: =IFERROR(_xlfn.XLOOKUP(A6,Aktiv!$A:$A,Aktiv!$H:$H,"–"),"") -> 103 | H6: =IFERROR(_xlfn.XLOOKUP(A6,Aktiv!$A:$A,Aktiv!$I:$I,"–"),"") -> 120 | I6: =IFERROR(_xlfn.XLOOKUP(A6,Aktiv!$A:$A,Aktiv!$J:$J,"–"),"") -> 145 | J6: =IFERROR(IF(OR(F6=0,G6=0,F6="",G6=""),"-",(G6-F6)/F6),"–") -> 2.8148148 | K6: =IFERROR(IF(OR(F6=0,H6=0,F6="",H6=""),"-",(H6-F6)/F6),"–") -> 3.4444444 | L6: =IFERROR(IF(OR(F6=0,I6=0,F6="",I6=""),"-",(I6-F6)/F6),"–") -> 4.3703704 | M6: =IFERROR(IF(OR(G6=0,H6=0,G6="",H6=""),"-",(H6-G6)/G6),"–") -> 0.16504854 | N6: =IFERROR(IF(OR(G6=0,I6=0,G6="",I6=""),"-",(I6-G6)/G6),"–") -> 0.40776699 | O6: =IFERROR(IF(OR(H6=0,I6=0,H6="",I6=""),"-",(I6-H6)/H6),"–") -> 0.20833333 | P6: =IFERROR(ROUND(AVERAGEIF(F6:I6,"<>0"),0),"–") -> 99
A7: 3002 | B7: =IFERROR(_xlfn.XLOOKUP(A7,Aktiv!$A:$A,Aktiv!$C:$C,"–"),"") -> Boden | C7: =IFERROR(_xlfn.XLOOKUP(A7,Aktiv!$A:$A,Aktiv!$D:$D,"–"),"") -> Boden (580x360) | D7: =IFERROR(_xlfn.XLOOKUP(A7,Aktiv!$A:$A,Aktiv!$E:$E,"–"),"") -> 580 | E7: =IFERROR(_xlfn.XLOOKUP(A7,Aktiv!$A:$A,Aktiv!$F:$F,"–"),"") -> 360 | F7: =IFERROR(_xlfn.XLOOKUP(A7,Aktiv!$A:$A,Aktiv!$G:$G,"–"),"") -> 37 | G7: =IFERROR(_xlfn.XLOOKUP(A7,Aktiv!$A:$A,Aktiv!$H:$H,"–"),"") -> 126 | H7: =IFERROR(_xlfn.XLOOKUP(A7,Aktiv!$A:$A,Aktiv!$I:$I,"–"),"") -> 131 | I7: =IFERROR(_xlfn.XLOOKUP(A7,Aktiv!$A:$A,Aktiv!$J:$J,"–"),"") -> 146 | J7: =IFERROR(IF(OR(F7=0,G7=0,F7="",G7=""),"-",(G7-F7)/F7),"–") -> 2.4054054 | K7: =IFERROR(IF(OR(F7=0,H7=0,F7="",H7=""),"-",(H7-F7)/F7),"–") -> 2.5405405 | L7: =IFERROR(IF(OR(F7=0,I7=0,F7="",I7=""),"-",(I7-F7)/F7),"–") -> 2.9459459 | M7: =IFERROR(IF(OR(G7=0,H7=0,G7="",H7=""),"-",(H7-G7)/G7),"–") -> 0.03968254 | N7: =IFERROR(IF(OR(G7=0,I7=0,G7="",I7=""),"-",(I7-G7)/G7),"–") -> 0.15873016 | O7: =IFERROR(IF(OR(H7=0,I7=0,H7="",I7=""),"-",(I7-H7)/H7),"–") -> 0.11450382 | P7: =IFERROR(ROUND(AVERAGEIF(F7:I7,"<>0"),0),"–") -> 110
A8: 3003 | B8: =IFERROR(_xlfn.XLOOKUP(A8,Aktiv!$A:$A,Aktiv!$C:$C,"–"),"") -> Boden | C8: =IFERROR(_xlfn.XLOOKUP(A8,Aktiv!$A:$A,Aktiv!$D:$D,"–"),"") -> Boden (780x360) | D8: =IFERROR(_xlfn.XLOOKUP(A8,Aktiv!$A:$A,Aktiv!$E:$E,"–"),"") -> 780 | E8: =IFERROR(_xlfn.XLOOKUP(A8,Aktiv!$A:$A,Aktiv!$F:$F,"–"),"") -> 360 | F8: =IFERROR(_xlfn.XLOOKUP(A8,Aktiv!$A:$A,Aktiv!$G:$G,"–"),"") -> 49 | G8: =IFERROR(_xlfn.XLOOKUP(A8,Aktiv!$A:$A,Aktiv!$H:$H,"–"),"") -> 169 | H8: =IFERROR(_xlfn.XLOOKUP(A8,Aktiv!$A:$A,Aktiv!$I:$I,"–"),"") -> 177 | I8: =IFERROR(_xlfn.XLOOKUP(A8,Aktiv!$A:$A,Aktiv!$J:$J,"–"),"") -> 196 | J8: =IFERROR(IF(OR(F8=0,G8=0,F8="",G8=""),"-",(G8-F8)/F8),"–") -> 2.4489796 | K8: =IFERROR(IF(OR(F8=0,H8=0,F8="",H8=""),"-",(H8-F8)/F8),"–") -> 2.6122449 | L8: =IFERROR(IF(OR(F8=0,I8=0,F8="",I8=""),"-",(I8-F8)/F8),"–") -> 3 | M8: =IFERROR(IF(OR(G8=0,H8=0,G8="",H8=""),"-",(H8-G8)/G8),"–") -> 0.047337278 | N8: =IFERROR(IF(OR(G8=0,I8=0,G8="",I8=""),"-",(I8-G8)/G8),"–") -> 0.15976331 | O8: =IFERROR(IF(OR(H8=0,I8=0,H8="",I8=""),"-",(I8-H8)/H8),"–") -> 0.10734463 | P8: =IFERROR(ROUND(AVERAGEIF(F8:I8,"<>0"),0),"–") -> 148
A9: 3004 | B9: =IFERROR(_xlfn.XLOOKUP(A9,Aktiv!$A:$A,Aktiv!$C:$C,"–"),"") -> Boden | C9: =IFERROR(_xlfn.XLOOKUP(A9,Aktiv!$A:$A,Aktiv!$D:$D,"–"),"") -> Boden (980x360) | D9: =IFERROR(_xlfn.XLOOKUP(A9,Aktiv!$A:$A,Aktiv!$E:$E,"–"),"") -> 980 | E9: =IFERROR(_xlfn.XLOOKUP(A9,Aktiv!$A:$A,Aktiv!$F:$F,"–"),"") -> 360 | F9: =IFERROR(_xlfn.XLOOKUP(A9,Aktiv!$A:$A,Aktiv!$G:$G,"–"),"") -> 62 | G9: =IFERROR(_xlfn.XLOOKUP(A9,Aktiv!$A:$A,Aktiv!$H:$H,"–"),"") -> 213 | H9: =IFERROR(_xlfn.XLOOKUP(A9,Aktiv!$A:$A,Aktiv!$I:$I,"–"),"") -> 222 | I9: =IFERROR(_xlfn.XLOOKUP(A9,Aktiv!$A:$A,Aktiv!$J:$J,"–"),"") -> 247 | J9: =IFERROR(IF(OR(F9=0,G9=0,F9="",G9=""),"-",(G9-F9)/F9),"–") -> 2.4354839 | K9: =IFERROR(IF(OR(F9=0,H9=0,F9="",H9=""),"-",(H9-F9)/F9),"–") -> 2.5806452 | L9: =IFERROR(IF(OR(F9=0,I9=0,F9="",I9=""),"-",(I9-F9)/F9),"–") -> 2.983871 | M9: =IFERROR(IF(OR(G9=0,H9=0,G9="",H9=""),"-",(H9-G9)/G9),"–") -> 0.042253521 | N9: =IFERROR(IF(OR(G9=0,I9=0,G9="",I9=""),"-",(I9-G9)/G9),"–") -> 0.15962441 | O9: =IFERROR(IF(OR(H9=0,I9=0,H9="",I9=""),"-",(I9-H9)/H9),"–") -> 0.11261261 | P9: =IFERROR(ROUND(AVERAGEIF(F9:I9,"<>0"),0),"–") -> 186
A10: 3005 | B10: =IFERROR(_xlfn.XLOOKUP(A10,Aktiv!$A:$A,Aktiv!$C:$C,"–"),"") -> Boden | C10: =IFERROR(_xlfn.XLOOKUP(A10,Aktiv!$A:$A,Aktiv!$D:$D,"–"),"") -> Boden (360x580) | D10: =IFERROR(_xlfn.XLOOKUP(A10,Aktiv!$A:$A,Aktiv!$E:$E,"–"),"") -> 360 | E10: =IFERROR(_xlfn.XLOOKUP(A10,Aktiv!$A:$A,Aktiv!$F:$F,"–"),"") -> 580 | F10: =IFERROR(_xlfn.XLOOKUP(A10,Aktiv!$A:$A,Aktiv!$G:$G,"–"),"") -> 37 | G10: =IFERROR(_xlfn.XLOOKUP(A10,Aktiv!$A:$A,Aktiv!$H:$H,"–"),"") -> 126 | H10: =IFERROR(_xlfn.XLOOKUP(A10,Aktiv!$A:$A,Aktiv!$I:$I,"–"),"") -> 131 | I10: =IFERROR(_xlfn.XLOOKUP(A10,Aktiv!$A:$A,Aktiv!$J:$J,"–"),"") -> 146 | J10: =IFERROR(IF(OR(F10=0,G10=0,F10="",G10=""),"-",(G10-F10)/F10),"–") -> 2.4054054 | K10: =IFERROR(IF(OR(F10=0,H10=0,F10="",H10=""),"-",(H10-F10)/F10),"–") -> 2.5405405 | L10: =IFERROR(IF(OR(F10=0,I10=0,F10="",I10=""),"-",(I10-F10)/F10),"–") -> 2.9459459 | M10: =IFERROR(IF(OR(G10=0,H10=0,G10="",H10=""),"-",(H10-G10)/G10),"–") -> 0.03968254 | N10: =IFERROR(IF(OR(G10=0,I10=0,G10="",I10=""),"-",(I10-G10)/G10),"–") -> 0.15873016 | O10: =IFERROR(IF(OR(H10=0,I10=0,H10="",I10=""),"-",(I10-H10)/H10),"–") -> 0.11450382 | P10: =IFERROR(ROUND(AVERAGEIF(F10:I10,"<>0"),0),"–") -> 110
A11: 3006 | B11: =IFERROR(_xlfn.XLOOKUP(A11,Aktiv!$A:$A,Aktiv!$C:$C,"–"),"") -> Boden | C11: =IFERROR(_xlfn.XLOOKUP(A11,Aktiv!$A:$A,Aktiv!$D:$D,"–"),"") -> Boden (420x580) | D11: =IFERROR(_xlfn.XLOOKUP(A11,Aktiv!$A:$A,Aktiv!$E:$E,"–"),"") -> 420 | E11: =IFERROR(_xlfn.XLOOKUP(A11,Aktiv!$A:$A,Aktiv!$F:$F,"–"),"") -> 580 | F11: =IFERROR(_xlfn.XLOOKUP(A11,Aktiv!$A:$A,Aktiv!$G:$G,"–"),"") -> 43 | G11: =IFERROR(_xlfn.XLOOKUP(A11,Aktiv!$A:$A,Aktiv!$H:$H,"–"),"") -> 147 | H11: =IFERROR(_xlfn.XLOOKUP(A11,Aktiv!$A:$A,Aktiv!$I:$I,"–"),"") -> 153 | I11: =IFERROR(_xlfn.XLOOKUP(A11,Aktiv!$A:$A,Aktiv!$J:$J,"–"),"") -> 170 | J11: =IFERROR(IF(OR(F11=0,G11=0,F11="",G11=""),"-",(G11-F11)/F11),"–") -> 2.4186047 | K11: =IFERROR(IF(OR(F11=0,H11=0,F11="",H11=""),"-",(H11-F11)/F11),"–") -> 2.5581395 | L11: =IFERROR(IF(OR(F11=0,I11=0,F11="",I11=""),"-",(I11-F11)/F11),"–") -> 2.9534884 | M11: =IFERROR(IF(OR(G11=0,H11=0,G11="",H11=""),"-",(H11-G11)/G11),"–") -> 0.040816327 | N11: =IFERROR(IF(OR(G11=0,I11=0,G11="",I11=""),"-",(I11-G11)/G11),"–") -> 0.15646259 | O11: =IFERROR(IF(OR(H11=0,I11=0,H11="",I11=""),"-",(I11-H11)/H11),"–") -> 0.11111111 | P11: =IFERROR(ROUND(AVERAGEIF(F11:I11,"<>0"),0),"–") -> 128
A12: 3007 | B12: =IFERROR(_xlfn.XLOOKUP(A12,Aktiv!$A:$A,Aktiv!$C:$C,"–"),"") -> Boden | C12: =IFERROR(_xlfn.XLOOKUP(A12,Aktiv!$A:$A,Aktiv!$D:$D,"–"),"") -> Boden (580x580) | D12: =IFERROR(_xlfn.XLOOKUP(A12,Aktiv!$A:$A,Aktiv!$E:$E,"–"),"") -> 580 | E12: =IFERROR(_xlfn.XLOOKUP(A12,Aktiv!$A:$A,Aktiv!$F:$F,"–"),"") -> 580 | F12: =IFERROR(_xlfn.XLOOKUP(A12,Aktiv!$A:$A,Aktiv!$G:$G,"–"),"") -> 59 | G12: =IFERROR(_xlfn.XLOOKUP(A12,Aktiv!$A:$A,Aktiv!$H:$H,"–"),"") -> 203 | H12: =IFERROR(_xlfn.XLOOKUP(A12,Aktiv!$A:$A,Aktiv!$I:$I,"–"),"") -> 211 | I12: =IFERROR(_xlfn.XLOOKUP(A12,Aktiv!$A:$A,Aktiv!$J:$J,"–"),"") -> 235 | J12: =IFERROR(IF(OR(F12=0,G12=0,F12="",G12=""),"-",(G12-F12)/F12),"–") -> 2.440678 | K12: =IFERROR(IF(OR(F12=0,H12=0,F12="",H12=""),"-",(H12-F12)/F12),"–") -> 2.5762712 | L12: =IFERROR(IF(OR(F12=0,I12=0,F12="",I12=""),"-",(I12-F12)/F12),"–") -> 2.9830508 | M12: =IFERROR(IF(OR(G12=0,H12=0,G12="",H12=""),"-",(H12-G12)/G12),"–") -> 0.039408867 | N12: =IFERROR(IF(OR(G12=0,I12=0,G12="",I12=""),"-",(I12-G12)/G12),"–") -> 0.15763547 | O12: =IFERROR(IF(OR(H12=0,I12=0,H12="",I12=""),"-",(I12-H12)/H12),"–") -> 0.11374408 | P12: =IFERROR(ROUND(AVERAGEIF(F12:I12,"<>0"),0),"–") -> 177
A13: 3008 | B13: =IFERROR(_xlfn.XLOOKUP(A13,Aktiv!$A:$A,Aktiv!$C:$C,"–"),"") -> Boden | C13: =IFERROR(_xlfn.XLOOKUP(A13,Aktiv!$A:$A,Aktiv!$D:$D,"–"),"") -> Boden (780x580) | D13: =IFERROR(_xlfn.XLOOKUP(A13,Aktiv!$A:$A,Aktiv!$E:$E,"–"),"") -> 780 | E13: =IFERROR(_xlfn.XLOOKUP(A13,Aktiv!$A:$A,Aktiv!$F:$F,"–"),"") -> 580 | F13: =IFERROR(_xlfn.XLOOKUP(A13,Aktiv!$A:$A,Aktiv!$G:$G,"–"),"") -> 80 | G13: =IFERROR(_xlfn.XLOOKUP(A13,Aktiv!$A:$A,Aktiv!$H:$H,"–"),"") -> 273 | H13: =IFERROR(_xlfn.XLOOKUP(A13,Aktiv!$A:$A,Aktiv!$I:$I,"–"),"") -> 284 | I13: =IFERROR(_xlfn.XLOOKUP(A13,Aktiv!$A:$A,Aktiv!$J:$J,"–"),"") -> 316 | J13: =IFERROR(IF(OR(F13=0,G13=0,F13="",G13=""),"-",(G13-F13)/F13),"–") -> 2.4125 | K13: =IFERROR(IF(OR(F13=0,H13=0,F13="",H13=""),"-",(H13-F13)/F13),"–") -> 2.55 | L13: =IFERROR(IF(OR(F13=0,I13=0,F13="",I13=""),"-",(I13-F13)/F13),"–") -> 2.95 | M13: =IFERROR(IF(OR(G13=0,H13=0,G13="",H13=""),"-",(H13-G13)/G13),"–") -> 0.04029304 | N13: =IFERROR(IF(OR(G13=0,I13=0,G13="",I13=""),"-",(I13-G13)/G13),"–") -> 0.15750916 | O13: =IFERROR(IF(OR(H13=0,I13=0,H13="",I13=""),"-",(I13-H13)/H13),"–") -> 0.11267606 | P13: =IFERROR(ROUND(AVERAGEIF(F13:I13,"<>0"),0),"–") -> 238
A14: 3009 | B14: =IFERROR(_xlfn.XLOOKUP(A14,Aktiv!$A:$A,Aktiv!$C:$C,"–"),"") -> Boden | C14: =IFERROR(_xlfn.XLOOKUP(A14,Aktiv!$A:$A,Aktiv!$D:$D,"–"),"") -> Boden (980x580) | D14: =IFERROR(_xlfn.XLOOKUP(A14,Aktiv!$A:$A,Aktiv!$E:$E,"–"),"") -> 980 | E14: =IFERROR(_xlfn.XLOOKUP(A14,Aktiv!$A:$A,Aktiv!$F:$F,"–"),"") -> 580 | F14: =IFERROR(_xlfn.XLOOKUP(A14,Aktiv!$A:$A,Aktiv!$G:$G,"–"),"") -> 100 | G14: =IFERROR(_xlfn.XLOOKUP(A14,Aktiv!$A:$A,Aktiv!$H:$H,"–"),"") -> 343 | H14: =IFERROR(_xlfn.XLOOKUP(A14,Aktiv!$A:$A,Aktiv!$I:$I,"–"),"") -> 357 | I14: =IFERROR(_xlfn.XLOOKUP(A14,Aktiv!$A:$A,Aktiv!$J:$J,"–"),"") -> 398 | J14: =IFERROR(IF(OR(F14=0,G14=0,F14="",G14=""),"-",(G14-F14)/F14),"–") -> 2.43 | K14: =IFERROR(IF(OR(F14=0,H14=0,F14="",H14=""),"-",(H14-F14)/F14),"–") -> 2.57 | L14: =IFERROR(IF(OR(F14=0,I14=0,F14="",I14=""),"-",(I14-F14)/F14),"–") -> 2.98 | M14: =IFERROR(IF(OR(G14=0,H14=0,G14="",H14=""),"-",(H14-G14)/G14),"–") -> 0.040816327 | N14: =IFERROR(IF(OR(G14=0,I14=0,G14="",I14=""),"-",(I14-G14)/G14),"–") -> 0.16034985 | O14: =IFERROR(IF(OR(H14=0,I14=0,H14="",I14=""),"-",(I14-H14)/H14),"–") -> 0.11484594 | P14: =IFERROR(ROUND(AVERAGEIF(F14:I14,"<>0"),0),"–") -> 300
A15: 3010 | B15: =IFERROR(_xlfn.XLOOKUP(A15,Aktiv!$A:$A,Aktiv!$C:$C,"–"),"") -> Boden | C15: =IFERROR(_xlfn.XLOOKUP(A15,Aktiv!$A:$A,Aktiv!$D:$D,"–"),"") -> Boden (780x780) | D15: =IFERROR(_xlfn.XLOOKUP(A15,Aktiv!$A:$A,Aktiv!$E:$E,"–"),"") -> 780 | E15: =IFERROR(_xlfn.XLOOKUP(A15,Aktiv!$A:$A,Aktiv!$F:$F,"–"),"") -> 780 | F15: =IFERROR(_xlfn.XLOOKUP(A15,Aktiv!$A:$A,Aktiv!$G:$G,"–"),"") -> 107 | G15: =IFERROR(_xlfn.XLOOKUP(A15,Aktiv!$A:$A,Aktiv!$H:$H,"–"),"") -> 367 | H15: =IFERROR(_xlfn.XLOOKUP(A15,Aktiv!$A:$A,Aktiv!$I:$I,"–"),"") -> 382 | I15: =IFERROR(_xlfn.XLOOKUP(A15,Aktiv!$A:$A,Aktiv!$J:$J,"–"),"") -> 426 | J15: =IFERROR(IF(OR(F15=0,G15=0,F15="",G15=""),"-",(G15-F15)/F15),"–") -> 2.4299065 | K15: =IFERROR(IF(OR(F15=0,H15=0,F15="",H15=""),"-",(H15-F15)/F15),"–") -> 2.5700935 | L15: =IFERROR(IF(OR(F15=0,I15=0,F15="",I15=""),"-",(I15-F15)/F15),"–") -> 2.9813084 | M15: =IFERROR(IF(OR(G15=0,H15=0,G15="",H15=""),"-",(H15-G15)/G15),"–") -> 0.040871935 | N15: =IFERROR(IF(OR(G15=0,I15=0,G15="",I15=""),"-",(I15-G15)/G15),"–") -> 0.16076294 | O15: =IFERROR(IF(OR(H15=0,I15=0,H15="",I15=""),"-",(I15-H15)/H15),"–") -> 0.11518325 | P15: =IFERROR(ROUND(AVERAGEIF(F15:I15,"<>0"),0),"–") -> 321
A16: 3011 | B16: =IFERROR(_xlfn.XLOOKUP(A16,Aktiv!$A:$A,Aktiv!$C:$C,"–"),"") -> Boden | C16: =IFERROR(_xlfn.XLOOKUP(A16,Aktiv!$A:$A,Aktiv!$D:$D,"–"),"") -> Boden (980x780) | D16: =IFERROR(_xlfn.XLOOKUP(A16,Aktiv!$A:$A,Aktiv!$E:$E,"–"),"") -> 980 | E16: =IFERROR(_xlfn.XLOOKUP(A16,Aktiv!$A:$A,Aktiv!$F:$F,"–"),"") -> 780 | F16: =IFERROR(_xlfn.XLOOKUP(A16,Aktiv!$A:$A,Aktiv!$G:$G,"–"),"") -> 135 | G16: =IFERROR(_xlfn.XLOOKUP(A16,Aktiv!$A:$A,Aktiv!$H:$H,"–"),"") -> 461 | H16: =IFERROR(_xlfn.XLOOKUP(A16,Aktiv!$A:$A,Aktiv!$I:$I,"–"),"") -> 480 | I16: =IFERROR(_xlfn.XLOOKUP(A16,Aktiv!$A:$A,Aktiv!$J:$J,"–"),"") -> 535 | J16: =IFERROR(IF(OR(F16=0,G16=0,F16="",G16=""),"-",(G16-F16)/F16),"–") -> 2.4148148 | K16: =IFERROR(IF(OR(F16=0,H16=0,F16="",H16=""),"-",(H16-F16)/F16),"–") -> 2.5555556 | L16: =IFERROR(IF(OR(F16=0,I16=0,F16="",I16=""),"-",(I16-F16)/F16),"–") -> 2.962963 | M16: =IFERROR(IF(OR(G16=0,H16=0,G16="",H16=""),"-",(H16-G16)/G16),"–") -> 0.041214751 | N16: =IFERROR(IF(OR(G16=0,I16=0,G16="",I16=""),"-",(I16-G16)/G16),"–") -> 0.16052061 | O16: =IFERROR(IF(OR(H16=0,I16=0,H16="",I16=""),"-",(I16-H16)/H16),"–") -> 0.11458333 | P16: =IFERROR(ROUND(AVERAGEIF(F16:I16,"<>0"),0),"–") -> 403
... A19: 3014 | B19: =IFERROR(_xlfn.XLOOKUP(A19,Aktiv!$A:$A,Aktiv!$C:$C,"–"),"") -> Boden | C19: =IFERROR(_xlfn.XLOOKUP(A19,Aktiv!$A:$A,Aktiv!$D:$D,"–"),"") -> Boden (420x980) | D19: =IFERROR(_xlfn.XLOOKUP(A19,Aktiv!$A:$A,Aktiv!$E:$E,"–"),"") -> 420 | E19: =IFERROR(_xlfn.XLOOKUP(A19,Aktiv!$A:$A,Aktiv!$F:$F,"–"),"") -> 980 | F19: =IFERROR(_xlfn.XLOOKUP(A19,Aktiv!$A:$A,Aktiv!$G:$G,"–"),"") -> 72 | G19: =IFERROR(_xlfn.XLOOKUP(A19,Aktiv!$A:$A,Aktiv!$H:$H,"–"),"") -> 248 | H19: =IFERROR(_xlfn.XLOOKUP(A19,Aktiv!$A:$A,Aktiv!$I:$I,"–"),"") -> 259 | I19: =IFERROR(_xlfn.XLOOKUP(A19,Aktiv!$A:$A,Aktiv!$J:$J,"–"),"") -> 288 | J19: =IFERROR(IF(OR(F19=0,G19=0,F19="",G19=""),"-",(G19-F19)/F19),"–") -> 2.4444444 | K19: =IFERROR(IF(OR(F19=0,H19=0,F19="",H19=""),"-",(H19-F19)/F19),"–") -> 2.5972222 | L19: =IFERROR(IF(OR(F19=0,I19=0,F19="",I19=""),"-",(I19-F19)/F19),"–") -> 3 | M19: =IFERROR(IF(OR(G19=0,H19=0,G19="",H19=""),"-",(H19-G19)/G19),"–") -> 0.044354839 | N19: =IFERROR(IF(OR(G19=0,I19=0,G19="",I19=""),"-",(I19-G19)/G19),"–") -> 0.16129032 | O19: =IFERROR(IF(OR(H19=0,I19=0,H19="",I19=""),"-",(I19-H19)/H19),"–") -> 0.11196911 | P19: =IFERROR(ROUND(AVERAGEIF(F19:I19,"<>0"),0),"–") -> 217
A20: S_0003 | B20: =IFERROR(_xlfn.XLOOKUP(A20,Aktiv!$A:$A,Aktiv!$C:$C,"–"),"") -> Boden | C20: =IFERROR(_xlfn.XLOOKUP(A20,Aktiv!$A:$A,Aktiv!$D:$D,"–"),"") -> Boden (420x420) | D20: =IFERROR(_xlfn.XLOOKUP(A20,Aktiv!$A:$A,Aktiv!$E:$E,"–"),"") -> 420 | E20: =IFERROR(_xlfn.XLOOKUP(A20,Aktiv!$A:$A,Aktiv!$F:$F,"–"),"") -> 420 | F20: =IFERROR(_xlfn.XLOOKUP(A20,Aktiv!$A:$A,Aktiv!$G:$G,"–"),"") -> 31 | G20: =IFERROR(_xlfn.XLOOKUP(A20,Aktiv!$A:$A,Aktiv!$H:$H,"–"),"") -> 106 | H20: =IFERROR(_xlfn.XLOOKUP(A20,Aktiv!$A:$A,Aktiv!$I:$I,"–"),"") -> 120 | I20: =IFERROR(_xlfn.XLOOKUP(A20,Aktiv!$A:$A,Aktiv!$J:$J,"–"),"") -> 145 | J20: =IFERROR(IF(OR(F20=0,G20=0,F20="",G20=""),"-",(G20-F20)/F20),"–") -> 2.4193548 | K20: =IFERROR(IF(OR(F20=0,H20=0,F20="",H20=""),"-",(H20-F20)/F20),"–") -> 2.8709677 | L20: =IFERROR(IF(OR(F20=0,I20=0,F20="",I20=""),"-",(I20-F20)/F20),"–") -> 3.6774194 | M20: =IFERROR(IF(OR(G20=0,H20=0,G20="",H20=""),"-",(H20-G20)/G20),"–") -> 0.13207547 | N20: =IFERROR(IF(OR(G20=0,I20=0,G20="",I20=""),"-",(I20-G20)/G20),"–") -> 0.36792453 | O20: =IFERROR(IF(OR(H20=0,I20=0,H20="",I20=""),"-",(I20-H20)/H20),"–") -> 0.20833333 | P20: =IFERROR(ROUND(AVERAGEIF(F20:I20,"<>0"),0),"–") -> 101
A21: 5200 | B21: =IFERROR(_xlfn.XLOOKUP(A21,Aktiv!$A:$A,Aktiv!$C:$C,"–"),"") -> Doppeltür | C21: =IFERROR(_xlfn.XLOOKUP(A21,Aktiv!$A:$A,Aktiv!$D:$D,"–"),"") -> Doppeltür (780x360) | D21: =IFERROR(_xlfn.XLOOKUP(A21,Aktiv!$A:$A,Aktiv!$E:$E,"–"),"") -> 780 | E21: =IFERROR(_xlfn.XLOOKUP(A21,Aktiv!$A:$A,Aktiv!$F:$F,"–"),"") -> 360 | F21: =IFERROR(_xlfn.XLOOKUP(A21,Aktiv!$A:$A,Aktiv!$G:$G,"–"),"") -> 212 | G21: =IFERROR(_xlfn.XLOOKUP(A21,Aktiv!$A:$A,Aktiv!$H:$H,"–"),"") -> 300 | H21: =IFERROR(_xlfn.XLOOKUP(A21,Aktiv!$A:$A,Aktiv!$I:$I,"–"),"") -> 316 | I21: =IFERROR(_xlfn.XLOOKUP(A21,Aktiv!$A:$A,Aktiv!$J:$J,"–"),"") -> 697 | J21: =IFERROR(IF(OR(F21=0,G21=0,F21="",G21=""),"-",(G21-F21)/F21),"–") -> 0.41509434 | K21: =IFERROR(IF(OR(F21=0,H21=0,F21="",H21=""),"-",(H21-F21)/F21),"–") -> 0.49056604 | L21: =IFERROR(IF(OR(F21=0,I21=0,F21="",I21=""),"-",(I21-F21)/F21),"–") -> 2.2877358 | M21: =IFERROR(IF(OR(G21=0,H21=0,G21="",H21=""),"-",(H21-G21)/G21),"–") -> 0.053333333 | N21: =IFERROR(IF(OR(G21=0,I21=0,G21="",I21=""),"-",(I21-G21)/G21),"–") -> 1.3233333 | O21: =IFERROR(IF(OR(H21=0,I21=0,H21="",I21=""),"-",(I21-H21)/H21),"–") -> 1.2056962 | P21: =IFERROR(ROUND(AVERAGEIF(F21:I21,"<>0"),0),"–") -> 381
A22: 5201 | B22: =IFERROR(_xlfn.XLOOKUP(A22,Aktiv!$A:$A,Aktiv!$C:$C,"–"),"") -> Doppeltür | C22: =IFERROR(_xlfn.XLOOKUP(A22,Aktiv!$A:$A,Aktiv!$D:$D,"–"),"") -> Doppeltür (780x720) | D22: =IFERROR(_xlfn.XLOOKUP(A22,Aktiv!$A:$A,Aktiv!$E:$E,"–"),"") -> 780 | E22: =IFERROR(_xlfn.XLOOKUP(A22,Aktiv!$A:$A,Aktiv!$F:$F,"–"),"") -> 720 | F22: =IFERROR(_xlfn.XLOOKUP(A22,Aktiv!$A:$A,Aktiv!$G:$G,"–"),"") -> 344 | G22: =IFERROR(_xlfn.XLOOKUP(A22,Aktiv!$A:$A,Aktiv!$H:$H,"–"),"") -> 487 | H22: =IFERROR(_xlfn.XLOOKUP(A22,Aktiv!$A:$A,Aktiv!$I:$I,"–"),"") -> 514 | I22: =IFERROR(_xlfn.XLOOKUP(A22,Aktiv!$A:$A,Aktiv!$J:$J,"–"),"") -> 1132 | J22: =IFERROR(IF(OR(F22=0,G22=0,F22="",G22=""),"-",(G22-F22)/F22),"–") -> 0.41569767 | K22: =IFERROR(IF(OR(F22=0,H22=0,F22="",H22=""),"-",(H22-F22)/F22),"–") -> 0.49418605 | L22: =IFERROR(IF(OR(F22=0,I22=0,F22="",I22=""),"-",(I22-F22)/F22),"–") -> 2.2906977 | M22: =IFERROR(IF(OR(G22=0,H22=0,G22="",H22=""),"-",(H22-G22)/G22),"–") -> 0.055441478 | N22: =IFERROR(IF(OR(G22=0,I22=0,G22="",I22=""),"-",(I22-G22)/G22),"–") -> 1.3244353 | O22: =IFERROR(IF(OR(H22=0,I22=0,H22="",I22=""),"-",(I22-H22)/H22),"–") -> 1.2023346 | P22: =IFERROR(ROUND(AVERAGEIF(F22:I22,"<>0"),0),"–") -> 619
A23: 5202 | B23: =IFERROR(_xlfn.XLOOKUP(A23,Aktiv!$A:$A,Aktiv!$C:$C,"–"),"") -> Doppeltür | C23: =IFERROR(_xlfn.XLOOKUP(A23,Aktiv!$A:$A,Aktiv!$D:$D,"–"),"") -> Doppeltür (780x1080) | D23: =IFERROR(_xlfn.XLOOKUP(A23,Aktiv!$A:$A,Aktiv!$E:$E,"–"),"") -> 780 | E23: =IFERROR(_xlfn.XLOOKUP(A23,Aktiv!$A:$A,Aktiv!$F:$F,"–"),"") -> 1080 | F23: =IFERROR(_xlfn.XLOOKUP(A23,Aktiv!$A:$A,Aktiv!$G:$G,"–"),"") -> 456 | G23: =IFERROR(_xlfn.XLOOKUP(A23,Aktiv!$A:$A,Aktiv!$H:$H,"–"),"") -> 646 | H23: =IFERROR(_xlfn.XLOOKUP(A23,Aktiv!$A:$A,Aktiv!$I:$I,"–"),"") -> 682 | I23: =IFERROR(_xlfn.XLOOKUP(A23,Aktiv!$A:$A,Aktiv!$J:$J,"–"),"") -> 1504 | J23: =IFERROR(IF(OR(F23=0,G23=0,F23="",G23=""),"-",(G23-F23)/F23),"–") -> 0.41666667 | K23: =IFERROR(IF(OR(F23=0,H23=0,F23="",H23=""),"-",(H23-F23)/F23),"–") -> 0.49561404 | L23: =IFERROR(IF(OR(F23=0,I23=0,F23="",I23=""),"-",(I23-F23)/F23),"–") -> 2.2982456 | M23: =IFERROR(IF(OR(G23=0,H23=0,G23="",H23=""),"-",(H23-G23)/G23),"–") -> 0.055727554 | N23: =IFERROR(IF(OR(G23=0,I23=0,G23="",I23=""),"-",(I23-G23)/G23),"–") -> 1.3281734 | O23: =IFERROR(IF(OR(H23=0,I23=0,H23="",I23=""),"-",(I23-H23)/H23),"–") -> 1.2052786 | P23: =IFERROR(ROUND(AVERAGEIF(F23:I23,"<>0"),0),"–") -> 822
A24: 5203 | B24: =IFERROR(_xlfn.XLOOKUP(A24,Aktiv!$A:$A,Aktiv!$C:$C,"–"),"") -> Doppeltür | C24: =IFERROR(_xlfn.XLOOKUP(A24,Aktiv!$A:$A,Aktiv!$D:$D,"–"),"") -> Doppeltür (780x1440) | D24: =IFERROR(_xlfn.XLOOKUP(A24,Aktiv!$A:$A,Aktiv!$E:$E,"–"),"") -> 780 | E24: =IFERROR(_xlfn.XLOOKUP(A24,Aktiv!$A:$A,Aktiv!$F:$F,"–"),"") -> 1440 | F24: =IFERROR(_xlfn.XLOOKUP(A24,Aktiv!$A:$A,Aktiv!$G:$G,"–"),"") -> 558 | G24: =IFERROR(_xlfn.XLOOKUP(A24,Aktiv!$A:$A,Aktiv!$H:$H,"–"),"") -> 790 | H24: =IFERROR(_xlfn.XLOOKUP(A24,Aktiv!$A:$A,Aktiv!$I:$I,"–"),"") -> 834 | I24: =IFERROR(_xlfn.XLOOKUP(A24,Aktiv!$A:$A,Aktiv!$J:$J,"–"),"") -> 1839 | J24: =IFERROR(IF(OR(F24=0,G24=0,F24="",G24=""),"-",(G24-F24)/F24),"–") -> 0.41577061 | K24: =IFERROR(IF(OR(F24=0,H24=0,F24="",H24=""),"-",(H24-F24)/F24),"–") -> 0.49462366 | L24: =IFERROR(IF(OR(F24=0,I24=0,F24="",I24=""),"-",(I24-F24)/F24),"–") -> 2.2956989 | M24: =IFERROR(IF(OR(G24=0,H24=0,G24="",H24=""),"-",(H24-G24)/G24),"–") -> 0.055696203 | N24: =IFERROR(IF(OR(G24=0,I24=0,G24="",I24=""),"-",(I24-G24)/G24),"–") -> 1.3278481 | O24: =IFERROR(IF(OR(H24=0,I24=0,H24="",I24=""),"-",(I24-H24)/H24),"–") -> 1.205036 | P24: =IFERROR(ROUND(AVERAGEIF(F24:I24,"<>0"),0),"–") -> 1005
A25: 5204 | B25: =IFERROR(_xlfn.XLOOKUP(A25,Aktiv!$A:$A,Aktiv!$C:$C,"–"),"") -> Doppeltür | C25: =IFERROR(_xlfn.XLOOKUP(A25,Aktiv!$A:$A,Aktiv!$D:$D,"–"),"") -> Doppeltür (780x1800) | D25: =IFERROR(_xlfn.XLOOKUP(A25,Aktiv!$A:$A,Aktiv!$E:$E,"–"),"") -> 780 | E25: =IFERROR(_xlfn.XLOOKUP(A25,Aktiv!$A:$A,Aktiv!$F:$F,"–"),"") -> 1800 | F25: =IFERROR(_xlfn.XLOOKUP(A25,Aktiv!$A:$A,Aktiv!$G:$G,"–"),"") -> 653 | G25: =IFERROR(_xlfn.XLOOKUP(A25,Aktiv!$A:$A,Aktiv!$H:$H,"–"),"") -> 924 | H25: =IFERROR(_xlfn.XLOOKUP(A25,Aktiv!$A:$A,Aktiv!$I:$I,"–"),"") -> 975 | I25: =IFERROR(_xlfn.XLOOKUP(A25,Aktiv!$A:$A,Aktiv!$J:$J,"–"),"") -> 2150 | J25: =IFERROR(IF(OR(F25=0,G25=0,F25="",G25=""),"-",(G25-F25)/F25),"–") -> 0.41500766 | K25: =IFERROR(IF(OR(F25=0,H25=0,F25="",H25=""),"-",(H25-F25)/F25),"–") -> 0.49310873 | L25: =IFERROR(IF(OR(F25=0,I25=0,F25="",I25=""),"-",(I25-F25)/F25),"–") -> 2.2924962 | M25: =IFERROR(IF(OR(G25=0,H25=0,G25="",H25=""),"-",(H25-G25)/G25),"–") -> 0.055194805 | N25: =IFERROR(IF(OR(G25=0,I25=0,G25="",I25=""),"-",(I25-G25)/G25),"–") -> 1.3268398 | O25: =IFERROR(IF(OR(H25=0,I25=0,H25="",I25=""),"-",(I25-H25)/H25),"–") -> 1.2051282 | P25: =IFERROR(ROUND(AVERAGEIF(F25:I25,"<>0"),0),"–") -> 1176
A26: 5205 | B26: =IFERROR(_xlfn.XLOOKUP(A26,Aktiv!$A:$A,Aktiv!$C:$C,"–"),"") -> Doppeltür | C26: =IFERROR(_xlfn.XLOOKUP(A26,Aktiv!$A:$A,Aktiv!$D:$D,"–"),"") -> Doppeltür (980x360) | D26: =IFERROR(_xlfn.XLOOKUP(A26,Aktiv!$A:$A,Aktiv!$E:$E,"–"),"") -> 980 | E26: =IFERROR(_xlfn.XLOOKUP(A26,Aktiv!$A:$A,Aktiv!$F:$F,"–"),"") -> 360 | F26: =IFERROR(_xlfn.XLOOKUP(A26,Aktiv!$A:$A,Aktiv!$G:$G,"–"),"") -> 248 | G26: =IFERROR(_xlfn.XLOOKUP(A26,Aktiv!$A:$A,Aktiv!$H:$H,"–"),"") -> 351 | H26: =IFERROR(_xlfn.XLOOKUP(A26,Aktiv!$A:$A,Aktiv!$I:$I,"–"),"") -> 371 | I26: =IFERROR(_xlfn.XLOOKUP(A26,Aktiv!$A:$A,Aktiv!$J:$J,"–"),"") -> 818 | J26: =IFERROR(IF(OR(F26=0,G26=0,F26="",G26=""),"-",(G26-F26)/F26),"–") -> 0.41532258 | K26: =IFERROR(IF(OR(F26=0,H26=0,F26="",H26=""),"-",(H26-F26)/F26),"–") -> 0.49596774 | L26: =IFERROR(IF(OR(F26=0,I26=0,F26="",I26=""),"-",(I26-F26)/F26),"–") -> 2.2983871 | M26: =IFERROR(IF(OR(G26=0,H26=0,G26="",H26=""),"-",(H26-G26)/G26),"–") -> 0.056980057 | N26: =IFERROR(IF(OR(G26=0,I26=0,G26="",I26=""),"-",(I26-G26)/G26),"–") -> 1.3304843 | O26: =IFERROR(IF(OR(H26=0,I26=0,H26="",I26=""),"-",(I26-H26)/H26),"–") -> 1.2048518 | P26: =IFERROR(ROUND(AVERAGEIF(F26:I26,"<>0"),0),"–") -> 447
A27: 5206 | B27: =IFERROR(_xlfn.XLOOKUP(A27,Aktiv!$A:$A,Aktiv!$C:$C,"–"),"") -> Doppeltür | C27: =IFERROR(_xlfn.XLOOKUP(A27,Aktiv!$A:$A,Aktiv!$D:$D,"–"),"") -> Doppeltür (980x720) | D27: =IFERROR(_xlfn.XLOOKUP(A27,Aktiv!$A:$A,Aktiv!$E:$E,"–"),"") -> 980 | E27: =IFERROR(_xlfn.XLOOKUP(A27,Aktiv!$A:$A,Aktiv!$F:$F,"–"),"") -> 720 | F27: =IFERROR(_xlfn.XLOOKUP(A27,Aktiv!$A:$A,Aktiv!$G:$G,"–"),"") -> 403 | G27: =IFERROR(_xlfn.XLOOKUP(A27,Aktiv!$A:$A,Aktiv!$H:$H,"–"),"") -> 571 | H27: =IFERROR(_xlfn.XLOOKUP(A27,Aktiv!$A:$A,Aktiv!$I:$I,"–"),"") -> 602 | I27: =IFERROR(_xlfn.XLOOKUP(A27,Aktiv!$A:$A,Aktiv!$J:$J,"–"),"") -> 1328 | J27: =IFERROR(IF(OR(F27=0,G27=0,F27="",G27=""),"-",(G27-F27)/F27),"–") -> 0.41687345 | K27: =IFERROR(IF(OR(F27=0,H27=0,F27="",H27=""),"-",(H27-F27)/F27),"–") -> 0.49379653 | L27: =IFERROR(IF(OR(F27=0,I27=0,F27="",I27=""),"-",(I27-F27)/F27),"–") -> 2.2952854 | M27: =IFERROR(IF(OR(G27=0,H27=0,G27="",H27=""),"-",(H27-G27)/G27),"–") -> 0.054290718 | N27: =IFERROR(IF(OR(G27=0,I27=0,G27="",I27=""),"-",(I27-G27)/G27),"–") -> 1.3257443 | O27: =IFERROR(IF(OR(H27=0,I27=0,H27="",I27=""),"-",(I27-H27)/H27),"–") -> 1.2059801 | P27: =IFERROR(ROUND(AVERAGEIF(F27:I27,"<>0"),0),"–") -> 726
A28: 5207 | B28: =IFERROR(_xlfn.XLOOKUP(A28,Aktiv!$A:$A,Aktiv!$C:$C,"–"),"") -> Doppeltür | C28: =IFERROR(_xlfn.XLOOKUP(A28,Aktiv!$A:$A,Aktiv!$D:$D,"–"),"") -> Doppeltür (980x1080) | D28: =IFERROR(_xlfn.XLOOKUP(A28,Aktiv!$A:$A,Aktiv!$E:$E,"–"),"") -> 980 | E28: =IFERROR(_xlfn.XLOOKUP(A28,Aktiv!$A:$A,Aktiv!$F:$F,"–"),"") -> 1080 | F28: =IFERROR(_xlfn.XLOOKUP(A28,Aktiv!$A:$A,Aktiv!$G:$G,"–"),"") -> 536 | G28: =IFERROR(_xlfn.XLOOKUP(A28,Aktiv!$A:$A,Aktiv!$H:$H,"–"),"") -> 758 | H28: =IFERROR(_xlfn.XLOOKUP(A28,Aktiv!$A:$A,Aktiv!$I:$I,"–"),"") -> 800 | I28: =IFERROR(_xlfn.XLOOKUP(A28,Aktiv!$A:$A,Aktiv!$J:$J,"–"),"") -> 1764 | J28: =IFERROR(IF(OR(F28=0,G28=0,F28="",G28=""),"-",(G28-F28)/F28),"–") -> 0.4141791 | K28: =IFERROR(IF(OR(F28=0,H28=0,F28="",H28=""),"-",(H28-F28)/F28),"–") -> 0.49253731 | L28: =IFERROR(IF(OR(F28=0,I28=0,F28="",I28=""),"-",(I28-F28)/F28),"–") -> 2.2910448 | M28: =IFERROR(IF(OR(G28=0,H28=0,G28="",H28=""),"-",(H28-G28)/G28),"–") -> 0.055408971 | N28: =IFERROR(IF(OR(G28=0,I28=0,G28="",I28=""),"-",(I28-G28)/G28),"–") -> 1.3271768 | O28: =IFERROR(IF(OR(H28=0,I28=0,H28="",I28=""),"-",(I28-H28)/H28),"–") -> 1.205 | P28: =IFERROR(ROUND(AVERAGEIF(F28:I28,"<>0"),0),"–") -> 965
A29: 5208 | B29: =IFERROR(_xlfn.XLOOKUP(A29,Aktiv!$A:$A,Aktiv!$C:$C,"–"),"") -> Doppeltür | C29: =IFERROR(_xlfn.XLOOKUP(A29,Aktiv!$A:$A,Aktiv!$D:$D,"–"),"") -> Doppeltür (980x1440) | D29: =IFERROR(_xlfn.XLOOKUP(A29,Aktiv!$A:$A,Aktiv!$E:$E,"–"),"") -> 980 | E29: =IFERROR(_xlfn.XLOOKUP(A29,Aktiv!$A:$A,Aktiv!$F:$F,"–"),"") -> 1440 | F29: =IFERROR(_xlfn.XLOOKUP(A29,Aktiv!$A:$A,Aktiv!$G:$G,"–"),"") -> - | G29: =IFERROR(_xlfn.XLOOKUP(A29,Aktiv!$A:$A,Aktiv!$H:$H,"–"),"") -> - | H29: =IFERROR(_xlfn.XLOOKUP(A29,Aktiv!$A:$A,Aktiv!$I:$I,"–"),"") -> - | I29: =IFERROR(_xlfn.XLOOKUP(A29,Aktiv!$A:$A,Aktiv!$J:$J,"–"),"") -> - | J29: =IFERROR(IF(OR(F29=0,G29=0,F29="",G29=""),"-",(G29-F29)/F29),"–") -> – | K29: =IFERROR(IF(OR(F29=0,H29=0,F29="",H29=""),"-",(H29-F29)/F29),"–") -> – | L29: =IFERROR(IF(OR(F29=0,I29=0,F29="",I29=""),"-",(I29-F29)/F29),"–") -> – | M29: =IFERROR(IF(OR(G29=0,H29=0,G29="",H29=""),"-",(H29-G29)/G29),"–") -> – | N29: =IFERROR(IF(OR(G29=0,I29=0,G29="",I29=""),"-",(I29-G29)/G29),"–") -> – | O29: =IFERROR(IF(OR(H29=0,I29=0,H29="",I29=""),"-",(I29-H29)/H29),"–") -> – | P29: =IFERROR(ROUND(AVERAGEIF(F29:I29,"<>0"),0),"–") -> –
A30: 5209 | B30: =IFERROR(_xlfn.XLOOKUP(A30,Aktiv!$A:$A,Aktiv!$C:$C,"–"),"") -> Doppeltür | C30: =IFERROR(_xlfn.XLOOKUP(A30,Aktiv!$A:$A,Aktiv!$D:$D,"–"),"") -> Doppeltür (980x1800) | D30: =IFERROR(_xlfn.XLOOKUP(A30,Aktiv!$A:$A,Aktiv!$E:$E,"–"),"") -> 980 | E30: =IFERROR(_xlfn.XLOOKUP(A30,Aktiv!$A:$A,Aktiv!$F:$F,"–"),"") -> 1800 | F30: =IFERROR(_xlfn.XLOOKUP(A30,Aktiv!$A:$A,Aktiv!$G:$G,"–"),"") -> - | G30: =IFERROR(_xlfn.XLOOKUP(A30,Aktiv!$A:$A,Aktiv!$H:$H,"–"),"") -> - | H30: =IFERROR(_xlfn.XLOOKUP(A30,Aktiv!$A:$A,Aktiv!$I:$I,"–"),"") -> - | I30: =IFERROR(_xlfn.XLOOKUP(A30,Aktiv!$A:$A,Aktiv!$J:$J,"–"),"") -> - | J30: =IFERROR(IF(OR(F30=0,G30=0,F30="",G30=""),"-",(G30-F30)/F30),"–") -> – | K30: =IFERROR(IF(OR(F30=0,H30=0,F30="",H30=""),"-",(H30-F30)/F30),"–") -> – | L30: =IFERROR(IF(OR(F30=0,I30=0,F30="",I30=""),"-",(I30-F30)/F30),"–") -> – | M30: =IFERROR(IF(OR(G30=0,H30=0,G30="",H30=""),"-",(H30-G30)/G30),"–") -> – | N30: =IFERROR(IF(OR(G30=0,I30=0,G30="",I30=""),"-",(I30-G30)/G30),"–") -> – | O30: =IFERROR(IF(OR(H30=0,I30=0,H30="",I30=""),"-",(I30-H30)/H30),"–") -> – | P30: =IFERROR(ROUND(AVERAGEIF(F30:I30,"<>0"),0),"–") -> –
A31: 5210 | B31: =IFERROR(_xlfn.XLOOKUP(A31,Aktiv!$A:$A,Aktiv!$C:$C,"–"),"") -> Doppeltür | C31: =IFERROR(_xlfn.XLOOKUP(A31,Aktiv!$A:$A,Aktiv!$D:$D,"–"),"") -> Doppeltür (780x660) | D31: =IFERROR(_xlfn.XLOOKUP(A31,Aktiv!$A:$A,Aktiv!$E:$E,"–"),"") -> 780 | E31: =IFERROR(_xlfn.XLOOKUP(A31,Aktiv!$A:$A,Aktiv!$F:$F,"–"),"") -> 660 | F31: =IFERROR(_xlfn.XLOOKUP(A31,Aktiv!$A:$A,Aktiv!$G:$G,"–"),"") -> 323 | G31: =IFERROR(_xlfn.XLOOKUP(A31,Aktiv!$A:$A,Aktiv!$H:$H,"–"),"") -> 458 | H31: =IFERROR(_xlfn.XLOOKUP(A31,Aktiv!$A:$A,Aktiv!$I:$I,"–"),"") -> 483 | I31: =IFERROR(_xlfn.XLOOKUP(A31,Aktiv!$A:$A,Aktiv!$J:$J,"–"),"") -> 1065 | J31: =IFERROR(IF(OR(F31=0,G31=0,F31="",G31=""),"-",(G31-F31)/F31),"–") -> 0.41795666 | K31: =IFERROR(IF(OR(F31=0,H31=0,F31="",H31=""),"-",(H31-F31)/F31),"–") -> 0.49535604 | L31: =IFERROR(IF(OR(F31=0,I31=0,F31="",I31=""),"-",(I31-F31)/F31),"–") -> 2.2972136 | M31: =IFERROR(IF(OR(G31=0,H31=0,G31="",H31=""),"-",(H31-G31)/G31),"–") -> 0.054585153 | N31: =IFERROR(IF(OR(G31=0,I31=0,G31="",I31=""),"-",(I31-G31)/G31),"–") -> 1.3253275 | O31: =IFERROR(IF(OR(H31=0,I31=0,H31="",I31=""),"-",(I31-H31)/H31),"–") -> 1.2049689 | P31: =IFERROR(ROUND(AVERAGEIF(F31:I31,"<>0"),0),"–") -> 582
A32: 3750 | B32: =IFERROR(_xlfn.XLOOKUP(A32,Aktiv!$A:$A,Aktiv!$C:$C,"–"),"") -> Fachboden groß | C32: =IFERROR(_xlfn.XLOOKUP(A32,Aktiv!$A:$A,Aktiv!$D:$D,"–"),"") -> Fachboden groß (360x360) | D32: =IFERROR(_xlfn.XLOOKUP(A32,Aktiv!$A:$A,Aktiv!$E:$E,"–"),"") -> 360 | E32: =IFERROR(_xlfn.XLOOKUP(A32,Aktiv!$A:$A,Aktiv!$F:$F,"–"),"") -> 360 | F32: =IFERROR(_xlfn.XLOOKUP(A32,Aktiv!$A:$A,Aktiv!$G:$G,"–"),"") -> 25 | G32: =IFERROR(_xlfn.XLOOKUP(A32,Aktiv!$A:$A,Aktiv!$H:$H,"–"),"") -> 103 | H32: =IFERROR(_xlfn.XLOOKUP(A32,Aktiv!$A:$A,Aktiv!$I:$I,"–"),"") -> 120 | I32: =IFERROR(_xlfn.XLOOKUP(A32,Aktiv!$A:$A,Aktiv!$J:$J,"–"),"") -> 145 | J32: =IFERROR(IF(OR(F32=0,G32=0,F32="",G32=""),"-",(G32-F32)/F32),"–") -> 3.12 | K32: =IFERROR(IF(OR(F32=0,H32=0,F32="",H32=""),"-",(H32-F32)/F32),"–") -> 3.8 | L32: =IFERROR(IF(OR(F32=0,I32=0,F32="",I32=""),"-",(I32-F32)/F32),"–") -> 4.8 | M32: =IFERROR(IF(OR(G32=0,H32=0,G32="",H32=""),"-",(H32-G32)/G32),"–") -> 0.16504854 | N32: =IFERROR(IF(OR(G32=0,I32=0,G32="",I32=""),"-",(I32-G32)/G32),"–") -> 0.40776699 | O32: =IFERROR(IF(OR(H32=0,I32=0,H32="",I32=""),"-",(I32-H32)/H32),"–") -> 0.20833333 | P32: =IFERROR(ROUND(AVERAGEIF(F32:I32,"<>0"),0),"–") -> 98
... A67: 5009 | B67: =IFERROR(_xlfn.XLOOKUP(A67,Aktiv!$A:$A,Aktiv!$C:$C,"–"),"") -> Klappe | C67: =IFERROR(_xlfn.XLOOKUP(A67,Aktiv!$A:$A,Aktiv!$D:$D,"–"),"") -> Klappe (360x180) | D67: =IFERROR(_xlfn.XLOOKUP(A67,Aktiv!$A:$A,Aktiv!$E:$E,"–"),"") -> 360 | E67: =IFERROR(_xlfn.XLOOKUP(A67,Aktiv!$A:$A,Aktiv!$F:$F,"–"),"") -> 180 | F67: =IFERROR(_xlfn.XLOOKUP(A67,Aktiv!$A:$A,Aktiv!$G:$G,"–"),"") -> - | G67: =IFERROR(_xlfn.XLOOKUP(A67,Aktiv!$A:$A,Aktiv!$H:$H,"–"),"") -> - | H67: =IFERROR(_xlfn.XLOOKUP(A67,Aktiv!$A:$A,Aktiv!$I:$I,"–"),"") -> - | I67: =IFERROR(_xlfn.XLOOKUP(A67,Aktiv!$A:$A,Aktiv!$J:$J,"–"),"") -> - | J67: =IFERROR(IF(OR(F67=0,G67=0,F67="",G67=""),"-",(G67-F67)/F67),"–") -> – | K67: =IFERROR(IF(OR(F67=0,H67=0,F67="",H67=""),"-",(H67-F67)/F67),"–") -> – | L67: =IFERROR(IF(OR(F67=0,I67=0,F67="",I67=""),"-",(I67-F67)/F67),"–") -> – | M67: =IFERROR(IF(OR(G67=0,H67=0,G67="",H67=""),"-",(H67-G67)/G67),"–") -> – | N67: =IFERROR(IF(OR(G67=0,I67=0,G67="",I67=""),"-",(I67-G67)/G67),"–") -> – | O67: =IFERROR(IF(OR(H67=0,I67=0,H67="",I67=""),"-",(I67-H67)/H67),"–") -> – | P67: =IFERROR(ROUND(AVERAGEIF(F67:I67,"<>0"),0),"–") -> –
A68: S_0046 | B68: =IFERROR(_xlfn.XLOOKUP(A68,Aktiv!$A:$A,Aktiv!$C:$C,"–"),"") -> Klappe | C68: =IFERROR(_xlfn.XLOOKUP(A68,Aktiv!$A:$A,Aktiv!$D:$D,"–"),"") -> Klappe (980x420) | D68: =IFERROR(_xlfn.XLOOKUP(A68,Aktiv!$A:$A,Aktiv!$E:$E,"–"),"") -> 980 | E68: =IFERROR(_xlfn.XLOOKUP(A68,Aktiv!$A:$A,Aktiv!$F:$F,"–"),"") -> 420 | F68: =IFERROR(_xlfn.XLOOKUP(A68,Aktiv!$A:$A,Aktiv!$G:$G,"–"),"") -> - | G68: =IFERROR(_xlfn.XLOOKUP(A68,Aktiv!$A:$A,Aktiv!$H:$H,"–"),"") -> - | H68: =IFERROR(_xlfn.XLOOKUP(A68,Aktiv!$A:$A,Aktiv!$I:$I,"–"),"") -> - | I68: =IFERROR(_xlfn.XLOOKUP(A68,Aktiv!$A:$A,Aktiv!$J:$J,"–"),"") -> - | J68: =IFERROR(IF(OR(F68=0,G68=0,F68="",G68=""),"-",(G68-F68)/F68),"–") -> – | K68: =IFERROR(IF(OR(F68=0,H68=0,F68="",H68=""),"-",(H68-F68)/F68),"–") -> – | L68: =IFERROR(IF(OR(F68=0,I68=0,F68="",I68=""),"-",(I68-F68)/F68),"–") -> – | M68: =IFERROR(IF(OR(G68=0,H68=0,G68="",H68=""),"-",(H68-G68)/G68),"–") -> – | N68: =IFERROR(IF(OR(G68=0,I68=0,G68="",I68=""),"-",(I68-G68)/G68),"–") -> – | O68: =IFERROR(IF(OR(H68=0,I68=0,H68="",I68=""),"-",(I68-H68)/H68),"–") -> – | P68: =IFERROR(ROUND(AVERAGEIF(F68:I68,"<>0"),0),"–") -> –
A69: 3800 | B69: =IFERROR(_xlfn.XLOOKUP(A69,Aktiv!$A:$A,Aktiv!$C:$C,"–"),"") -> Klappenboden | C69: =IFERROR(_xlfn.XLOOKUP(A69,Aktiv!$A:$A,Aktiv!$D:$D,"–"),"") -> Klappenboden (360x360) | D69: =IFERROR(_xlfn.XLOOKUP(A69,Aktiv!$A:$A,Aktiv!$E:$E,"–"),"") -> 360 | E69: =IFERROR(_xlfn.XLOOKUP(A69,Aktiv!$A:$A,Aktiv!$F:$F,"–"),"") -> 360 | F69: =IFERROR(_xlfn.XLOOKUP(A69,Aktiv!$A:$A,Aktiv!$G:$G,"–"),"") -> 25 | G69: =IFERROR(_xlfn.XLOOKUP(A69,Aktiv!$A:$A,Aktiv!$H:$H,"–"),"") -> 103 | H69: =IFERROR(_xlfn.XLOOKUP(A69,Aktiv!$A:$A,Aktiv!$I:$I,"–"),"") -> 120 | I69: =IFERROR(_xlfn.XLOOKUP(A69,Aktiv!$A:$A,Aktiv!$J:$J,"–"),"") -> 145 | J69: =IFERROR(IF(OR(F69=0,G69=0,F69="",G69=""),"-",(G69-F69)/F69),"–") -> 3.12 | K69: =IFERROR(IF(OR(F69=0,H69=0,F69="",H69=""),"-",(H69-F69)/F69),"–") -> 3.8 | L69: =IFERROR(IF(OR(F69=0,I69=0,F69="",I69=""),"-",(I69-F69)/F69),"–") -> 4.8 | M69: =IFERROR(IF(OR(G69=0,H69=0,G69="",H69=""),"-",(H69-G69)/G69),"–") -> 0.16504854 | N69: =IFERROR(IF(OR(G69=0,I69=0,G69="",I69=""),"-",(I69-G69)/G69),"–") -> 0.40776699 | O69: =IFERROR(IF(OR(H69=0,I69=0,H69="",I69=""),"-",(I69-H69)/H69),"–") -> 0.20833333 | P69: =IFERROR(ROUND(AVERAGEIF(F69:I69,"<>0"),0),"–") -> 98
A70: 3801 | B70: =IFERROR(_xlfn.XLOOKUP(A70,Aktiv!$A:$A,Aktiv!$C:$C,"–"),"") -> Klappenboden | C70: =IFERROR(_xlfn.XLOOKUP(A70,Aktiv!$A:$A,Aktiv!$D:$D,"–"),"") -> Klappenboden (420x360) | D70: =IFERROR(_xlfn.XLOOKUP(A70,Aktiv!$A:$A,Aktiv!$E:$E,"–"),"") -> 420 | E70: =IFERROR(_xlfn.XLOOKUP(A70,Aktiv!$A:$A,Aktiv!$F:$F,"–"),"") -> 360 | F70: =IFERROR(_xlfn.XLOOKUP(A70,Aktiv!$A:$A,Aktiv!$G:$G,"–"),"") -> 27 | G70: =IFERROR(_xlfn.XLOOKUP(A70,Aktiv!$A:$A,Aktiv!$H:$H,"–"),"") -> 103 | H70: =IFERROR(_xlfn.XLOOKUP(A70,Aktiv!$A:$A,Aktiv!$I:$I,"–"),"") -> 120 | I70: =IFERROR(_xlfn.XLOOKUP(A70,Aktiv!$A:$A,Aktiv!$J:$J,"–"),"") -> 145 | J70: =IFERROR(IF(OR(F70=0,G70=0,F70="",G70=""),"-",(G70-F70)/F70),"–") -> 2.8148148 | K70: =IFERROR(IF(OR(F70=0,H70=0,F70="",H70=""),"-",(H70-F70)/F70),"–") -> 3.4444444 | L70: =IFERROR(IF(OR(F70=0,I70=0,F70="",I70=""),"-",(I70-F70)/F70),"–") -> 4.3703704 | M70: =IFERROR(IF(OR(G70=0,H70=0,G70="",H70=""),"-",(H70-G70)/G70),"–") -> 0.16504854 | N70: =IFERROR(IF(OR(G70=0,I70=0,G70="",I70=""),"-",(I70-G70)/G70),"–") -> 0.40776699 | O70: =IFERROR(IF(OR(H70=0,I70=0,H70="",I70=""),"-",(I70-H70)/H70),"–") -> 0.20833333 | P70: =IFERROR(ROUND(AVERAGEIF(F70:I70,"<>0"),0),"–") -> 99
A71: 3802 | B71: =IFERROR(_xlfn.XLOOKUP(A71,Aktiv!$A:$A,Aktiv!$C:$C,"–"),"") -> Klappenboden | C71: =IFERROR(_xlfn.XLOOKUP(A71,Aktiv!$A:$A,Aktiv!$D:$D,"–"),"") -> Klappenboden (580x360) | D71: =IFERROR(_xlfn.XLOOKUP(A71,Aktiv!$A:$A,Aktiv!$E:$E,"–"),"") -> 580 | E71: =IFERROR(_xlfn.XLOOKUP(A71,Aktiv!$A:$A,Aktiv!$F:$F,"–"),"") -> 360 | F71: =IFERROR(_xlfn.XLOOKUP(A71,Aktiv!$A:$A,Aktiv!$G:$G,"–"),"") -> 37 | G71: =IFERROR(_xlfn.XLOOKUP(A71,Aktiv!$A:$A,Aktiv!$H:$H,"–"),"") -> 126 | H71: =IFERROR(_xlfn.XLOOKUP(A71,Aktiv!$A:$A,Aktiv!$I:$I,"–"),"") -> 131 | I71: =IFERROR(_xlfn.XLOOKUP(A71,Aktiv!$A:$A,Aktiv!$J:$J,"–"),"") -> 146 | J71: =IFERROR(IF(OR(F71=0,G71=0,F71="",G71=""),"-",(G71-F71)/F71),"–") -> 2.4054054 | K71: =IFERROR(IF(OR(F71=0,H71=0,F71="",H71=""),"-",(H71-F71)/F71),"–") -> 2.5405405 | L71: =IFERROR(IF(OR(F71=0,I71=0,F71="",I71=""),"-",(I71-F71)/F71),"–") -> 2.9459459 | M71: =IFERROR(IF(OR(G71=0,H71=0,G71="",H71=""),"-",(H71-G71)/G71),"–") -> 0.03968254 | N71: =IFERROR(IF(OR(G71=0,I71=0,G71="",I71=""),"-",(I71-G71)/G71),"–") -> 0.15873016 | O71: =IFERROR(IF(OR(H71=0,I71=0,H71="",I71=""),"-",(I71-H71)/H71),"–") -> 0.11450382 | P71: =IFERROR(ROUND(AVERAGEIF(F71:I71,"<>0"),0),"–") -> 110
A72: 3803 | B72: =IFERROR(_xlfn.XLOOKUP(A72,Aktiv!$A:$A,Aktiv!$C:$C,"–"),"") -> Klappenboden | C72: =IFERROR(_xlfn.XLOOKUP(A72,Aktiv!$A:$A,Aktiv!$D:$D,"–"),"") -> Klappenboden (780x360) | D72: =IFERROR(_xlfn.XLOOKUP(A72,Aktiv!$A:$A,Aktiv!$E:$E,"–"),"") -> 780 | E72: =IFERROR(_xlfn.XLOOKUP(A72,Aktiv!$A:$A,Aktiv!$F:$F,"–"),"") -> 360 | F72: =IFERROR(_xlfn.XLOOKUP(A72,Aktiv!$A:$A,Aktiv!$G:$G,"–"),"") -> 49 | G72: =IFERROR(_xlfn.XLOOKUP(A72,Aktiv!$A:$A,Aktiv!$H:$H,"–"),"") -> 169 | H72: =IFERROR(_xlfn.XLOOKUP(A72,Aktiv!$A:$A,Aktiv!$I:$I,"–"),"") -> 177 | I72: =IFERROR(_xlfn.XLOOKUP(A72,Aktiv!$A:$A,Aktiv!$J:$J,"–"),"") -> 196 | J72: =IFERROR(IF(OR(F72=0,G72=0,F72="",G72=""),"-",(G72-F72)/F72),"–") -> 2.4489796 | K72: =IFERROR(IF(OR(F72=0,H72=0,F72="",H72=""),"-",(H72-F72)/F72),"–") -> 2.6122449 | L72: =IFERROR(IF(OR(F72=0,I72=0,F72="",I72=""),"-",(I72-F72)/F72),"–") -> 3 | M72: =IFERROR(IF(OR(G72=0,H72=0,G72="",H72=""),"-",(H72-G72)/G72),"–") -> 0.047337278 | N72: =IFERROR(IF(OR(G72=0,I72=0,G72="",I72=""),"-",(I72-G72)/G72),"–") -> 0.15976331 | O72: =IFERROR(IF(OR(H72=0,I72=0,H72="",I72=""),"-",(I72-H72)/H72),"–") -> 0.10734463 | P72: =IFERROR(ROUND(AVERAGEIF(F72:I72,"<>0"),0),"–") -> 148
A73: 3804 | B73: =IFERROR(_xlfn.XLOOKUP(A73,Aktiv!$A:$A,Aktiv!$C:$C,"–"),"") -> Klappenboden | C73: =IFERROR(_xlfn.XLOOKUP(A73,Aktiv!$A:$A,Aktiv!$D:$D,"–"),"") -> Klappenboden (980x360) | D73: =IFERROR(_xlfn.XLOOKUP(A73,Aktiv!$A:$A,Aktiv!$E:$E,"–"),"") -> 980 | E73: =IFERROR(_xlfn.XLOOKUP(A73,Aktiv!$A:$A,Aktiv!$F:$F,"–"),"") -> 360 | F73: =IFERROR(_xlfn.XLOOKUP(A73,Aktiv!$A:$A,Aktiv!$G:$G,"–"),"") -> 62 | G73: =IFERROR(_xlfn.XLOOKUP(A73,Aktiv!$A:$A,Aktiv!$H:$H,"–"),"") -> 213 | H73: =IFERROR(_xlfn.XLOOKUP(A73,Aktiv!$A:$A,Aktiv!$I:$I,"–"),"") -> 222 | I73: =IFERROR(_xlfn.XLOOKUP(A73,Aktiv!$A:$A,Aktiv!$J:$J,"–"),"") -> 247 | J73: =IFERROR(IF(OR(F73=0,G73=0,F73="",G73=""),"-",(G73-F73)/F73),"–") -> 2.4354839 | K73: =IFERROR(IF(OR(F73=0,H73=0,F73="",H73=""),"-",(H73-F73)/F73),"–") -> 2.5806452 | L73: =IFERROR(IF(OR(F73=0,I73=0,F73="",I73=""),"-",(I73-F73)/F73),"–") -> 2.983871 | M73: =IFERROR(IF(OR(G73=0,H73=0,G73="",H73=""),"-",(H73-G73)/G73),"–") -> 0.042253521 | N73: =IFERROR(IF(OR(G73=0,I73=0,G73="",I73=""),"-",(I73-G73)/G73),"–") -> 0.15962441 | O73: =IFERROR(IF(OR(H73=0,I73=0,H73="",I73=""),"-",(I73-H73)/H73),"–") -> 0.11261261 | P73: =IFERROR(ROUND(AVERAGEIF(F73:I73,"<>0"),0),"–") -> 186
A74: 3805 | B74: =IFERROR(_xlfn.XLOOKUP(A74,Aktiv!$A:$A,Aktiv!$C:$C,"–"),"") -> Klappenboden | C74: =IFERROR(_xlfn.XLOOKUP(A74,Aktiv!$A:$A,Aktiv!$D:$D,"–"),"") -> Klappenboden (360x580) | D74: =IFERROR(_xlfn.XLOOKUP(A74,Aktiv!$A:$A,Aktiv!$E:$E,"–"),"") -> 360 | E74: =IFERROR(_xlfn.XLOOKUP(A74,Aktiv!$A:$A,Aktiv!$F:$F,"–"),"") -> 580 | F74: =IFERROR(_xlfn.XLOOKUP(A74,Aktiv!$A:$A,Aktiv!$G:$G,"–"),"") -> 37 | G74: =IFERROR(_xlfn.XLOOKUP(A74,Aktiv!$A:$A,Aktiv!$H:$H,"–"),"") -> 126 | H74: =IFERROR(_xlfn.XLOOKUP(A74,Aktiv!$A:$A,Aktiv!$I:$I,"–"),"") -> 131 | I74: =IFERROR(_xlfn.XLOOKUP(A74,Aktiv!$A:$A,Aktiv!$J:$J,"–"),"") -> 146 | J74: =IFERROR(IF(OR(F74=0,G74=0,F74="",G74=""),"-",(G74-F74)/F74),"–") -> 2.4054054 | K74: =IFERROR(IF(OR(F74=0,H74=0,F74="",H74=""),"-",(H74-F74)/F74),"–") -> 2.5405405 | L74: =IFERROR(IF(OR(F74=0,I74=0,F74="",I74=""),"-",(I74-F74)/F74),"–") -> 2.9459459 | M74: =IFERROR(IF(OR(G74=0,H74=0,G74="",H74=""),"-",(H74-G74)/G74),"–") -> 0.03968254 | N74: =IFERROR(IF(OR(G74=0,I74=0,G74="",I74=""),"-",(I74-G74)/G74),"–") -> 0.15873016 | O74: =IFERROR(IF(OR(H74=0,I74=0,H74="",I74=""),"-",(I74-H74)/H74),"–") -> 0.11450382 | P74: =IFERROR(ROUND(AVERAGEIF(F74:I74,"<>0"),0),"–") -> 110
A75: 3806 | B75: =IFERROR(_xlfn.XLOOKUP(A75,Aktiv!$A:$A,Aktiv!$C:$C,"–"),"") -> Klappenboden | C75: =IFERROR(_xlfn.XLOOKUP(A75,Aktiv!$A:$A,Aktiv!$D:$D,"–"),"") -> Klappenboden (420x580) | D75: =IFERROR(_xlfn.XLOOKUP(A75,Aktiv!$A:$A,Aktiv!$E:$E,"–"),"") -> 420 | E75: =IFERROR(_xlfn.XLOOKUP(A75,Aktiv!$A:$A,Aktiv!$F:$F,"–"),"") -> 580 | F75: =IFERROR(_xlfn.XLOOKUP(A75,Aktiv!$A:$A,Aktiv!$G:$G,"–"),"") -> 43 | G75: =IFERROR(_xlfn.XLOOKUP(A75,Aktiv!$A:$A,Aktiv!$H:$H,"–"),"") -> 147 | H75: =IFERROR(_xlfn.XLOOKUP(A75,Aktiv!$A:$A,Aktiv!$I:$I,"–"),"") -> 153 | I75: =IFERROR(_xlfn.XLOOKUP(A75,Aktiv!$A:$A,Aktiv!$J:$J,"–"),"") -> 170 | J75: =IFERROR(IF(OR(F75=0,G75=0,F75="",G75=""),"-",(G75-F75)/F75),"–") -> 2.4186047 | K75: =IFERROR(IF(OR(F75=0,H75=0,F75="",H75=""),"-",(H75-F75)/F75),"–") -> 2.5581395 | L75: =IFERROR(IF(OR(F75=0,I75=0,F75="",I75=""),"-",(I75-F75)/F75),"–") -> 2.9534884 | M75: =IFERROR(IF(OR(G75=0,H75=0,G75="",H75=""),"-",(H75-G75)/G75),"–") -> 0.040816327 | N75: =IFERROR(IF(OR(G75=0,I75=0,G75="",I75=""),"-",(I75-G75)/G75),"–") -> 0.15646259 | O75: =IFERROR(IF(OR(H75=0,I75=0,H75="",I75=""),"-",(I75-H75)/H75),"–") -> 0.11111111 | P75: =IFERROR(ROUND(AVERAGEIF(F75:I75,"<>0"),0),"–") -> 128
A76: 3807 | B76: =IFERROR(_xlfn.XLOOKUP(A76,Aktiv!$A:$A,Aktiv!$C:$C,"–"),"") -> Klappenboden | C76: =IFERROR(_xlfn.XLOOKUP(A76,Aktiv!$A:$A,Aktiv!$D:$D,"–"),"") -> Klappenboden (580x580) | D76: =IFERROR(_xlfn.XLOOKUP(A76,Aktiv!$A:$A,Aktiv!$E:$E,"–"),"") -> 580 | E76: =IFERROR(_xlfn.XLOOKUP(A76,Aktiv!$A:$A,Aktiv!$F:$F,"–"),"") -> 580 | F76: =IFERROR(_xlfn.XLOOKUP(A76,Aktiv!$A:$A,Aktiv!$G:$G,"–"),"") -> 59 | G76: =IFERROR(_xlfn.XLOOKUP(A76,Aktiv!$A:$A,Aktiv!$H:$H,"–"),"") -> 203 | H76: =IFERROR(_xlfn.XLOOKUP(A76,Aktiv!$A:$A,Aktiv!$I:$I,"–"),"") -> 211 | I76: =IFERROR(_xlfn.XLOOKUP(A76,Aktiv!$A:$A,Aktiv!$J:$J,"–"),"") -> 235 | J76: =IFERROR(IF(OR(F76=0,G76=0,F76="",G76=""),"-",(G76-F76)/F76),"–") -> 2.440678 | K76: =IFERROR(IF(OR(F76=0,H76=0,F76="",H76=""),"-",(H76-F76)/F76),"–") -> 2.5762712 | L76: =IFERROR(IF(OR(F76=0,I76=0,F76="",I76=""),"-",(I76-F76)/F76),"–") -> 2.9830508 | M76: =IFERROR(IF(OR(G76=0,H76=0,G76="",H76=""),"-",(H76-G76)/G76),"–") -> 0.039408867 | N76: =IFERROR(IF(OR(G76=0,I76=0,G76="",I76=""),"-",(I76-G76)/G76),"–") -> 0.15763547 | O76: =IFERROR(IF(OR(H76=0,I76=0,H76="",I76=""),"-",(I76-H76)/H76),"–") -> 0.11374408 | P76: =IFERROR(ROUND(AVERAGEIF(F76:I76,"<>0"),0),"–") -> 177
A77: 3808 | B77: =IFERROR(_xlfn.XLOOKUP(A77,Aktiv!$A:$A,Aktiv!$C:$C,"–"),"") -> Klappenboden | C77: =IFERROR(_xlfn.XLOOKUP(A77,Aktiv!$A:$A,Aktiv!$D:$D,"–"),"") -> Klappenboden (780x580) | D77: =IFERROR(_xlfn.XLOOKUP(A77,Aktiv!$A:$A,Aktiv!$E:$E,"–"),"") -> 780 | E77: =IFERROR(_xlfn.XLOOKUP(A77,Aktiv!$A:$A,Aktiv!$F:$F,"–"),"") -> 580 | F77: =IFERROR(_xlfn.XLOOKUP(A77,Aktiv!$A:$A,Aktiv!$G:$G,"–"),"") -> 80 | G77: =IFERROR(_xlfn.XLOOKUP(A77,Aktiv!$A:$A,Aktiv!$H:$H,"–"),"") -> 273 | H77: =IFERROR(_xlfn.XLOOKUP(A77,Aktiv!$A:$A,Aktiv!$I:$I,"–"),"") -> 284 | I77: =IFERROR(_xlfn.XLOOKUP(A77,Aktiv!$A:$A,Aktiv!$J:$J,"–"),"") -> 316 | J77: =IFERROR(IF(OR(F77=0,G77=0,F77="",G77=""),"-",(G77-F77)/F77),"–") -> 2.4125 | K77: =IFERROR(IF(OR(F77=0,H77=0,F77="",H77=""),"-",(H77-F77)/F77),"–") -> 2.55 | L77: =IFERROR(IF(OR(F77=0,I77=0,F77="",I77=""),"-",(I77-F77)/F77),"–") -> 2.95 | M77: =IFERROR(IF(OR(G77=0,H77=0,G77="",H77=""),"-",(H77-G77)/G77),"–") -> 0.04029304 | N77: =IFERROR(IF(OR(G77=0,I77=0,G77="",I77=""),"-",(I77-G77)/G77),"–") -> 0.15750916 | O77: =IFERROR(IF(OR(H77=0,I77=0,H77="",I77=""),"-",(I77-H77)/H77),"–") -> 0.11267606 | P77: =IFERROR(ROUND(AVERAGEIF(F77:I77,"<>0"),0),"–") -> 238
...

Sheet Konfigurator_Export
A1: art_nr | B1: typ | C1: kategorie | D1: bezeichnung | E1: breite_mm | F1: tiefe_mm | G1: pg1_mdf_eur | H1: pg2_furnier_eur | I1: pg3_alu_eur | J1: pg4_glas_eur | K1: pg1_mdf_chf | L1: pg2_furnier_chf | M1: pg3_alu_chf | N1: pg4_glas_chf | O1: warnung
A2: 3000 | B2: Platte | C2: Boden | D2: Boden (360x360) | E2: 360 | F2: 360 | G2: =IFERROR(INDEX(Aktiv!$G$6:$G$326,MATCH(A2,Aktiv!$A$6:$A$326,0)),"") -> 25 | H2: =IFERROR(INDEX(Aktiv!$H$6:$H$326,MATCH(A2,Aktiv!$A$6:$A$326,0)),"") -> 103 | I2: =IFERROR(INDEX(Aktiv!$I$6:$I$326,MATCH(A2,Aktiv!$A$6:$A$326,0)),"") -> 120 | J2: =IFERROR(INDEX(Aktiv!$J$6:$J$326,MATCH(A2,Aktiv!$A$6:$A$326,0)),"") -> 145 | K2: =IFERROR(ROUND(G2*Steuerungsdaten!$B$5,0),"-") -> 29 | L2: =IFERROR(ROUND(H2*Steuerungsdaten!$B$5,0),"-") -> 118 | M2: =IFERROR(ROUND(I2*Steuerungsdaten!$B$5,0),"-") -> 138 | N2: =IFERROR(ROUND(J2*Steuerungsdaten!$B$5,0),"-") -> 167 | O2: =IF(ISNA(MATCH(A2,Aktiv!$A$6:$A$326,0)),"⚠ nicht im Modell","")
A3: 3001 | B3: Platte | C3: Boden | D3: Boden (420x360) | E3: 420 | F3: 360 | G3: =IFERROR(INDEX(Aktiv!$G$6:$G$326,MATCH(A3,Aktiv!$A$6:$A$326,0)),"") -> 27 | H3: =IFERROR(INDEX(Aktiv!$H$6:$H$326,MATCH(A3,Aktiv!$A$6:$A$326,0)),"") -> 103 | I3: =IFERROR(INDEX(Aktiv!$I$6:$I$326,MATCH(A3,Aktiv!$A$6:$A$326,0)),"") -> 120 | J3: =IFERROR(INDEX(Aktiv!$J$6:$J$326,MATCH(A3,Aktiv!$A$6:$A$326,0)),"") -> 145 | K3: =IFERROR(ROUND(G3*Steuerungsdaten!$B$5,0),"-") -> 31 | L3: =IFERROR(ROUND(H3*Steuerungsdaten!$B$5,0),"-") -> 118 | M3: =IFERROR(ROUND(I3*Steuerungsdaten!$B$5,0),"-") -> 138 | N3: =IFERROR(ROUND(J3*Steuerungsdaten!$B$5,0),"-") -> 167 | O3: =IF(ISNA(MATCH(A3,Aktiv!$A$6:$A$326,0)),"⚠ nicht im Modell","")
A4: 3002 | B4: Platte | C4: Boden | D4: Boden (580x360) | E4: 580 | F4: 360 | G4: =IFERROR(INDEX(Aktiv!$G$6:$G$326,MATCH(A4,Aktiv!$A$6:$A$326,0)),"") -> 37 | H4: =IFERROR(INDEX(Aktiv!$H$6:$H$326,MATCH(A4,Aktiv!$A$6:$A$326,0)),"") -> 126 | I4: =IFERROR(INDEX(Aktiv!$I$6:$I$326,MATCH(A4,Aktiv!$A$6:$A$326,0)),"") -> 131 | J4: =IFERROR(INDEX(Aktiv!$J$6:$J$326,MATCH(A4,Aktiv!$A$6:$A$326,0)),"") -> 146 | K4: =IFERROR(ROUND(G4*Steuerungsdaten!$B$5,0),"-") -> 43 | L4: =IFERROR(ROUND(H4*Steuerungsdaten!$B$5,0),"-") -> 145 | M4: =IFERROR(ROUND(I4*Steuerungsdaten!$B$5,0),"-") -> 151 | N4: =IFERROR(ROUND(J4*Steuerungsdaten!$B$5,0),"-") -> 168 | O4: =IF(ISNA(MATCH(A4,Aktiv!$A$6:$A$326,0)),"⚠ nicht im Modell","")
A5: 3003 | B5: Platte | C5: Boden | D5: Boden (780x360) | E5: 780 | F5: 360 | G5: =IFERROR(INDEX(Aktiv!$G$6:$G$326,MATCH(A5,Aktiv!$A$6:$A$326,0)),"") -> 49 | H5: =IFERROR(INDEX(Aktiv!$H$6:$H$326,MATCH(A5,Aktiv!$A$6:$A$326,0)),"") -> 169 | I5: =IFERROR(INDEX(Aktiv!$I$6:$I$326,MATCH(A5,Aktiv!$A$6:$A$326,0)),"") -> 177 | J5: =IFERROR(INDEX(Aktiv!$J$6:$J$326,MATCH(A5,Aktiv!$A$6:$A$326,0)),"") -> 196 | K5: =IFERROR(ROUND(G5*Steuerungsdaten!$B$5,0),"-") -> 56 | L5: =IFERROR(ROUND(H5*Steuerungsdaten!$B$5,0),"-") -> 194 | M5: =IFERROR(ROUND(I5*Steuerungsdaten!$B$5,0),"-") -> 204 | N5: =IFERROR(ROUND(J5*Steuerungsdaten!$B$5,0),"-") -> 225 | O5: =IF(ISNA(MATCH(A5,Aktiv!$A$6:$A$326,0)),"⚠ nicht im Modell","")
A6: 3004 | B6: Platte | C6: Boden | D6: Boden (980x360) | E6: 980 | F6: 360 | G6: =IFERROR(INDEX(Aktiv!$G$6:$G$326,MATCH(A6,Aktiv!$A$6:$A$326,0)),"") -> 62 | H6: =IFERROR(INDEX(Aktiv!$H$6:$H$326,MATCH(A6,Aktiv!$A$6:$A$326,0)),"") -> 213 | I6: =IFERROR(INDEX(Aktiv!$I$6:$I$326,MATCH(A6,Aktiv!$A$6:$A$326,0)),"") -> 222 | J6: =IFERROR(INDEX(Aktiv!$J$6:$J$326,MATCH(A6,Aktiv!$A$6:$A$326,0)),"") -> 247 | K6: =IFERROR(ROUND(G6*Steuerungsdaten!$B$5,0),"-") -> 71 | L6: =IFERROR(ROUND(H6*Steuerungsdaten!$B$5,0),"-") -> 245 | M6: =IFERROR(ROUND(I6*Steuerungsdaten!$B$5,0),"-") -> 255 | N6: =IFERROR(ROUND(J6*Steuerungsdaten!$B$5,0),"-") -> 284 | O6: =IF(ISNA(MATCH(A6,Aktiv!$A$6:$A$326,0)),"⚠ nicht im Modell","")
A7: 3005 | B7: Platte | C7: Boden | D7: Boden (360x580) | E7: 360 | F7: 580 | G7: =IFERROR(INDEX(Aktiv!$G$6:$G$326,MATCH(A7,Aktiv!$A$6:$A$326,0)),"") -> 37 | H7: =IFERROR(INDEX(Aktiv!$H$6:$H$326,MATCH(A7,Aktiv!$A$6:$A$326,0)),"") -> 126 | I7: =IFERROR(INDEX(Aktiv!$I$6:$I$326,MATCH(A7,Aktiv!$A$6:$A$326,0)),"") -> 131 | J7: =IFERROR(INDEX(Aktiv!$J$6:$J$326,MATCH(A7,Aktiv!$A$6:$A$326,0)),"") -> 146 | K7: =IFERROR(ROUND(G7*Steuerungsdaten!$B$5,0),"-") -> 43 | L7: =IFERROR(ROUND(H7*Steuerungsdaten!$B$5,0),"-") -> 145 | M7: =IFERROR(ROUND(I7*Steuerungsdaten!$B$5,0),"-") -> 151 | N7: =IFERROR(ROUND(J7*Steuerungsdaten!$B$5,0),"-") -> 168 | O7: =IF(ISNA(MATCH(A7,Aktiv!$A$6:$A$326,0)),"⚠ nicht im Modell","")
A8: 3006 | B8: Platte | C8: Boden | D8: Boden (420x580) | E8: 420 | F8: 580 | G8: =IFERROR(INDEX(Aktiv!$G$6:$G$326,MATCH(A8,Aktiv!$A$6:$A$326,0)),"") -> 43 | H8: =IFERROR(INDEX(Aktiv!$H$6:$H$326,MATCH(A8,Aktiv!$A$6:$A$326,0)),"") -> 147 | I8: =IFERROR(INDEX(Aktiv!$I$6:$I$326,MATCH(A8,Aktiv!$A$6:$A$326,0)),"") -> 153 | J8: =IFERROR(INDEX(Aktiv!$J$6:$J$326,MATCH(A8,Aktiv!$A$6:$A$326,0)),"") -> 170 | K8: =IFERROR(ROUND(G8*Steuerungsdaten!$B$5,0),"-") -> 49 | L8: =IFERROR(ROUND(H8*Steuerungsdaten!$B$5,0),"-") -> 169 | M8: =IFERROR(ROUND(I8*Steuerungsdaten!$B$5,0),"-") -> 176 | N8: =IFERROR(ROUND(J8*Steuerungsdaten!$B$5,0),"-") -> 196 | O8: =IF(ISNA(MATCH(A8,Aktiv!$A$6:$A$326,0)),"⚠ nicht im Modell","")
A9: 3007 | B9: Platte | C9: Boden | D9: Boden (580x580) | E9: 580 | F9: 580 | G9: =IFERROR(INDEX(Aktiv!$G$6:$G$326,MATCH(A9,Aktiv!$A$6:$A$326,0)),"") -> 59 | H9: =IFERROR(INDEX(Aktiv!$H$6:$H$326,MATCH(A9,Aktiv!$A$6:$A$326,0)),"") -> 203 | I9: =IFERROR(INDEX(Aktiv!$I$6:$I$326,MATCH(A9,Aktiv!$A$6:$A$326,0)),"") -> 211 | J9: =IFERROR(INDEX(Aktiv!$J$6:$J$326,MATCH(A9,Aktiv!$A$6:$A$326,0)),"") -> 235 | K9: =IFERROR(ROUND(G9*Steuerungsdaten!$B$5,0),"-") -> 68 | L9: =IFERROR(ROUND(H9*Steuerungsdaten!$B$5,0),"-") -> 233 | M9: =IFERROR(ROUND(I9*Steuerungsdaten!$B$5,0),"-") -> 243 | N9: =IFERROR(ROUND(J9*Steuerungsdaten!$B$5,0),"-") -> 270 | O9: =IF(ISNA(MATCH(A9,Aktiv!$A$6:$A$326,0)),"⚠ nicht im Modell","")
A10: 3008 | B10: Platte | C10: Boden | D10: Boden (780x580) | E10: 780 | F10: 580 | G10: =IFERROR(INDEX(Aktiv!$G$6:$G$326,MATCH(A10,Aktiv!$A$6:$A$326,0)),"") -> 80 | H10: =IFERROR(INDEX(Aktiv!$H$6:$H$326,MATCH(A10,Aktiv!$A$6:$A$326,0)),"") -> 273 | I10: =IFERROR(INDEX(Aktiv!$I$6:$I$326,MATCH(A10,Aktiv!$A$6:$A$326,0)),"") -> 284 | J10: =IFERROR(INDEX(Aktiv!$J$6:$J$326,MATCH(A10,Aktiv!$A$6:$A$326,0)),"") -> 316 | K10: =IFERROR(ROUND(G10*Steuerungsdaten!$B$5,0),"-") -> 92 | L10: =IFERROR(ROUND(H10*Steuerungsdaten!$B$5,0),"-") -> 314 | M10: =IFERROR(ROUND(I10*Steuerungsdaten!$B$5,0),"-") -> 327 | N10: =IFERROR(ROUND(J10*Steuerungsdaten!$B$5,0),"-") -> 363 | O10: =IF(ISNA(MATCH(A10,Aktiv!$A$6:$A$326,0)),"⚠ nicht im Modell","")
A11: 3009 | B11: Platte | C11: Boden | D11: Boden (980x580) | E11: 980 | F11: 580 | G11: =IFERROR(INDEX(Aktiv!$G$6:$G$326,MATCH(A11,Aktiv!$A$6:$A$326,0)),"") -> 100 | H11: =IFERROR(INDEX(Aktiv!$H$6:$H$326,MATCH(A11,Aktiv!$A$6:$A$326,0)),"") -> 343 | I11: =IFERROR(INDEX(Aktiv!$I$6:$I$326,MATCH(A11,Aktiv!$A$6:$A$326,0)),"") -> 357 | J11: =IFERROR(INDEX(Aktiv!$J$6:$J$326,MATCH(A11,Aktiv!$A$6:$A$326,0)),"") -> 398 | K11: =IFERROR(ROUND(G11*Steuerungsdaten!$B$5,0),"-") -> 115 | L11: =IFERROR(ROUND(H11*Steuerungsdaten!$B$5,0),"-") -> 394 | M11: =IFERROR(ROUND(I11*Steuerungsdaten!$B$5,0),"-") -> 411 | N11: =IFERROR(ROUND(J11*Steuerungsdaten!$B$5,0),"-") -> 458 | O11: =IF(ISNA(MATCH(A11,Aktiv!$A$6:$A$326,0)),"⚠ nicht im Modell","")
A12: 3010 | B12: Platte | C12: Boden | D12: Boden (780x780) | E12: 780 | F12: 780 | G12: =IFERROR(INDEX(Aktiv!$G$6:$G$326,MATCH(A12,Aktiv!$A$6:$A$326,0)),"") -> 107 | H12: =IFERROR(INDEX(Aktiv!$H$6:$H$326,MATCH(A12,Aktiv!$A$6:$A$326,0)),"") -> 367 | I12: =IFERROR(INDEX(Aktiv!$I$6:$I$326,MATCH(A12,Aktiv!$A$6:$A$326,0)),"") -> 382 | J12: =IFERROR(INDEX(Aktiv!$J$6:$J$326,MATCH(A12,Aktiv!$A$6:$A$326,0)),"") -> 426 | K12: =IFERROR(ROUND(G12*Steuerungsdaten!$B$5,0),"-") -> 123 | L12: =IFERROR(ROUND(H12*Steuerungsdaten!$B$5,0),"-") -> 422 | M12: =IFERROR(ROUND(I12*Steuerungsdaten!$B$5,0),"-") -> 439 | N12: =IFERROR(ROUND(J12*Steuerungsdaten!$B$5,0),"-") -> 490 | O12: =IF(ISNA(MATCH(A12,Aktiv!$A$6:$A$326,0)),"⚠ nicht im Modell","")
A13: 3011 | B13: Platte | C13: Boden | D13: Boden (980x780) | E13: 980 | F13: 780 | G13: =IFERROR(INDEX(Aktiv!$G$6:$G$326,MATCH(A13,Aktiv!$A$6:$A$326,0)),"") -> 135 | H13: =IFERROR(INDEX(Aktiv!$H$6:$H$326,MATCH(A13,Aktiv!$A$6:$A$326,0)),"") -> 461 | I13: =IFERROR(INDEX(Aktiv!$I$6:$I$326,MATCH(A13,Aktiv!$A$6:$A$326,0)),"") -> 480 | J13: =IFERROR(INDEX(Aktiv!$J$6:$J$326,MATCH(A13,Aktiv!$A$6:$A$326,0)),"") -> 535 | K13: =IFERROR(ROUND(G13*Steuerungsdaten!$B$5,0),"-") -> 155 | L13: =IFERROR(ROUND(H13*Steuerungsdaten!$B$5,0),"-") -> 530 | M13: =IFERROR(ROUND(I13*Steuerungsdaten!$B$5,0),"-") -> 552 | N13: =IFERROR(ROUND(J13*Steuerungsdaten!$B$5,0),"-") -> 615 | O13: =IF(ISNA(MATCH(A13,Aktiv!$A$6:$A$326,0)),"⚠ nicht im Modell","")
... A16: 3014 | B16: Platte | C16: Boden | D16: Boden (420x980) | E16: 420 | F16: 980 | G16: =IFERROR(INDEX(Aktiv!$G$6:$G$326,MATCH(A16,Aktiv!$A$6:$A$326,0)),"") -> 72 | H16: =IFERROR(INDEX(Aktiv!$H$6:$H$326,MATCH(A16,Aktiv!$A$6:$A$326,0)),"") -> 248 | I16: =IFERROR(INDEX(Aktiv!$I$6:$I$326,MATCH(A16,Aktiv!$A$6:$A$326,0)),"") -> 259 | J16: =IFERROR(INDEX(Aktiv!$J$6:$J$326,MATCH(A16,Aktiv!$A$6:$A$326,0)),"") -> 288 | K16: =IFERROR(ROUND(G16*Steuerungsdaten!$B$5,0),"-") -> 83 | L16: =IFERROR(ROUND(H16*Steuerungsdaten!$B$5,0),"-") -> 285 | M16: =IFERROR(ROUND(I16*Steuerungsdaten!$B$5,0),"-") -> 298 | N16: =IFERROR(ROUND(J16*Steuerungsdaten!$B$5,0),"-") -> 331 | O16: =IF(ISNA(MATCH(A16,Aktiv!$A$6:$A$326,0)),"⚠ nicht im Modell","")
A17: S_0003 | B17: Platte | C17: Boden | D17: Boden (420x420) | E17: 420 | F17: 420 | G17: =IFERROR(INDEX(Aktiv!$G$6:$G$326,MATCH(A17,Aktiv!$A$6:$A$326,0)),"") -> 31 | H17: =IFERROR(INDEX(Aktiv!$H$6:$H$326,MATCH(A17,Aktiv!$A$6:$A$326,0)),"") -> 106 | I17: =IFERROR(INDEX(Aktiv!$I$6:$I$326,MATCH(A17,Aktiv!$A$6:$A$326,0)),"") -> 120 | J17: =IFERROR(INDEX(Aktiv!$J$6:$J$326,MATCH(A17,Aktiv!$A$6:$A$326,0)),"") -> 145 | K17: =IFERROR(ROUND(G17*Steuerungsdaten!$B$5,0),"-") -> 36 | L17: =IFERROR(ROUND(H17*Steuerungsdaten!$B$5,0),"-") -> 122 | M17: =IFERROR(ROUND(I17*Steuerungsdaten!$B$5,0),"-") -> 138 | N17: =IFERROR(ROUND(J17*Steuerungsdaten!$B$5,0),"-") -> 167 | O17: =IF(ISNA(MATCH(A17,Aktiv!$A$6:$A$326,0)),"⚠ nicht im Modell","")
A18: 3100 | B18: Platte | C18: Seite außen | D18: Seite außen (360x180) | E18: 360 | F18: 180 | G18: =IFERROR(INDEX(Aktiv!$G$6:$G$326,MATCH(A18,Aktiv!$A$6:$A$326,0)),"") -> 25 | H18: =IFERROR(INDEX(Aktiv!$H$6:$H$326,MATCH(A18,Aktiv!$A$6:$A$326,0)),"") -> 103 | I18: =IFERROR(INDEX(Aktiv!$I$6:$I$326,MATCH(A18,Aktiv!$A$6:$A$326,0)),"") -> 120 | J18: =IFERROR(INDEX(Aktiv!$J$6:$J$326,MATCH(A18,Aktiv!$A$6:$A$326,0)),"") -> 145 | K18: =IFERROR(ROUND(G18*Steuerungsdaten!$B$5,0),"-") -> 29 | L18: =IFERROR(ROUND(H18*Steuerungsdaten!$B$5,0),"-") -> 118 | M18: =IFERROR(ROUND(I18*Steuerungsdaten!$B$5,0),"-") -> 138 | N18: =IFERROR(ROUND(J18*Steuerungsdaten!$B$5,0),"-") -> 167 | O18: =IF(ISNA(MATCH(A18,Aktiv!$A$6:$A$326,0)),"⚠ nicht im Modell","")
A19: 3101 | B19: Platte | C19: Seite außen | D19: Seite außen (360x360) | E19: 360 | F19: 360 | G19: =IFERROR(INDEX(Aktiv!$G$6:$G$326,MATCH(A19,Aktiv!$A$6:$A$326,0)),"") -> 25 | H19: =IFERROR(INDEX(Aktiv!$H$6:$H$326,MATCH(A19,Aktiv!$A$6:$A$326,0)),"") -> 103 | I19: =IFERROR(INDEX(Aktiv!$I$6:$I$326,MATCH(A19,Aktiv!$A$6:$A$326,0)),"") -> 120 | J19: =IFERROR(INDEX(Aktiv!$J$6:$J$326,MATCH(A19,Aktiv!$A$6:$A$326,0)),"") -> 145 | K19: =IFERROR(ROUND(G19*Steuerungsdaten!$B$5,0),"-") -> 29 | L19: =IFERROR(ROUND(H19*Steuerungsdaten!$B$5,0),"-") -> 118 | M19: =IFERROR(ROUND(I19*Steuerungsdaten!$B$5,0),"-") -> 138 | N19: =IFERROR(ROUND(J19*Steuerungsdaten!$B$5,0),"-") -> 167 | O19: =IF(ISNA(MATCH(A19,Aktiv!$A$6:$A$326,0)),"⚠ nicht im Modell","")
A20: 3102 | B20: Platte | C20: Seite außen | D20: Seite außen (360x720) | E20: 360 | F20: 720 | G20: =IFERROR(INDEX(Aktiv!$G$6:$G$326,MATCH(A20,Aktiv!$A$6:$A$326,0)),"") -> 46 | H20: =IFERROR(INDEX(Aktiv!$H$6:$H$326,MATCH(A20,Aktiv!$A$6:$A$326,0)),"") -> 156 | I20: =IFERROR(INDEX(Aktiv!$I$6:$I$326,MATCH(A20,Aktiv!$A$6:$A$326,0)),"") -> 163 | J20: =IFERROR(INDEX(Aktiv!$J$6:$J$326,MATCH(A20,Aktiv!$A$6:$A$326,0)),"") -> 181 | K20: =IFERROR(ROUND(G20*Steuerungsdaten!$B$5,0),"-") -> 53 | L20: =IFERROR(ROUND(H20*Steuerungsdaten!$B$5,0),"-") -> 179 | M20: =IFERROR(ROUND(I20*Steuerungsdaten!$B$5,0),"-") -> 187 | N20: =IFERROR(ROUND(J20*Steuerungsdaten!$B$5,0),"-") -> 208 | O20: =IF(ISNA(MATCH(A20,Aktiv!$A$6:$A$326,0)),"⚠ nicht im Modell","")
A21: 3103 | B21: Platte | C21: Seite außen | D21: Seite außen (360x1080) | E21: 360 | F21: 1080 | G21: =IFERROR(INDEX(Aktiv!$G$6:$G$326,MATCH(A21,Aktiv!$A$6:$A$326,0)),"") -> 68 | H21: =IFERROR(INDEX(Aktiv!$H$6:$H$326,MATCH(A21,Aktiv!$A$6:$A$326,0)),"") -> 235 | I21: =IFERROR(INDEX(Aktiv!$I$6:$I$326,MATCH(A21,Aktiv!$A$6:$A$326,0)),"") -> 244 | J21: =IFERROR(INDEX(Aktiv!$J$6:$J$326,MATCH(A21,Aktiv!$A$6:$A$326,0)),"") -> 272 | K21: =IFERROR(ROUND(G21*Steuerungsdaten!$B$5,0),"-") -> 78 | L21: =IFERROR(ROUND(H21*Steuerungsdaten!$B$5,0),"-") -> 270 | M21: =IFERROR(ROUND(I21*Steuerungsdaten!$B$5,0),"-") -> 281 | N21: =IFERROR(ROUND(J21*Steuerungsdaten!$B$5,0),"-") -> 313 | O21: =IF(ISNA(MATCH(A21,Aktiv!$A$6:$A$326,0)),"⚠ nicht im Modell","")
A22: 3104 | B22: Platte | C22: Seite außen | D22: Seite außen (360x1440) | E22: 360 | F22: 1440 | G22: =IFERROR(INDEX(Aktiv!$G$6:$G$326,MATCH(A22,Aktiv!$A$6:$A$326,0)),"") -> 91 | H22: =IFERROR(INDEX(Aktiv!$H$6:$H$326,MATCH(A22,Aktiv!$A$6:$A$326,0)),"") -> 313 | I22: =IFERROR(INDEX(Aktiv!$I$6:$I$326,MATCH(A22,Aktiv!$A$6:$A$326,0)),"") -> 326 | J22: =IFERROR(INDEX(Aktiv!$J$6:$J$326,MATCH(A22,Aktiv!$A$6:$A$326,0)),"") -> 363 | K22: =IFERROR(ROUND(G22*Steuerungsdaten!$B$5,0),"-") -> 105 | L22: =IFERROR(ROUND(H22*Steuerungsdaten!$B$5,0),"-") -> 360 | M22: =IFERROR(ROUND(I22*Steuerungsdaten!$B$5,0),"-") -> 375 | N22: =IFERROR(ROUND(J22*Steuerungsdaten!$B$5,0),"-") -> 417 | O22: =IF(ISNA(MATCH(A22,Aktiv!$A$6:$A$326,0)),"⚠ nicht im Modell","")
A23: 3105 | B23: Platte | C23: Seite außen | D23: Seite außen (360x1800) | E23: 360 | F23: 1800 | G23: =IFERROR(INDEX(Aktiv!$G$6:$G$326,MATCH(A23,Aktiv!$A$6:$A$326,0)),"") -> 114 | H23: =IFERROR(INDEX(Aktiv!$H$6:$H$326,MATCH(A23,Aktiv!$A$6:$A$326,0)),"") -> 391 | I23: =IFERROR(INDEX(Aktiv!$I$6:$I$326,MATCH(A23,Aktiv!$A$6:$A$326,0)),"") -> 407 | J23: =IFERROR(INDEX(Aktiv!$J$6:$J$326,MATCH(A23,Aktiv!$A$6:$A$326,0)),"") -> 453 | K23: =IFERROR(ROUND(G23*Steuerungsdaten!$B$5,0),"-") -> 131 | L23: =IFERROR(ROUND(H23*Steuerungsdaten!$B$5,0),"-") -> 450 | M23: =IFERROR(ROUND(I23*Steuerungsdaten!$B$5,0),"-") -> 468 | N23: =IFERROR(ROUND(J23*Steuerungsdaten!$B$5,0),"-") -> 521 | O23: =IF(ISNA(MATCH(A23,Aktiv!$A$6:$A$326,0)),"⚠ nicht im Modell","")
